Workbook
Name ANN: Parametres!$A$116
Name ATR: Parametres!$A$129
Name BDG_DIR: #REF!
Name BDG_FAM: #REF!
Name BDG_MNT: #REF!
Name BDG_NAT: #REF!
Name BUDGET: 'ENGAGEMENTS 2026'!$L:$L
Name cc: Parametres!$A$80:$A$94
Name DIRECTION: #REF!
Name ENGAGE: Parametres!$A$99
Name Estimation: 'ENGAGEMENTS 2026'!$O:$O
Name Excep: Parametres!$A$5
Name FON: Parametres!$A$7
Name FONCTIONNEMENT: Parametres!$A$10:$A$32
Name INF: Parametres!$A$115
Name INV: Parametres!$A$8
Name INVESTISSEMENT: Parametres!$A$34:$A$44
Name LBDG: 'ENGAGEMENTS 2026'!$M:$M
Name MntENG: 'ENGAGEMENTS 2026'!$AD:$AD
Name MTP: Parametres!$B$48
Name MTT: Parametres!$B$46
Name NA: Parametres!$A$113
Name Ordn: Parametres!$A$4
Name PhaAo: Parametres!$A$134
Name PREENGAGE: Parametres!$A$97
Name qq: Parametres!$A$80:$A$94
Name SSENG: #REF!
Name StatutEng: 'ENGAGEMENTS 2026'!$AE:$AE
Name TypBudget: Parametres!$A$2:$A$5
Name TypeBudget: 'ENGAGEMENTS 2026'!$K:$K
Name xBesoin: Parametres!$A$146:$A$149
Name xBUDGET: Parametres!$A$7:$A$8
Name xCATEGORIES: Parametres!$A$137:$A$139
Name xDIRECTION: Parametres!$A$51:$A$78
Name xENG: Parametres!$A$99
Name XLB: Parametres!$A$80:$A$94
Name xNatype: Parametres!$A$142:$A$144
Name xRec: Parametres!$A$149
Name xStatut1: Parametres!$A$113:$A$118
Name xSTATUTSUP: Parametres!$A$128:$A$135
Name xStEng: Parametres!$A$96:$A$100
Name xTYPE1: Parametres!$A$102:$A$111
Name xTYPSUP: Parametres!$A$120:$A$126

Sheet Tableau de Bord
A1: TABLEAU DE BORD DES ENGAGEMENTS BUDGÉTAIRES 2026 — SNRT
A2: Montants en MAD TTC — calculés dynamiquement (SUMIFS) depuis la feuille « Données Suivi »
A3: DIRECTION | B3: FONCTIONNEMENT | H3: INVESTISSEMENT | N3: TOTAL GÉNÉRAL
B4: ENGAGE | C4: PREENGAGE | D4: EN COURS D'ENGAGEMENT | E4: EN COURS DE PREENGAGEMENT | F4: NON ENGAGE | G4: TOTAL FONC. | H4: ENGAGE | I4: PREENGAGE | J4: EN COURS D'ENGAGEMENT | K4: EN COURS DE PREENGAGEMENT | L4: NON ENGAGE | M4: TOTAL INVE.
A5: ARRIYADIA | B5: =SUMIFS('Données Suivi'!$J$2:$J$3000,'Données Suivi'!$A$2:$A$3000,$A5,'Données Suivi'!$O$2:$O$3000,"FONCTIONNEMENT",'Données Suivi'!$H$2:$H$3000,"ENGAGE") | C5: =SUMIFS('Données Suivi'!$J$2:$J$3000,'Données Suivi'!$A$2:$A$3000,$A5,'Données Suivi'!$O$2:$O$3000,"FONCTIONNEMENT",'Données Suivi'!$H$2:$H$3000,"PREENGAGE") | D5: =SUMIFS('Données Suivi'!$J$2:$J$3000,'Données Suivi'!$A$2:$A$3000,$A5,'Données Suivi'!$O$2:$O$3000,"FONCTIONNEMENT",'Données Suivi'!$H$2:$H$3000,"EN COURS D'ENGAGEMENT") | E5: =SUMIFS('Données Suivi'!$J$2:$J$3000,'Données Suivi'!$A$2:$A$3000,$A5,'Données Suivi'!$O$2:$O$3000,"FONCTIONNEMENT",'Données Suivi'!$H$2:$H$3000,"EN COURS DE PREENGAGEMENT") | F5: =SUMIFS('Données Suivi'!$J$2:$J$3000,'Données Suivi'!$A$2:$A$3000,$A5,'Données Suivi'!$O$2:$O$3000,"FONCTIONNEMENT",'Données Suivi'!$H$2:$H$3000,"NON ENGAGE") | G5: =B5+C5+D5+E5+F5 | H5: =SUMIFS('Données Suivi'!$J$2:$J$3000,'Données Suivi'!$A$2:$A$3000,$A5,'Données Suivi'!$O$2:$O$3000,"INVESTISSEMENT",'Données Suivi'!$H$2:$H$3000,"ENGAGE") | I5: =SUMIFS('Données Suivi'!$J$2:$J$3000,'Données Suivi'!$A$2:$A$3000,$A5,'Données Suivi'!$O$2:$O$3000,"INVESTISSEMENT",'Données Suivi'!$H$2:$H$3000,"PREENGAGE") | J5: =SUMIFS('Données Suivi'!$J$2:$J$3000,'Données Suivi'!$A$2:$A$3000,$A5,'Données Suivi'!$O$2:$O$3000,"INVESTISSEMENT",'Données Suivi'!$H$2:$H$3000,"EN COURS D'ENGAGEMENT") | K5: =SUMIFS('Données Suivi'!$J$2:$J$3000,'Données Suivi'!$A$2:$A$3000,$A5,'Données Suivi'!$O$2:$O$3000,"INVESTISSEMENT",'Données Suivi'!$H$2:$H$3000,"EN COURS DE PREENGAGEMENT") | L5: =SUMIFS('Données Suivi'!$J$2:$J$3000,'Données Suivi'!$A$2:$A$3000,$A5,'Données Suivi'!$O$2:$O$3000,"INVESTISSEMENT",'Données Suivi'!$H$2:$H$3000,"NON ENGAGE") | M5: =H5+I5+J5+K5+L5 | N5: =G5+M5
A6: ASSADISSA | B6: =SUMIFS('Données Suivi'!$J$2:$J$3000,'Données Suivi'!$A$2:$A$3000,$A6,'Données Suivi'!$O$2:$O$3000,"FONCTIONNEMENT",'Données Suivi'!$H$2:$H$3000,"ENGAGE") | C6: =SUMIFS('Données Suivi'!$J$2:$J$3000,'Données Suivi'!$A$2:$A$3000,$A6,'Données Suivi'!$O$2:$O$3000,"FONCTIONNEMENT",'Données Suivi'!$H$2:$H$3000,"PREENGAGE") | D6: =SUMIFS('Données Suivi'!$J$2:$J$3000,'Données Suivi'!$A$2:$A$3000,$A6,'Données Suivi'!$O$2:$O$3000,"FONCTIONNEMENT",'Données Suivi'!$H$2:$H$3000,"EN COURS D'ENGAGEMENT") | E6: =SUMIFS('Données Suivi'!$J$2:$J$3000,'Données Suivi'!$A$2:$A$3000,$A6,'Données Suivi'!$O$2:$O$3000,"FONCTIONNEMENT",'Données Suivi'!$H$2:$H$3000,"EN COURS DE PREENGAGEMENT") | F6: =SUMIFS('Données Suivi'!$J$2:$J$3000,'Données Suivi'!$A$2:$A$3000,$A6,'Données Suivi'!$O$2:$O$3000,"FONCTIONNEMENT",'Données Suivi'!$H$2:$H$3000,"NON ENGAGE") | G6: =B6+C6+D6+E6+F6 | H6: =SUMIFS('Données Suivi'!$J$2:$J$3000,'Données Suivi'!$A$2:$A$3000,$A6,'Données Suivi'!$O$2:$O$3000,"INVESTISSEMENT",'Données Suivi'!$H$2:$H$3000,"ENGAGE") | I6: =SUMIFS('Données Suivi'!$J$2:$J$3000,'Données Suivi'!$A$2:$A$3000,$A6,'Données Suivi'!$O$2:$O$3000,"INVESTISSEMENT",'Données Suivi'!$H$2:$H$3000,"PREENGAGE") | J6: =SUMIFS('Données Suivi'!$J$2:$J$3000,'Données Suivi'!$A$2:$A$3000,$A6,'Données Suivi'!$O$2:$O$3000,"INVESTISSEMENT",'Données Suivi'!$H$2:$H$3000,"EN COURS D'ENGAGEMENT") | K6: =SUMIFS('Données Suivi'!$J$2:$J$3000,'Données Suivi'!$A$2:$A$3000,$A6,'Données Suivi'!$O$2:$O$3000,"INVESTISSEMENT",'Données Suivi'!$H$2:$H$3000,"EN COURS DE PREENGAGEMENT") | L6: =SUMIFS('Données Suivi'!$J$2:$J$3000,'Données Suivi'!$A$2:$A$3000,$A6,'Données Suivi'!$O$2:$O$3000,"INVESTISSEMENT",'Données Suivi'!$H$2:$H$3000,"NON ENGAGE") | M6: =H6+I6+J6+K6+L6 | N6: =G6+M6
A7: DA | B7: =SUMIFS('Données Suivi'!$J$2:$J$3000,'Données Suivi'!$A$2:$A$3000,$A7,'Données Suivi'!$O$2:$O$3000,"FONCTIONNEMENT",'Données Suivi'!$H$2:$H$3000,"ENGAGE") | C7: =SUMIFS('Données Suivi'!$J$2:$J$3000,'Données Suivi'!$A$2:$A$3000,$A7,'Données Suivi'!$O$2:$O$3000,"FONCTIONNEMENT",'Données Suivi'!$H$2:$H$3000,"PREENGAGE") | D7: =SUMIFS('Données Suivi'!$J$2:$J$3000,'Données Suivi'!$A$2:$A$3000,$A7,'Données Suivi'!$O$2:$O$3000,"FONCTIONNEMENT",'Données Suivi'!$H$2:$H$3000,"EN COURS D'ENGAGEMENT") | E7: =SUMIFS('Données Suivi'!$J$2:$J$3000,'Données Suivi'!$A$2:$A$3000,$A7,'Données Suivi'!$O$2:$O$3000,"FONCTIONNEMENT",'Données Suivi'!$H$2:$H$3000,"EN COURS DE PREENGAGEMENT") | F7: =SUMIFS('Données Suivi'!$J$2:$J$3000,'Données Suivi'!$A$2:$A$3000,$A7,'Données Suivi'!$O$2:$O$3000,"FONCTIONNEMENT",'Données Suivi'!$H$2:$H$3000,"NON ENGAGE") | G7: =B7+C7+D7+E7+F7 | H7: =SUMIFS('Données Suivi'!$J$2:$J$3000,'Données Suivi'!$A$2:$A$3000,$A7,'Données Suivi'!$O$2:$O$3000,"INVESTISSEMENT",'Données Suivi'!$H$2:$H$3000,"ENGAGE") | I7: =SUMIFS('Données Suivi'!$J$2:$J$3000,'Données Suivi'!$A$2:$A$3000,$A7,'Données Suivi'!$O$2:$O$3000,"INVESTISSEMENT",'Données Suivi'!$H$2:$H$3000,"PREENGAGE") | J7: =SUMIFS('Données Suivi'!$J$2:$J$3000,'Données Suivi'!$A$2:$A$3000,$A7,'Données Suivi'!$O$2:$O$3000,"INVESTISSEMENT",'Données Suivi'!$H$2:$H$3000,"EN COURS D'ENGAGEMENT") | K7: =SUMIFS('Données Suivi'!$J$2:$J$3000,'Données Suivi'!$A$2:$A$3000,$A7,'Données Suivi'!$O$2:$O$3000,"INVESTISSEMENT",'Données Suivi'!$H$2:$H$3000,"EN COURS DE PREENGAGEMENT") | L7: =SUMIFS('Données Suivi'!$J$2:$J$3000,'Données Suivi'!$A$2:$A$3000,$A7,'Données Suivi'!$O$2:$O$3000,"INVESTISSEMENT",'Données Suivi'!$H$2:$H$3000,"NON ENGAGE") | M7: =H7+I7+J7+K7+L7 | N7: =G7+M7
A8: DACG | B8: =SUMIFS('Données Suivi'!$J$2:$J$3000,'Données Suivi'!$A$2:$A$3000,$A8,'Données Suivi'!$O$2:$O$3000,"FONCTIONNEMENT",'Données Suivi'!$H$2:$H$3000,"ENGAGE") | C8: =SUMIFS('Données Suivi'!$J$2:$J$3000,'Données Suivi'!$A$2:$A$3000,$A8,'Données Suivi'!$O$2:$O$3000,"FONCTIONNEMENT",'Données Suivi'!$H$2:$H$3000,"PREENGAGE") | D8: =SUMIFS('Données Suivi'!$J$2:$J$3000,'Données Suivi'!$A$2:$A$3000,$A8,'Données Suivi'!$O$2:$O$3000,"FONCTIONNEMENT",'Données Suivi'!$H$2:$H$3000,"EN COURS D'ENGAGEMENT") | E8: =SUMIFS('Données Suivi'!$J$2:$J$3000,'Données Suivi'!$A$2:$A$3000,$A8,'Données Suivi'!$O$2:$O$3000,"FONCTIONNEMENT",'Données Suivi'!$H$2:$H$3000,"EN COURS DE PREENGAGEMENT") | F8: =SUMIFS('Données Suivi'!$J$2:$J$3000,'Données Suivi'!$A$2:$A$3000,$A8,'Données Suivi'!$O$2:$O$3000,"FONCTIONNEMENT",'Données Suivi'!$H$2:$H$3000,"NON ENGAGE") | G8: =B8+C8+D8+E8+F8 | H8: =SUMIFS('Données Suivi'!$J$2:$J$3000,'Données Suivi'!$A$2:$A$3000,$A8,'Données Suivi'!$O$2:$O$3000,"INVESTISSEMENT",'Données Suivi'!$H$2:$H$3000,"ENGAGE") | I8: =SUMIFS('Données Suivi'!$J$2:$J$3000,'Données Suivi'!$A$2:$A$3000,$A8,'Données Suivi'!$O$2:$O$3000,"INVESTISSEMENT",'Données Suivi'!$H$2:$H$3000,"PREENGAGE") | J8: =SUMIFS('Données Suivi'!$J$2:$J$3000,'Données Suivi'!$A$2:$A$3000,$A8,'Données Suivi'!$O$2:$O$3000,"INVESTISSEMENT",'Données Suivi'!$H$2:$H$3000,"EN COURS D'ENGAGEMENT") | K8: =SUMIFS('Données Suivi'!$J$2:$J$3000,'Données Suivi'!$A$2:$A$3000,$A8,'Données Suivi'!$O$2:$O$3000,"INVESTISSEMENT",'Données Suivi'!$H$2:$H$3000,"EN COURS DE PREENGAGEMENT") | L8: =SUMIFS('Données Suivi'!$J$2:$J$3000,'Données Suivi'!$A$2:$A$3000,$A8,'Données Suivi'!$O$2:$O$3000,"INVESTISSEMENT",'Données Suivi'!$H$2:$H$3000,"NON ENGAGE") | M8: =H8+I8+J8+K8+L8 | N8: =G8+M8
A9: DAR | B9: =SUMIFS('Données Suivi'!$J$2:$J$3000,'Données Suivi'!$A$2:$A$3000,$A9,'Données Suivi'!$O$2:$O$3000,"FONCTIONNEMENT",'Données Suivi'!$H$2:$H$3000,"ENGAGE") | C9: =SUMIFS('Données Suivi'!$J$2:$J$3000,'Données Suivi'!$A$2:$A$3000,$A9,'Données Suivi'!$O$2:$O$3000,"FONCTIONNEMENT",'Données Suivi'!$H$2:$H$3000,"PREENGAGE") | D9: =SUMIFS('Données Suivi'!$J$2:$J$3000,'Données Suivi'!$A$2:$A$3000,$A9,'Données Suivi'!$O$2:$O$3000,"FONCTIONNEMENT",'Données Suivi'!$H$2:$H$3000,"EN COURS D'ENGAGEMENT") | E9: =SUMIFS('Données Suivi'!$J$2:$J$3000,'Données Suivi'!$A$2:$A$3000,$A9,'Données Suivi'!$O$2:$O$3000,"FONCTIONNEMENT",'Données Suivi'!$H$2:$H$3000,"EN COURS DE PREENGAGEMENT") | F9: =SUMIFS('Données Suivi'!$J$2:$J$3000,'Données Suivi'!$A$2:$A$3000,$A9,'Données Suivi'!$O$2:$O$3000,"FONCTIONNEMENT",'Données Suivi'!$H$2:$H$3000,"NON ENGAGE") | G9: =B9+C9+D9+E9+F9 | H9: =SUMIFS('Données Suivi'!$J$2:$J$3000,'Données Suivi'!$A$2:$A$3000,$A9,'Données Suivi'!$O$2:$O$3000,"INVESTISSEMENT",'Données Suivi'!$H$2:$H$3000,"ENGAGE") | I9: =SUMIFS('Données Suivi'!$J$2:$J$3000,'Données Suivi'!$A$2:$A$3000,$A9,'Données Suivi'!$O$2:$O$3000,"INVESTISSEMENT",'Données Suivi'!$H$2:$H$3000,"PREENGAGE") | J9: =SUMIFS('Données Suivi'!$J$2:$J$3000,'Données Suivi'!$A$2:$A$3000,$A9,'Données Suivi'!$O$2:$O$3000,"INVESTISSEMENT",'Données Suivi'!$H$2:$H$3000,"EN COURS D'ENGAGEMENT") | K9: =SUMIFS('Données Suivi'!$J$2:$J$3000,'Données Suivi'!$A$2:$A$3000,$A9,'Données Suivi'!$O$2:$O$3000,"INVESTISSEMENT",'Données Suivi'!$H$2:$H$3000,"EN COURS DE PREENGAGEMENT") | L9: =SUMIFS('Données Suivi'!$J$2:$J$3000,'Données Suivi'!$A$2:$A$3000,$A9,'Données Suivi'!$O$2:$O$3000,"INVESTISSEMENT",'Données Suivi'!$H$2:$H$3000,"NON ENGAGE") | M9: =H9+I9+J9+K9+L9 | N9: =G9+M9
A10: DCPA | B10: =SUMIFS('Données Suivi'!$J$2:$J$3000,'Données Suivi'!$A$2:$A$3000,$A10,'Données Suivi'!$O$2:$O$3000,"FONCTIONNEMENT",'Données Suivi'!$H$2:$H$3000,"ENGAGE") | C10: =SUMIFS('Données Suivi'!$J$2:$J$3000,'Données Suivi'!$A$2:$A$3000,$A10,'Données Suivi'!$O$2:$O$3000,"FONCTIONNEMENT",'Données Suivi'!$H$2:$H$3000,"PREENGAGE") | D10: =SUMIFS('Données Suivi'!$J$2:$J$3000,'Données Suivi'!$A$2:$A$3000,$A10,'Données Suivi'!$O$2:$O$3000,"FONCTIONNEMENT",'Données Suivi'!$H$2:$H$3000,"EN COURS D'ENGAGEMENT") | E10: =SUMIFS('Données Suivi'!$J$2:$J$3000,'Données Suivi'!$A$2:$A$3000,$A10,'Données Suivi'!$O$2:$O$3000,"FONCTIONNEMENT",'Données Suivi'!$H$2:$H$3000,"EN COURS DE PREENGAGEMENT") | F10: =SUMIFS('Données Suivi'!$J$2:$J$3000,'Données Suivi'!$A$2:$A$3000,$A10,'Données Suivi'!$O$2:$O$3000,"FONCTIONNEMENT",'Données Suivi'!$H$2:$H$3000,"NON ENGAGE") | G10: =B10+C10+D10+E10+F10 | H10: =SUMIFS('Données Suivi'!$J$2:$J$3000,'Données Suivi'!$A$2:$A$3000,$A10,'Données Suivi'!$O$2:$O$3000,"INVESTISSEMENT",'Données Suivi'!$H$2:$H$3000,"ENGAGE") | I10: =SUMIFS('Données Suivi'!$J$2:$J$3000,'Données Suivi'!$A$2:$A$3000,$A10,'Données Suivi'!$O$2:$O$3000,"INVESTISSEMENT",'Données Suivi'!$H$2:$H$3000,"PREENGAGE") | J10: =SUMIFS('Données Suivi'!$J$2:$J$3000,'Données Suivi'!$A$2:$A$3000,$A10,'Données Suivi'!$O$2:$O$3000,"INVESTISSEMENT",'Données Suivi'!$H$2:$H$3000,"EN COURS D'ENGAGEMENT") | K10: =SUMIFS('Données Suivi'!$J$2:$J$3000,'Données Suivi'!$A$2:$A$3000,$A10,'Données Suivi'!$O$2:$O$3000,"INVESTISSEMENT",'Données Suivi'!$H$2:$H$3000,"EN COURS DE PREENGAGEMENT") | L10: =SUMIFS('Données Suivi'!$J$2:$J$3000,'Données Suivi'!$A$2:$A$3000,$A10,'Données Suivi'!$O$2:$O$3000,"INVESTISSEMENT",'Données Suivi'!$H$2:$H$3000,"NON ENGAGE") | M10: =H10+I10+J10+K10+L10 | N10: =G10+M10
A11: DCRI | B11: =SUMIFS('Données Suivi'!$J$2:$J$3000,'Données Suivi'!$A$2:$A$3000,$A11,'Données Suivi'!$O$2:$O$3000,"FONCTIONNEMENT",'Données Suivi'!$H$2:$H$3000,"ENGAGE") | C11: =SUMIFS('Données Suivi'!$J$2:$J$3000,'Données Suivi'!$A$2:$A$3000,$A11,'Données Suivi'!$O$2:$O$3000,"FONCTIONNEMENT",'Données Suivi'!$H$2:$H$3000,"PREENGAGE") | D11: =SUMIFS('Données Suivi'!$J$2:$J$3000,'Données Suivi'!$A$2:$A$3000,$A11,'Données Suivi'!$O$2:$O$3000,"FONCTIONNEMENT",'Données Suivi'!$H$2:$H$3000,"EN COURS D'ENGAGEMENT") | E11: =SUMIFS('Données Suivi'!$J$2:$J$3000,'Données Suivi'!$A$2:$A$3000,$A11,'Données Suivi'!$O$2:$O$3000,"FONCTIONNEMENT",'Données Suivi'!$H$2:$H$3000,"EN COURS DE PREENGAGEMENT") | F11: =SUMIFS('Données Suivi'!$J$2:$J$3000,'Données Suivi'!$A$2:$A$3000,$A11,'Données Suivi'!$O$2:$O$3000,"FONCTIONNEMENT",'Données Suivi'!$H$2:$H$3000,"NON ENGAGE") | G11: =B11+C11+D11+E11+F11 | H11: =SUMIFS('Données Suivi'!$J$2:$J$3000,'Données Suivi'!$A$2:$A$3000,$A11,'Données Suivi'!$O$2:$O$3000,"INVESTISSEMENT",'Données Suivi'!$H$2:$H$3000,"ENGAGE") | I11: =SUMIFS('Données Suivi'!$J$2:$J$3000,'Données Suivi'!$A$2:$A$3000,$A11,'Données Suivi'!$O$2:$O$3000,"INVESTISSEMENT",'Données Suivi'!$H$2:$H$3000,"PREENGAGE") | J11: =SUMIFS('Données Suivi'!$J$2:$J$3000,'Données Suivi'!$A$2:$A$3000,$A11,'Données Suivi'!$O$2:$O$3000,"INVESTISSEMENT",'Données Suivi'!$H$2:$H$3000,"EN COURS D'ENGAGEMENT") | K11: =SUMIFS('Données Suivi'!$J$2:$J$3000,'Données Suivi'!$A$2:$A$3000,$A11,'Données Suivi'!$O$2:$O$3000,"INVESTISSEMENT",'Données Suivi'!$H$2:$H$3000,"EN COURS DE PREENGAGEMENT") | L11: =SUMIFS('Données Suivi'!$J$2:$J$3000,'Données Suivi'!$A$2:$A$3000,$A11,'Données Suivi'!$O$2:$O$3000,"INVESTISSEMENT",'Données Suivi'!$H$2:$H$3000,"NON ENGAGE") | M11: =H11+I11+J11+K11+L11 | N11: =G11+M11
A12: DCT | B12: =SUMIFS('Données Suivi'!$J$2:$J$3000,'Données Suivi'!$A$2:$A$3000,$A12,'Données Suivi'!$O$2:$O$3000,"FONCTIONNEMENT",'Données Suivi'!$H$2:$H$3000,"ENGAGE") | C12: =SUMIFS('Données Suivi'!$J$2:$J$3000,'Données Suivi'!$A$2:$A$3000,$A12,'Données Suivi'!$O$2:$O$3000,"FONCTIONNEMENT",'Données Suivi'!$H$2:$H$3000,"PREENGAGE") | D12: =SUMIFS('Données Suivi'!$J$2:$J$3000,'Données Suivi'!$A$2:$A$3000,$A12,'Données Suivi'!$O$2:$O$3000,"FONCTIONNEMENT",'Données Suivi'!$H$2:$H$3000,"EN COURS D'ENGAGEMENT") | E12: =SUMIFS('Données Suivi'!$J$2:$J$3000,'Données Suivi'!$A$2:$A$3000,$A12,'Données Suivi'!$O$2:$O$3000,"FONCTIONNEMENT",'Données Suivi'!$H$2:$H$3000,"EN COURS DE PREENGAGEMENT") | F12: =SUMIFS('Données Suivi'!$J$2:$J$3000,'Données Suivi'!$A$2:$A$3000,$A12,'Données Suivi'!$O$2:$O$3000,"FONCTIONNEMENT",'Données Suivi'!$H$2:$H$3000,"NON ENGAGE") | G12: =B12+C12+D12+E12+F12 | H12: =SUMIFS('Données Suivi'!$J$2:$J$3000,'Données Suivi'!$A$2:$A$3000,$A12,'Données Suivi'!$O$2:$O$3000,"INVESTISSEMENT",'Données Suivi'!$H$2:$H$3000,"ENGAGE") | I12: =SUMIFS('Données Suivi'!$J$2:$J$3000,'Données Suivi'!$A$2:$A$3000,$A12,'Données Suivi'!$O$2:$O$3000,"INVESTISSEMENT",'Données Suivi'!$H$2:$H$3000,"PREENGAGE") | J12: =SUMIFS('Données Suivi'!$J$2:$J$3000,'Données Suivi'!$A$2:$A$3000,$A12,'Données Suivi'!$O$2:$O$3000,"INVESTISSEMENT",'Données Suivi'!$H$2:$H$3000,"EN COURS D'ENGAGEMENT") | K12: =SUMIFS('Données Suivi'!$J$2:$J$3000,'Données Suivi'!$A$2:$A$3000,$A12,'Données Suivi'!$O$2:$O$3000,"INVESTISSEMENT",'Données Suivi'!$H$2:$H$3000,"EN COURS DE PREENGAGEMENT") | L12: =SUMIFS('Données Suivi'!$J$2:$J$3000,'Données Suivi'!$A$2:$A$3000,$A12,'Données Suivi'!$O$2:$O$3000,"INVESTISSEMENT",'Données Suivi'!$H$2:$H$3000,"NON ENGAGE") | M12: =H12+I12+J12+K12+L12 | N12: =G12+M12
A13: DG | B13: =SUMIFS('Données Suivi'!$J$2:$J$3000,'Données Suivi'!$A$2:$A$3000,$A13,'Données Suivi'!$O$2:$O$3000,"FONCTIONNEMENT",'Données Suivi'!$H$2:$H$3000,"ENGAGE") | C13: =SUMIFS('Données Suivi'!$J$2:$J$3000,'Données Suivi'!$A$2:$A$3000,$A13,'Données Suivi'!$O$2:$O$3000,"FONCTIONNEMENT",'Données Suivi'!$H$2:$H$3000,"PREENGAGE") | D13: =SUMIFS('Données Suivi'!$J$2:$J$3000,'Données Suivi'!$A$2:$A$3000,$A13,'Données Suivi'!$O$2:$O$3000,"FONCTIONNEMENT",'Données Suivi'!$H$2:$H$3000,"EN COURS D'ENGAGEMENT") | E13: =SUMIFS('Données Suivi'!$J$2:$J$3000,'Données Suivi'!$A$2:$A$3000,$A13,'Données Suivi'!$O$2:$O$3000,"FONCTIONNEMENT",'Données Suivi'!$H$2:$H$3000,"EN COURS DE PREENGAGEMENT") | F13: =SUMIFS('Données Suivi'!$J$2:$J$3000,'Données Suivi'!$A$2:$A$3000,$A13,'Données Suivi'!$O$2:$O$3000,"FONCTIONNEMENT",'Données Suivi'!$H$2:$H$3000,"NON ENGAGE") | G13: =B13+C13+D13+E13+F13 | H13: =SUMIFS('Données Suivi'!$J$2:$J$3000,'Données Suivi'!$A$2:$A$3000,$A13,'Données Suivi'!$O$2:$O$3000,"INVESTISSEMENT",'Données Suivi'!$H$2:$H$3000,"ENGAGE") | I13: =SUMIFS('Données Suivi'!$J$2:$J$3000,'Données Suivi'!$A$2:$A$3000,$A13,'Données Suivi'!$O$2:$O$3000,"INVESTISSEMENT",'Données Suivi'!$H$2:$H$3000,"PREENGAGE") | J13: =SUMIFS('Données Suivi'!$J$2:$J$3000,'Données Suivi'!$A$2:$A$3000,$A13,'Données Suivi'!$O$2:$O$3000,"INVESTISSEMENT",'Données Suivi'!$H$2:$H$3000,"EN COURS D'ENGAGEMENT") | K13: =SUMIFS('Données Suivi'!$J$2:$J$3000,'Données Suivi'!$A$2:$A$3000,$A13,'Données Suivi'!$O$2:$O$3000,"INVESTISSEMENT",'Données Suivi'!$H$2:$H$3000,"EN COURS DE PREENGAGEMENT") | L13: =SUMIFS('Données Suivi'!$J$2:$J$3000,'Données Suivi'!$A$2:$A$3000,$A13,'Données Suivi'!$O$2:$O$3000,"INVESTISSEMENT",'Données Suivi'!$H$2:$H$3000,"NON ENGAGE") | M13: =H13+I13+J13+K13+L13 | N13: =G13+M13
A14: DINFORADIO | B14: =SUMIFS('Données Suivi'!$J$2:$J$3000,'Données Suivi'!$A$2:$A$3000,$A14,'Données Suivi'!$O$2:$O$3000,"FONCTIONNEMENT",'Données Suivi'!$H$2:$H$3000,"ENGAGE") | C14: =SUMIFS('Données Suivi'!$J$2:$J$3000,'Données Suivi'!$A$2:$A$3000,$A14,'Données Suivi'!$O$2:$O$3000,"FONCTIONNEMENT",'Données Suivi'!$H$2:$H$3000,"PREENGAGE") | D14: =SUMIFS('Données Suivi'!$J$2:$J$3000,'Données Suivi'!$A$2:$A$3000,$A14,'Données Suivi'!$O$2:$O$3000,"FONCTIONNEMENT",'Données Suivi'!$H$2:$H$3000,"EN COURS D'ENGAGEMENT") | E14: =SUMIFS('Données Suivi'!$J$2:$J$3000,'Données Suivi'!$A$2:$A$3000,$A14,'Données Suivi'!$O$2:$O$3000,"FONCTIONNEMENT",'Données Suivi'!$H$2:$H$3000,"EN COURS DE PREENGAGEMENT") | F14: =SUMIFS('Données Suivi'!$J$2:$J$3000,'Données Suivi'!$A$2:$A$3000,$A14,'Données Suivi'!$O$2:$O$3000,"FONCTIONNEMENT",'Données Suivi'!$H$2:$H$3000,"NON ENGAGE") | G14: =B14+C14+D14+E14+F14 | H14: =SUMIFS('Données Suivi'!$J$2:$J$3000,'Données Suivi'!$A$2:$A$3000,$A14,'Données Suivi'!$O$2:$O$3000,"INVESTISSEMENT",'Données Suivi'!$H$2:$H$3000,"ENGAGE") | I14: =SUMIFS('Données Suivi'!$J$2:$J$3000,'Données Suivi'!$A$2:$A$3000,$A14,'Données Suivi'!$O$2:$O$3000,"INVESTISSEMENT",'Données Suivi'!$H$2:$H$3000,"PREENGAGE") | J14: =SUMIFS('Données Suivi'!$J$2:$J$3000,'Données Suivi'!$A$2:$A$3000,$A14,'Données Suivi'!$O$2:$O$3000,"INVESTISSEMENT",'Données Suivi'!$H$2:$H$3000,"EN COURS D'ENGAGEMENT") | K14: =SUMIFS('Données Suivi'!$J$2:$J$3000,'Données Suivi'!$A$2:$A$3000,$A14,'Données Suivi'!$O$2:$O$3000,"INVESTISSEMENT",'Données Suivi'!$H$2:$H$3000,"EN COURS DE PREENGAGEMENT") | L14: =SUMIFS('Données Suivi'!$J$2:$J$3000,'Données Suivi'!$A$2:$A$3000,$A14,'Données Suivi'!$O$2:$O$3000,"INVESTISSEMENT",'Données Suivi'!$H$2:$H$3000,"NON ENGAGE") | M14: =H14+I14+J14+K14+L14 | N14: =G14+M14
A15: DINFOTV | B15: =SUMIFS('Données Suivi'!$J$2:$J$3000,'Données Suivi'!$A$2:$A$3000,$A15,'Données Suivi'!$O$2:$O$3000,"FONCTIONNEMENT",'Données Suivi'!$H$2:$H$3000,"ENGAGE") | C15: =SUMIFS('Données Suivi'!$J$2:$J$3000,'Données Suivi'!$A$2:$A$3000,$A15,'Données Suivi'!$O$2:$O$3000,"FONCTIONNEMENT",'Données Suivi'!$H$2:$H$3000,"PREENGAGE") | D15: =SUMIFS('Données Suivi'!$J$2:$J$3000,'Données Suivi'!$A$2:$A$3000,$A15,'Données Suivi'!$O$2:$O$3000,"FONCTIONNEMENT",'Données Suivi'!$H$2:$H$3000,"EN COURS D'ENGAGEMENT") | E15: =SUMIFS('Données Suivi'!$J$2:$J$3000,'Données Suivi'!$A$2:$A$3000,$A15,'Données Suivi'!$O$2:$O$3000,"FONCTIONNEMENT",'Données Suivi'!$H$2:$H$3000,"EN COURS DE PREENGAGEMENT") | F15: =SUMIFS('Données Suivi'!$J$2:$J$3000,'Données Suivi'!$A$2:$A$3000,$A15,'Données Suivi'!$O$2:$O$3000,"FONCTIONNEMENT",'Données Suivi'!$H$2:$H$3000,"NON ENGAGE") | G15: =B15+C15+D15+E15+F15 | H15: =SUMIFS('Données Suivi'!$J$2:$J$3000,'Données Suivi'!$A$2:$A$3000,$A15,'Données Suivi'!$O$2:$O$3000,"INVESTISSEMENT",'Données Suivi'!$H$2:$H$3000,"ENGAGE") | I15: =SUMIFS('Données Suivi'!$J$2:$J$3000,'Données Suivi'!$A$2:$A$3000,$A15,'Données Suivi'!$O$2:$O$3000,"INVESTISSEMENT",'Données Suivi'!$H$2:$H$3000,"PREENGAGE") | J15: =SUMIFS('Données Suivi'!$J$2:$J$3000,'Données Suivi'!$A$2:$A$3000,$A15,'Données Suivi'!$O$2:$O$3000,"INVESTISSEMENT",'Données Suivi'!$H$2:$H$3000,"EN COURS D'ENGAGEMENT") | K15: =SUMIFS('Données Suivi'!$J$2:$J$3000,'Données Suivi'!$A$2:$A$3000,$A15,'Données Suivi'!$O$2:$O$3000,"INVESTISSEMENT",'Données Suivi'!$H$2:$H$3000,"EN COURS DE PREENGAGEMENT") | L15: =SUMIFS('Données Suivi'!$J$2:$J$3000,'Données Suivi'!$A$2:$A$3000,$A15,'Données Suivi'!$O$2:$O$3000,"INVESTISSEMENT",'Données Suivi'!$H$2:$H$3000,"NON ENGAGE") | M15: =H15+I15+J15+K15+L15 | N15: =G15+M15
A16: DJURIDIQUE | B16: =SUMIFS('Données Suivi'!$J$2:$J$3000,'Données Suivi'!$A$2:$A$3000,$A16,'Données Suivi'!$O$2:$O$3000,"FONCTIONNEMENT",'Données Suivi'!$H$2:$H$3000,"ENGAGE") | C16: =SUMIFS('Données Suivi'!$J$2:$J$3000,'Données Suivi'!$A$2:$A$3000,$A16,'Données Suivi'!$O$2:$O$3000,"FONCTIONNEMENT",'Données Suivi'!$H$2:$H$3000,"PREENGAGE") | D16: =SUMIFS('Données Suivi'!$J$2:$J$3000,'Données Suivi'!$A$2:$A$3000,$A16,'Données Suivi'!$O$2:$O$3000,"FONCTIONNEMENT",'Données Suivi'!$H$2:$H$3000,"EN COURS D'ENGAGEMENT") | E16: =SUMIFS('Données Suivi'!$J$2:$J$3000,'Données Suivi'!$A$2:$A$3000,$A16,'Données Suivi'!$O$2:$O$3000,"FONCTIONNEMENT",'Données Suivi'!$H$2:$H$3000,"EN COURS DE PREENGAGEMENT") | F16: =SUMIFS('Données Suivi'!$J$2:$J$3000,'Données Suivi'!$A$2:$A$3000,$A16,'Données Suivi'!$O$2:$O$3000,"FONCTIONNEMENT",'Données Suivi'!$H$2:$H$3000,"NON ENGAGE") | G16: =B16+C16+D16+E16+F16 | H16: =SUMIFS('Données Suivi'!$J$2:$J$3000,'Données Suivi'!$A$2:$A$3000,$A16,'Données Suivi'!$O$2:$O$3000,"INVESTISSEMENT",'Données Suivi'!$H$2:$H$3000,"ENGAGE") | I16: =SUMIFS('Données Suivi'!$J$2:$J$3000,'Données Suivi'!$A$2:$A$3000,$A16,'Données Suivi'!$O$2:$O$3000,"INVESTISSEMENT",'Données Suivi'!$H$2:$H$3000,"PREENGAGE") | J16: =SUMIFS('Données Suivi'!$J$2:$J$3000,'Données Suivi'!$A$2:$A$3000,$A16,'Données Suivi'!$O$2:$O$3000,"INVESTISSEMENT",'Données Suivi'!$H$2:$H$3000,"EN COURS D'ENGAGEMENT") | K16: =SUMIFS('Données Suivi'!$J$2:$J$3000,'Données Suivi'!$A$2:$A$3000,$A16,'Données Suivi'!$O$2:$O$3000,"INVESTISSEMENT",'Données Suivi'!$H$2:$H$3000,"EN COURS DE PREENGAGEMENT") | L16: =SUMIFS('Données Suivi'!$J$2:$J$3000,'Données Suivi'!$A$2:$A$3000,$A16,'Données Suivi'!$O$2:$O$3000,"INVESTISSEMENT",'Données Suivi'!$H$2:$H$3000,"NON ENGAGE") | M16: =H16+I16+J16+K16+L16 | N16: =G16+M16
... A27: TV LAAYOUNE | B27: =SUMIFS('Données Suivi'!$J$2:$J$3000,'Données Suivi'!$A$2:$A$3000,$A27,'Données Suivi'!$O$2:$O$3000,"FONCTIONNEMENT",'Données Suivi'!$H$2:$H$3000,"ENGAGE") | C27: =SUMIFS('Données Suivi'!$J$2:$J$3000,'Données Suivi'!$A$2:$A$3000,$A27,'Données Suivi'!$O$2:$O$3000,"FONCTIONNEMENT",'Données Suivi'!$H$2:$H$3000,"PREENGAGE") | D27: =SUMIFS('Données Suivi'!$J$2:$J$3000,'Données Suivi'!$A$2:$A$3000,$A27,'Données Suivi'!$O$2:$O$3000,"FONCTIONNEMENT",'Données Suivi'!$H$2:$H$3000,"EN COURS D'ENGAGEMENT") | E27: =SUMIFS('Données Suivi'!$J$2:$J$3000,'Données Suivi'!$A$2:$A$3000,$A27,'Données Suivi'!$O$2:$O$3000,"FONCTIONNEMENT",'Données Suivi'!$H$2:$H$3000,"EN COURS DE PREENGAGEMENT") | F27: =SUMIFS('Données Suivi'!$J$2:$J$3000,'Données Suivi'!$A$2:$A$3000,$A27,'Données Suivi'!$O$2:$O$3000,"FONCTIONNEMENT",'Données Suivi'!$H$2:$H$3000,"NON ENGAGE") | G27: =B27+C27+D27+E27+F27 | H27: =SUMIFS('Données Suivi'!$J$2:$J$3000,'Données Suivi'!$A$2:$A$3000,$A27,'Données Suivi'!$O$2:$O$3000,"INVESTISSEMENT",'Données Suivi'!$H$2:$H$3000,"ENGAGE") | I27: =SUMIFS('Données Suivi'!$J$2:$J$3000,'Données Suivi'!$A$2:$A$3000,$A27,'Données Suivi'!$O$2:$O$3000,"INVESTISSEMENT",'Données Suivi'!$H$2:$H$3000,"PREENGAGE") | J27: =SUMIFS('Données Suivi'!$J$2:$J$3000,'Données Suivi'!$A$2:$A$3000,$A27,'Données Suivi'!$O$2:$O$3000,"INVESTISSEMENT",'Données Suivi'!$H$2:$H$3000,"EN COURS D'ENGAGEMENT") | K27: =SUMIFS('Données Suivi'!$J$2:$J$3000,'Données Suivi'!$A$2:$A$3000,$A27,'Données Suivi'!$O$2:$O$3000,"INVESTISSEMENT",'Données Suivi'!$H$2:$H$3000,"EN COURS DE PREENGAGEMENT") | L27: =SUMIFS('Données Suivi'!$J$2:$J$3000,'Données Suivi'!$A$2:$A$3000,$A27,'Données Suivi'!$O$2:$O$3000,"INVESTISSEMENT",'Données Suivi'!$H$2:$H$3000,"NON ENGAGE") | M27: =H27+I27+J27+K27+L27 | N27: =G27+M27
A28: TOTAL GÉNÉRAL | B28: =SUM(B5:B27) | C28: =SUM(C5:C27) | D28: =SUM(D5:D27) | E28: =SUM(E5:E27) | F28: =SUM(F5:F27) | G28: =SUM(G5:G27) | H28: =SUM(H5:H27) | I28: =SUM(I5:I27) | ... N28: =SUM(N5:N27)

Sheet Filtre Interactif
A1: FILTRE INTERACTIF — DIRECTION / BCI / STATUT D'ENGAGEMENT
A3: 1) Choisir une Direction : | C3: DCT
A5: 2) Choisir un Type de BCI (à partir de la répartition ci-dessous) : | C5: CONTRAT
A7: Nombre de dossiers par Type de BCI — Direction sélectionnée
A8: Type de BCI | B8: Nb dossiers | C8: Montant (MAD) | D8: NATURE BUDGET | F8: CATEGORIE
D9: Fonctionnement | E9: Investissement | F9: Général | G9: PME | H9: Non concerné
A10: CONTRAT | B10: =COUNTIFS('Données Suivi'!$A$2:$A$3000,$C$3,'Données Suivi'!$C$2:$C$3000,$A10) | C10: =SUMIFS('Données Suivi'!$J$2:$J$3000,'Données Suivi'!$A$2:$A$3000,$C$3,'Données Suivi'!$C$2:$C$3000,$A10) | D10: =COUNTIFS('Données Suivi'!$A$2:$A$3000,$C$3,'Données Suivi'!$C$2:$C$3000,$A10,'Données Suivi'!$O$2:$O$3000,"FONCTIONNEMENT") | E10: =COUNTIFS('Données Suivi'!$A$2:$A$3000,$C$3,'Données Suivi'!$C$2:$C$3000,$A10,'Données Suivi'!$O$2:$O$3000,"INVESTISSEMENT") | F10: =COUNTIFS('Données Suivi'!$A$2:$A$3000,$C$3,'Données Suivi'!$C$2:$C$3000,$A10,'Données Suivi'!$P$2:$P$3000,"GENERAL") | G10: =COUNTIFS('Données Suivi'!$A$2:$A$3000,$C$3,'Données Suivi'!$C$2:$C$3000,$A10,'Données Suivi'!$P$2:$P$3000,"PME") | H10: =COUNTIFS('Données Suivi'!$A$2:$A$3000,$C$3,'Données Suivi'!$C$2:$C$3000,$A10,'Données Suivi'!$P$2:$P$3000,"NON CONCERNE")
A11: AOO-M | B11: =COUNTIFS('Données Suivi'!$A$2:$A$3000,$C$3,'Données Suivi'!$C$2:$C$3000,$A11) | C11: =SUMIFS('Données Suivi'!$J$2:$J$3000,'Données Suivi'!$A$2:$A$3000,$C$3,'Données Suivi'!$C$2:$C$3000,$A11) | D11: =COUNTIFS('Données Suivi'!$A$2:$A$3000,$C$3,'Données Suivi'!$C$2:$C$3000,$A11,'Données Suivi'!$O$2:$O$3000,"FONCTIONNEMENT") | E11: =COUNTIFS('Données Suivi'!$A$2:$A$3000,$C$3,'Données Suivi'!$C$2:$C$3000,$A11,'Données Suivi'!$O$2:$O$3000,"INVESTISSEMENT") | F11: =COUNTIFS('Données Suivi'!$A$2:$A$3000,$C$3,'Données Suivi'!$C$2:$C$3000,$A11,'Données Suivi'!$P$2:$P$3000,"GENERAL") | G11: =COUNTIFS('Données Suivi'!$A$2:$A$3000,$C$3,'Données Suivi'!$C$2:$C$3000,$A11,'Données Suivi'!$P$2:$P$3000,"PME") | H11: =COUNTIFS('Données Suivi'!$A$2:$A$3000,$C$3,'Données Suivi'!$C$2:$C$3000,$A11,'Données Suivi'!$P$2:$P$3000,"NON CONCERNE")
A12: AOO-CT | B12: =COUNTIFS('Données Suivi'!$A$2:$A$3000,$C$3,'Données Suivi'!$C$2:$C$3000,$A12) | C12: =SUMIFS('Données Suivi'!$J$2:$J$3000,'Données Suivi'!$A$2:$A$3000,$C$3,'Données Suivi'!$C$2:$C$3000,$A12) | D12: =COUNTIFS('Données Suivi'!$A$2:$A$3000,$C$3,'Données Suivi'!$C$2:$C$3000,$A12,'Données Suivi'!$O$2:$O$3000,"FONCTIONNEMENT") | E12: =COUNTIFS('Données Suivi'!$A$2:$A$3000,$C$3,'Données Suivi'!$C$2:$C$3000,$A12,'Données Suivi'!$O$2:$O$3000,"INVESTISSEMENT") | F12: =COUNTIFS('Données Suivi'!$A$2:$A$3000,$C$3,'Données Suivi'!$C$2:$C$3000,$A12,'Données Suivi'!$P$2:$P$3000,"GENERAL") | G12: =COUNTIFS('Données Suivi'!$A$2:$A$3000,$C$3,'Données Suivi'!$C$2:$C$3000,$A12,'Données Suivi'!$P$2:$P$3000,"PME") | H12: =COUNTIFS('Données Suivi'!$A$2:$A$3000,$C$3,'Données Suivi'!$C$2:$C$3000,$A12,'Données Suivi'!$P$2:$P$3000,"NON CONCERNE")
A13: BCL | B13: =COUNTIFS('Données Suivi'!$A$2:$A$3000,$C$3,'Données Suivi'!$C$2:$C$3000,$A13) | C13: =SUMIFS('Données Suivi'!$J$2:$J$3000,'Données Suivi'!$A$2:$A$3000,$C$3,'Données Suivi'!$C$2:$C$3000,$A13) | D13: =COUNTIFS('Données Suivi'!$A$2:$A$3000,$C$3,'Données Suivi'!$C$2:$C$3000,$A13,'Données Suivi'!$O$2:$O$3000,"FONCTIONNEMENT") | E13: =COUNTIFS('Données Suivi'!$A$2:$A$3000,$C$3,'Données Suivi'!$C$2:$C$3000,$A13,'Données Suivi'!$O$2:$O$3000,"INVESTISSEMENT") | F13: =COUNTIFS('Données Suivi'!$A$2:$A$3000,$C$3,'Données Suivi'!$C$2:$C$3000,$A13,'Données Suivi'!$P$2:$P$3000,"GENERAL") | G13: =COUNTIFS('Données Suivi'!$A$2:$A$3000,$C$3,'Données Suivi'!$C$2:$C$3000,$A13,'Données Suivi'!$P$2:$P$3000,"PME") | H13: =COUNTIFS('Données Suivi'!$A$2:$A$3000,$C$3,'Données Suivi'!$C$2:$C$3000,$A13,'Données Suivi'!$P$2:$P$3000,"NON CONCERNE")
A14: BCI | B14: =COUNTIFS('Données Suivi'!$A$2:$A$3000,$C$3,'Données Suivi'!$C$2:$C$3000,$A14) | C14: =SUMIFS('Données Suivi'!$J$2:$J$3000,'Données Suivi'!$A$2:$A$3000,$C$3,'Données Suivi'!$C$2:$C$3000,$A14) | D14: =COUNTIFS('Données Suivi'!$A$2:$A$3000,$C$3,'Données Suivi'!$C$2:$C$3000,$A14,'Données Suivi'!$O$2:$O$3000,"FONCTIONNEMENT") | E14: =COUNTIFS('Données Suivi'!$A$2:$A$3000,$C$3,'Données Suivi'!$C$2:$C$3000,$A14,'Données Suivi'!$O$2:$O$3000,"INVESTISSEMENT") | F14: =COUNTIFS('Données Suivi'!$A$2:$A$3000,$C$3,'Données Suivi'!$C$2:$C$3000,$A14,'Données Suivi'!$P$2:$P$3000,"GENERAL") | G14: =COUNTIFS('Données Suivi'!$A$2:$A$3000,$C$3,'Données Suivi'!$C$2:$C$3000,$A14,'Données Suivi'!$P$2:$P$3000,"PME") | H14: =COUNTIFS('Données Suivi'!$A$2:$A$3000,$C$3,'Données Suivi'!$C$2:$C$3000,$A14,'Données Suivi'!$P$2:$P$3000,"NON CONCERNE")
A15: CA | B15: =COUNTIFS('Données Suivi'!$A$2:$A$3000,$C$3,'Données Suivi'!$C$2:$C$3000,$A15) | C15: =SUMIFS('Données Suivi'!$J$2:$J$3000,'Données Suivi'!$A$2:$A$3000,$C$3,'Données Suivi'!$C$2:$C$3000,$A15) | D15: =COUNTIFS('Données Suivi'!$A$2:$A$3000,$C$3,'Données Suivi'!$C$2:$C$3000,$A15,'Données Suivi'!$O$2:$O$3000,"FONCTIONNEMENT") | E15: =COUNTIFS('Données Suivi'!$A$2:$A$3000,$C$3,'Données Suivi'!$C$2:$C$3000,$A15,'Données Suivi'!$O$2:$O$3000,"INVESTISSEMENT") | F15: =COUNTIFS('Données Suivi'!$A$2:$A$3000,$C$3,'Données Suivi'!$C$2:$C$3000,$A15,'Données Suivi'!$P$2:$P$3000,"GENERAL") | G15: =COUNTIFS('Données Suivi'!$A$2:$A$3000,$C$3,'Données Suivi'!$C$2:$C$3000,$A15,'Données Suivi'!$P$2:$P$3000,"PME") | H15: =COUNTIFS('Données Suivi'!$A$2:$A$3000,$C$3,'Données Suivi'!$C$2:$C$3000,$A15,'Données Suivi'!$P$2:$P$3000,"NON CONCERNE")
A16: TOTAL direction | B16: =SUM(B10:B15) | C16: =SUM(C10:C15) | D16: =SUM(D10:D15) | E16: =SUM(E10:E15) | F16: =SUM(F10:F15) | G16: =SUM(G10:G15) | H16: =SUM(H10:H15)
A18: Répartition par Statut d'Engagement — Direction + Type de BCI sélectionnés
A19: Statut d'Engagement | B19: Nb dossiers | C19: Montant Fonctionnement (MAD) | D19: Montant Investissement (MAD)
A20: NON ENGAGE | B20: =COUNTIFS('Données Suivi'!$A$2:$A$3000,$C$3,'Données Suivi'!$C$2:$C$3000,$C$5,'Données Suivi'!$H$2:$H$3000,$A20) | C20: =SUMIFS('Données Suivi'!$J$2:$J$3000,'Données Suivi'!$A$2:$A$3000,$C$3,'Données Suivi'!$C$2:$C$3000,$C$5,'Données Suivi'!$H$2:$H$3000,$A20,'Données Suivi'!$O$2:$O$3000,"FONCTIONNEMENT") | D20: =SUMIFS('Données Suivi'!$J$2:$J$3000,'Données Suivi'!$A$2:$A$3000,$C$3,'Données Suivi'!$C$2:$C$3000,$C$5,'Données Suivi'!$H$2:$H$3000,$A20,'Données Suivi'!$O$2:$O$3000,"INVESTISSEMENT")
A21: EN COURS DE PREENGAGEMENT | B21: =COUNTIFS('Données Suivi'!$A$2:$A$3000,$C$3,'Données Suivi'!$C$2:$C$3000,$C$5,'Données Suivi'!$H$2:$H$3000,$A21) | C21: =SUMIFS('Données Suivi'!$J$2:$J$3000,'Données Suivi'!$A$2:$A$3000,$C$3,'Données Suivi'!$C$2:$C$3000,$C$5,'Données Suivi'!$H$2:$H$3000,$A21,'Données Suivi'!$O$2:$O$3000,"FONCTIONNEMENT") | D21: =SUMIFS('Données Suivi'!$J$2:$J$3000,'Données Suivi'!$A$2:$A$3000,$C$3,'Données Suivi'!$C$2:$C$3000,$C$5,'Données Suivi'!$H$2:$H$3000,$A21,'Données Suivi'!$O$2:$O$3000,"INVESTISSEMENT")
A22: PREENGAGE | B22: =COUNTIFS('Données Suivi'!$A$2:$A$3000,$C$3,'Données Suivi'!$C$2:$C$3000,$C$5,'Données Suivi'!$H$2:$H$3000,$A22) | C22: =SUMIFS('Données Suivi'!$J$2:$J$3000,'Données Suivi'!$A$2:$A$3000,$C$3,'Données Suivi'!$C$2:$C$3000,$C$5,'Données Suivi'!$H$2:$H$3000,$A22,'Données Suivi'!$O$2:$O$3000,"FONCTIONNEMENT") | D22: =SUMIFS('Données Suivi'!$J$2:$J$3000,'Données Suivi'!$A$2:$A$3000,$C$3,'Données Suivi'!$C$2:$C$3000,$C$5,'Données Suivi'!$H$2:$H$3000,$A22,'Données Suivi'!$O$2:$O$3000,"INVESTISSEMENT")
A23: EN COURS D'ENGAGEMENT | B23: =COUNTIFS('Données Suivi'!$A$2:$A$3000,$C$3,'Données Suivi'!$C$2:$C$3000,$C$5,'Données Suivi'!$H$2:$H$3000,$A23) | C23: =SUMIFS('Données Suivi'!$J$2:$J$3000,'Données Suivi'!$A$2:$A$3000,$C$3,'Données Suivi'!$C$2:$C$3000,$C$5,'Données Suivi'!$H$2:$H$3000,$A23,'Données Suivi'!$O$2:$O$3000,"FONCTIONNEMENT") | D23: =SUMIFS('Données Suivi'!$J$2:$J$3000,'Données Suivi'!$A$2:$A$3000,$C$3,'Données Suivi'!$C$2:$C$3000,$C$5,'Données Suivi'!$H$2:$H$3000,$A23,'Données Suivi'!$O$2:$O$3000,"INVESTISSEMENT")
A24: ENGAGE | B24: =COUNTIFS('Données Suivi'!$A$2:$A$3000,$C$3,'Données Suivi'!$C$2:$C$3000,$C$5,'Données Suivi'!$H$2:$H$3000,$A24) | C24: =SUMIFS('Données Suivi'!$J$2:$J$3000,'Données Suivi'!$A$2:$A$3000,$C$3,'Données Suivi'!$C$2:$C$3000,$C$5,'Données Suivi'!$H$2:$H$3000,$A24,'Données Suivi'!$O$2:$O$3000,"FONCTIONNEMENT") | D24: =SUMIFS('Données Suivi'!$J$2:$J$3000,'Données Suivi'!$A$2:$A$3000,$C$3,'Données Suivi'!$C$2:$C$3000,$C$5,'Données Suivi'!$H$2:$H$3000,$A24,'Données Suivi'!$O$2:$O$3000,"INVESTISSEMENT")
A25: TOTAL direction + BCI | B25: =SUM(B20:B24) | C25: =SUM(C20:C24) | D25: =SUM(D20:D24)
A27: Détail des dossiers Non Engagé (Statut Support d'Engagement) — Direction sélectionnée
A28: Statut Support (Non Engagé) | B28: Nb dossiers | C28: Montant (MAD)
A29: INFRUCTUEUX | B29: =COUNTIFS('Données Suivi'!$A$2:$A$3000,$C$3,'Données Suivi'!$H$2:$H$3000,"NON ENGAGE",'Données Suivi'!$E$2:$E$3000,$A29) | C29: =SUMIFS('Données Suivi'!$J$2:$J$3000,'Données Suivi'!$A$2:$A$3000,$C$3,'Données Suivi'!$H$2:$H$3000,"NON ENGAGE",'Données Suivi'!$E$2:$E$3000,$A29)
A30: ANNULE | B30: =COUNTIFS('Données Suivi'!$A$2:$A$3000,$C$3,'Données Suivi'!$H$2:$H$3000,"NON ENGAGE",'Données Suivi'!$E$2:$E$3000,$A30) | C30: =SUMIFS('Données Suivi'!$J$2:$J$3000,'Données Suivi'!$A$2:$A$3000,$C$3,'Données Suivi'!$H$2:$H$3000,"NON ENGAGE",'Données Suivi'!$E$2:$E$3000,$A30)
A31: EN SIGNATURE | B31: =COUNTIFS('Données Suivi'!$A$2:$A$3000,$C$3,'Données Suivi'!$H$2:$H$3000,"NON ENGAGE",'Données Suivi'!$E$2:$E$3000,$A31) | C31: =SUMIFS('Données Suivi'!$J$2:$J$3000,'Données Suivi'!$A$2:$A$3000,$C$3,'Données Suivi'!$H$2:$H$3000,"NON ENGAGE",'Données Suivi'!$E$2:$E$3000,$A31)
A32: TOTAL Non Engagé — direction | B32: =SUM(B29:B31) | C32: =SUM(C29:C31)
A34: Détail des dossiers Infructueux / Annulé — Direction sélectionnée
A35: Objet | B35: Réf | C35: BCI | D35: Statut Support | E35: Montant (MAD) | F35: Date Fiche
A36: =IF($T36="","",INDEX('Données Suivi'!$D$2:$D$3000,$T36)) | B36: =IF($T36="","",INDEX('Données Suivi'!$B$2:$B$3000,$T36)) | C36: =IF($T36="","",INDEX('Données Suivi'!$C$2:$C$3000,$T36)) | D36: =IF($T36="","",INDEX('Données Suivi'!$E$2:$E$3000,$T36)) | E36: =IF($T36="","",INDEX('Données Suivi'!$J$2:$J$3000,$T36)) | F36: =IF($T36="","",INDEX('Données Suivi'!$K$2:$K$3000,$T36)) | T36: =IFERROR(MATCH($C$3&"|"&1,'Données Suivi'!$Q$2:$Q$3000,0),"")
A37: =IF($T37="","",INDEX('Données Suivi'!$D$2:$D$3000,$T37)) | B37: =IF($T37="","",INDEX('Données Suivi'!$B$2:$B$3000,$T37)) | C37: =IF($T37="","",INDEX('Données Suivi'!$C$2:$C$3000,$T37)) | D37: =IF($T37="","",INDEX('Données Suivi'!$E$2:$E$3000,$T37)) | E37: =IF($T37="","",INDEX('Données Suivi'!$J$2:$J$3000,$T37)) | F37: =IF($T37="","",INDEX('Données Suivi'!$K$2:$K$3000,$T37)) | T37: =IFERROR(MATCH($C$3&"|"&2,'Données Suivi'!$Q$2:$Q$3000,0),"")
A38: =IF($T38="","",INDEX('Données Suivi'!$D$2:$D$3000,$T38)) | B38: =IF($T38="","",INDEX('Données Suivi'!$B$2:$B$3000,$T38)) | C38: =IF($T38="","",INDEX('Données Suivi'!$C$2:$C$3000,$T38)) | D38: =IF($T38="","",INDEX('Données Suivi'!$E$2:$E$3000,$T38)) | E38: =IF($T38="","",INDEX('Données Suivi'!$J$2:$J$3000,$T38)) | F38: =IF($T38="","",INDEX('Données Suivi'!$K$2:$K$3000,$T38)) | T38: =IFERROR(MATCH($C$3&"|"&3,'Données Suivi'!$Q$2:$Q$3000,0),"")
A39: =IF($T39="","",INDEX('Données Suivi'!$D$2:$D$3000,$T39)) | B39: =IF($T39="","",INDEX('Données Suivi'!$B$2:$B$3000,$T39)) | C39: =IF($T39="","",INDEX('Données Suivi'!$C$2:$C$3000,$T39)) | D39: =IF($T39="","",INDEX('Données Suivi'!$E$2:$E$3000,$T39)) | E39: =IF($T39="","",INDEX('Données Suivi'!$J$2:$J$3000,$T39)) | F39: =IF($T39="","",INDEX('Données Suivi'!$K$2:$K$3000,$T39)) | T39: =IFERROR(MATCH($C$3&"|"&4,'Données Suivi'!$Q$2:$Q$3000,0),"")
A40: =IF($T40="","",INDEX('Données Suivi'!$D$2:$D$3000,$T40)) | B40: =IF($T40="","",INDEX('Données Suivi'!$B$2:$B$3000,$T40)) | C40: =IF($T40="","",INDEX('Données Suivi'!$C$2:$C$3000,$T40)) | D40: =IF($T40="","",INDEX('Données Suivi'!$E$2:$E$3000,$T40)) | E40: =IF($T40="","",INDEX('Données Suivi'!$J$2:$J$3000,$T40)) | F40: =IF($T40="","",INDEX('Données Suivi'!$K$2:$K$3000,$T40)) | T40: =IFERROR(MATCH($C$3&"|"&5,'Données Suivi'!$Q$2:$Q$3000,0),"")
A41: =IF($T41="","",INDEX('Données Suivi'!$D$2:$D$3000,$T41)) | B41: =IF($T41="","",INDEX('Données Suivi'!$B$2:$B$3000,$T41)) | C41: =IF($T41="","",INDEX('Données Suivi'!$C$2:$C$3000,$T41)) | D41: =IF($T41="","",INDEX('Données Suivi'!$E$2:$E$3000,$T41)) | E41: =IF($T41="","",INDEX('Données Suivi'!$J$2:$J$3000,$T41)) | F41: =IF($T41="","",INDEX('Données Suivi'!$K$2:$K$3000,$T41)) | T41: =IFERROR(MATCH($C$3&"|"&6,'Données Suivi'!$Q$2:$Q$3000,0),"")
A42: =IF($T42="","",INDEX('Données Suivi'!$D$2:$D$3000,$T42)) | B42: =IF($T42="","",INDEX('Données Suivi'!$B$2:$B$3000,$T42)) | C42: =IF($T42="","",INDEX('Données Suivi'!$C$2:$C$3000,$T42)) | D42: =IF($T42="","",INDEX('Données Suivi'!$E$2:$E$3000,$T42)) | E42: =IF($T42="","",INDEX('Données Suivi'!$J$2:$J$3000,$T42)) | F42: =IF($T42="","",INDEX('Données Suivi'!$K$2:$K$3000,$T42)) | T42: =IFERROR(MATCH($C$3&"|"&7,'Données Suivi'!$Q$2:$Q$3000,0),"")
A43: =IF($T43="","",INDEX('Données Suivi'!$D$2:$D$3000,$T43)) | B43: =IF($T43="","",INDEX('Données Suivi'!$B$2:$B$3000,$T43)) | C43: =IF($T43="","",INDEX('Données Suivi'!$C$2:$C$3000,$T43)) | D43: =IF($T43="","",INDEX('Données Suivi'!$E$2:$E$3000,$T43)) | E43: =IF($T43="","",INDEX('Données Suivi'!$J$2:$J$3000,$T43)) | F43: =IF($T43="","",INDEX('Données Suivi'!$K$2:$K$3000,$T43)) | T43: =IFERROR(MATCH($C$3&"|"&8,'Données Suivi'!$Q$2:$Q$3000,0),"")
A44: =IF($T44="","",INDEX('Données Suivi'!$D$2:$D$3000,$T44)) | B44: =IF($T44="","",INDEX('Données Suivi'!$B$2:$B$3000,$T44)) | C44: =IF($T44="","",INDEX('Données Suivi'!$C$2:$C$3000,$T44)) | D44: =IF($T44="","",INDEX('Données Suivi'!$E$2:$E$3000,$T44)) | E44: =IF($T44="","",INDEX('Données Suivi'!$J$2:$J$3000,$T44)) | F44: =IF($T44="","",INDEX('Données Suivi'!$K$2:$K$3000,$T44)) | T44: =IFERROR(MATCH($C$3&"|"&9,'Données Suivi'!$Q$2:$Q$3000,0),"")
A45: =IF($T45="","",INDEX('Données Suivi'!$D$2:$D$3000,$T45)) | B45: =IF($T45="","",INDEX('Données Suivi'!$B$2:$B$3000,$T45)) | C45: =IF($T45="","",INDEX('Données Suivi'!$C$2:$C$3000,$T45)) | D45: =IF($T45="","",INDEX('Données Suivi'!$E$2:$E$3000,$T45)) | E45: =IF($T45="","",INDEX('Données Suivi'!$J$2:$J$3000,$T45)) | F45: =IF($T45="","",INDEX('Données Suivi'!$K$2:$K$3000,$T45)) | T45: =IFERROR(MATCH($C$3&"|"&10,'Données Suivi'!$Q$2:$Q$3000,0),"")
A46: =IF($T46="","",INDEX('Données Suivi'!$D$2:$D$3000,$T46)) | B46: =IF($T46="","",INDEX('Données Suivi'!$B$2:$B$3000,$T46)) | C46: =IF($T46="","",INDEX('Données Suivi'!$C$2:$C$3000,$T46)) | D46: =IF($T46="","",INDEX('Données Suivi'!$E$2:$E$3000,$T46)) | E46: =IF($T46="","",INDEX('Données Suivi'!$J$2:$J$3000,$T46)) | F46: =IF($T46="","",INDEX('Données Suivi'!$K$2:$K$3000,$T46)) | T46: =IFERROR(MATCH($C$3&"|"&11,'Données Suivi'!$Q$2:$Q$3000,0),"")
...

Sheet Tableau de Bord Suivi
A1: TABLEAU DE BORD DE SUIVI — ETAT D'ENGAGEMENTS 2026
A3: Nb dossiers total | C3: Montant total (MAD) | E3: Nb directions | G3: Taux d'engagement (montant) | I3: Montant restant à engager | K3: Nb dossiers en cours (à suivre)
A4: =COUNTIF('Données Suivi'!A2:A3000,"?*") | C4: =SUM('Données Suivi'!J2:J3000) | E4: =SUMPRODUCT(('Données Suivi'!$A$2:$A$3000<>"")/COUNTIF('Données Suivi'!$A$2:$A$3000,'Données Suivi'!$A$2:$A$3000&"")) | G4: =SUMIF('Données Suivi'!M2:M3000,"Engagé",'Données Suivi'!J2:J3000)/SUM('Données Suivi'!J2:J3000) | I4: =SUMIF('Données Suivi'!M2:M3000,"En cours",'Données Suivi'!J2:J3000) | K4: =COUNTIF('Données Suivi'!M2:M3000,"En cours")
A6: Nb clôturés sans suite | C6: Ancienneté moy. dossiers en cours (j)
A7: =COUNTIF('Données Suivi'!M2:M3000,"Clôturé sans suite") | C7: =AVERAGEIFS('Données Suivi'!L2:L3000,'Données Suivi'!M2:M3000,"En cours",'Données Suivi'!L2:L3000,">=0")
A10: Répartition des dossiers par Direction et par BCI (type d'achat) — Nombre de dossiers
A11: Direction | B11: CONTRAT | C11: AOO-M | D11: AOO-CT | E11: BCL | F11: BCI | G11: CA | H11: TOTAL
A12: ARRIYADIA | B12: =COUNTIFS('Données Suivi'!$A$2:$A$3000,$A12,'Données Suivi'!$C$2:$C$3000,"CONTRAT") | C12: =COUNTIFS('Données Suivi'!$A$2:$A$3000,$A12,'Données Suivi'!$C$2:$C$3000,"AOO-M") | D12: =COUNTIFS('Données Suivi'!$A$2:$A$3000,$A12,'Données Suivi'!$C$2:$C$3000,"AOO-CT") | E12: =COUNTIFS('Données Suivi'!$A$2:$A$3000,$A12,'Données Suivi'!$C$2:$C$3000,"BCL") | F12: =COUNTIFS('Données Suivi'!$A$2:$A$3000,$A12,'Données Suivi'!$C$2:$C$3000,"BCI") | G12: =COUNTIFS('Données Suivi'!$A$2:$A$3000,$A12,'Données Suivi'!$C$2:$C$3000,"CA") | H12: =COUNTIF('Données Suivi'!$A$2:$A$3000,$A12)
A13: ASSADISSA | B13: =COUNTIFS('Données Suivi'!$A$2:$A$3000,$A13,'Données Suivi'!$C$2:$C$3000,"CONTRAT") | C13: =COUNTIFS('Données Suivi'!$A$2:$A$3000,$A13,'Données Suivi'!$C$2:$C$3000,"AOO-M") | D13: =COUNTIFS('Données Suivi'!$A$2:$A$3000,$A13,'Données Suivi'!$C$2:$C$3000,"AOO-CT") | E13: =COUNTIFS('Données Suivi'!$A$2:$A$3000,$A13,'Données Suivi'!$C$2:$C$3000,"BCL") | F13: =COUNTIFS('Données Suivi'!$A$2:$A$3000,$A13,'Données Suivi'!$C$2:$C$3000,"BCI") | G13: =COUNTIFS('Données Suivi'!$A$2:$A$3000,$A13,'Données Suivi'!$C$2:$C$3000,"CA") | H13: =COUNTIF('Données Suivi'!$A$2:$A$3000,$A13)
A14: DA | B14: =COUNTIFS('Données Suivi'!$A$2:$A$3000,$A14,'Données Suivi'!$C$2:$C$3000,"CONTRAT") | C14: =COUNTIFS('Données Suivi'!$A$2:$A$3000,$A14,'Données Suivi'!$C$2:$C$3000,"AOO-M") | D14: =COUNTIFS('Données Suivi'!$A$2:$A$3000,$A14,'Données Suivi'!$C$2:$C$3000,"AOO-CT") | E14: =COUNTIFS('Données Suivi'!$A$2:$A$3000,$A14,'Données Suivi'!$C$2:$C$3000,"BCL") | F14: =COUNTIFS('Données Suivi'!$A$2:$A$3000,$A14,'Données Suivi'!$C$2:$C$3000,"BCI") | G14: =COUNTIFS('Données Suivi'!$A$2:$A$3000,$A14,'Données Suivi'!$C$2:$C$3000,"CA") | H14: =COUNTIF('Données Suivi'!$A$2:$A$3000,$A14)
A15: DACG | B15: =COUNTIFS('Données Suivi'!$A$2:$A$3000,$A15,'Données Suivi'!$C$2:$C$3000,"CONTRAT") | C15: =COUNTIFS('Données Suivi'!$A$2:$A$3000,$A15,'Données Suivi'!$C$2:$C$3000,"AOO-M") | D15: =COUNTIFS('Données Suivi'!$A$2:$A$3000,$A15,'Données Suivi'!$C$2:$C$3000,"AOO-CT") | E15: =COUNTIFS('Données Suivi'!$A$2:$A$3000,$A15,'Données Suivi'!$C$2:$C$3000,"BCL") | F15: =COUNTIFS('Données Suivi'!$A$2:$A$3000,$A15,'Données Suivi'!$C$2:$C$3000,"BCI") | G15: =COUNTIFS('Données Suivi'!$A$2:$A$3000,$A15,'Données Suivi'!$C$2:$C$3000,"CA") | H15: =COUNTIF('Données Suivi'!$A$2:$A$3000,$A15)
A16: DAR | B16: =COUNTIFS('Données Suivi'!$A$2:$A$3000,$A16,'Données Suivi'!$C$2:$C$3000,"CONTRAT") | C16: =COUNTIFS('Données Suivi'!$A$2:$A$3000,$A16,'Données Suivi'!$C$2:$C$3000,"AOO-M") | D16: =COUNTIFS('Données Suivi'!$A$2:$A$3000,$A16,'Données Suivi'!$C$2:$C$3000,"AOO-CT") | E16: =COUNTIFS('Données Suivi'!$A$2:$A$3000,$A16,'Données Suivi'!$C$2:$C$3000,"BCL") | F16: =COUNTIFS('Données Suivi'!$A$2:$A$3000,$A16,'Données Suivi'!$C$2:$C$3000,"BCI") | G16: =COUNTIFS('Données Suivi'!$A$2:$A$3000,$A16,'Données Suivi'!$C$2:$C$3000,"CA") | H16: =COUNTIF('Données Suivi'!$A$2:$A$3000,$A16)
A17: DCPA | B17: =COUNTIFS('Données Suivi'!$A$2:$A$3000,$A17,'Données Suivi'!$C$2:$C$3000,"CONTRAT") | C17: =COUNTIFS('Données Suivi'!$A$2:$A$3000,$A17,'Données Suivi'!$C$2:$C$3000,"AOO-M") | D17: =COUNTIFS('Données Suivi'!$A$2:$A$3000,$A17,'Données Suivi'!$C$2:$C$3000,"AOO-CT") | E17: =COUNTIFS('Données Suivi'!$A$2:$A$3000,$A17,'Données Suivi'!$C$2:$C$3000,"BCL") | F17: =COUNTIFS('Données Suivi'!$A$2:$A$3000,$A17,'Données Suivi'!$C$2:$C$3000,"BCI") | G17: =COUNTIFS('Données Suivi'!$A$2:$A$3000,$A17,'Données Suivi'!$C$2:$C$3000,"CA") | H17: =COUNTIF('Données Suivi'!$A$2:$A$3000,$A17)
A18: DCRI | B18: =COUNTIFS('Données Suivi'!$A$2:$A$3000,$A18,'Données Suivi'!$C$2:$C$3000,"CONTRAT") | C18: =COUNTIFS('Données Suivi'!$A$2:$A$3000,$A18,'Données Suivi'!$C$2:$C$3000,"AOO-M") | D18: =COUNTIFS('Données Suivi'!$A$2:$A$3000,$A18,'Données Suivi'!$C$2:$C$3000,"AOO-CT") | E18: =COUNTIFS('Données Suivi'!$A$2:$A$3000,$A18,'Données Suivi'!$C$2:$C$3000,"BCL") | F18: =COUNTIFS('Données Suivi'!$A$2:$A$3000,$A18,'Données Suivi'!$C$2:$C$3000,"BCI") | G18: =COUNTIFS('Données Suivi'!$A$2:$A$3000,$A18,'Données Suivi'!$C$2:$C$3000,"CA") | H18: =COUNTIF('Données Suivi'!$A$2:$A$3000,$A18)
A19: DCT | B19: =COUNTIFS('Données Suivi'!$A$2:$A$3000,$A19,'Données Suivi'!$C$2:$C$3000,"CONTRAT") | C19: =COUNTIFS('Données Suivi'!$A$2:$A$3000,$A19,'Données Suivi'!$C$2:$C$3000,"AOO-M") | D19: =COUNTIFS('Données Suivi'!$A$2:$A$3000,$A19,'Données Suivi'!$C$2:$C$3000,"AOO-CT") | E19: =COUNTIFS('Données Suivi'!$A$2:$A$3000,$A19,'Données Suivi'!$C$2:$C$3000,"BCL") | F19: =COUNTIFS('Données Suivi'!$A$2:$A$3000,$A19,'Données Suivi'!$C$2:$C$3000,"BCI") | G19: =COUNTIFS('Données Suivi'!$A$2:$A$3000,$A19,'Données Suivi'!$C$2:$C$3000,"CA") | H19: =COUNTIF('Données Suivi'!$A$2:$A$3000,$A19)
A20: DG | B20: =COUNTIFS('Données Suivi'!$A$2:$A$3000,$A20,'Données Suivi'!$C$2:$C$3000,"CONTRAT") | C20: =COUNTIFS('Données Suivi'!$A$2:$A$3000,$A20,'Données Suivi'!$C$2:$C$3000,"AOO-M") | D20: =COUNTIFS('Données Suivi'!$A$2:$A$3000,$A20,'Données Suivi'!$C$2:$C$3000,"AOO-CT") | E20: =COUNTIFS('Données Suivi'!$A$2:$A$3000,$A20,'Données Suivi'!$C$2:$C$3000,"BCL") | F20: =COUNTIFS('Données Suivi'!$A$2:$A$3000,$A20,'Données Suivi'!$C$2:$C$3000,"BCI") | G20: =COUNTIFS('Données Suivi'!$A$2:$A$3000,$A20,'Données Suivi'!$C$2:$C$3000,"CA") | H20: =COUNTIF('Données Suivi'!$A$2:$A$3000,$A20)
A21: DINFORADIO | B21: =COUNTIFS('Données Suivi'!$A$2:$A$3000,$A21,'Données Suivi'!$C$2:$C$3000,"CONTRAT") | C21: =COUNTIFS('Données Suivi'!$A$2:$A$3000,$A21,'Données Suivi'!$C$2:$C$3000,"AOO-M") | D21: =COUNTIFS('Données Suivi'!$A$2:$A$3000,$A21,'Données Suivi'!$C$2:$C$3000,"AOO-CT") | E21: =COUNTIFS('Données Suivi'!$A$2:$A$3000,$A21,'Données Suivi'!$C$2:$C$3000,"BCL") | F21: =COUNTIFS('Données Suivi'!$A$2:$A$3000,$A21,'Données Suivi'!$C$2:$C$3000,"BCI") | G21: =COUNTIFS('Données Suivi'!$A$2:$A$3000,$A21,'Données Suivi'!$C$2:$C$3000,"CA") | H21: =COUNTIF('Données Suivi'!$A$2:$A$3000,$A21)
A22: DINFOTV | B22: =COUNTIFS('Données Suivi'!$A$2:$A$3000,$A22,'Données Suivi'!$C$2:$C$3000,"CONTRAT") | C22: =COUNTIFS('Données Suivi'!$A$2:$A$3000,$A22,'Données Suivi'!$C$2:$C$3000,"AOO-M") | D22: =COUNTIFS('Données Suivi'!$A$2:$A$3000,$A22,'Données Suivi'!$C$2:$C$3000,"AOO-CT") | E22: =COUNTIFS('Données Suivi'!$A$2:$A$3000,$A22,'Données Suivi'!$C$2:$C$3000,"BCL") | F22: =COUNTIFS('Données Suivi'!$A$2:$A$3000,$A22,'Données Suivi'!$C$2:$C$3000,"BCI") | G22: =COUNTIFS('Données Suivi'!$A$2:$A$3000,$A22,'Données Suivi'!$C$2:$C$3000,"CA") | H22: =COUNTIF('Données Suivi'!$A$2:$A$3000,$A22)
A23: DJURIDIQUE | B23: =COUNTIFS('Données Suivi'!$A$2:$A$3000,$A23,'Données Suivi'!$C$2:$C$3000,"CONTRAT") | C23: =COUNTIFS('Données Suivi'!$A$2:$A$3000,$A23,'Données Suivi'!$C$2:$C$3000,"AOO-M") | D23: =COUNTIFS('Données Suivi'!$A$2:$A$3000,$A23,'Données Suivi'!$C$2:$C$3000,"AOO-CT") | E23: =COUNTIFS('Données Suivi'!$A$2:$A$3000,$A23,'Données Suivi'!$C$2:$C$3000,"BCL") | F23: =COUNTIFS('Données Suivi'!$A$2:$A$3000,$A23,'Données Suivi'!$C$2:$C$3000,"BCI") | G23: =COUNTIFS('Données Suivi'!$A$2:$A$3000,$A23,'Données Suivi'!$C$2:$C$3000,"CA") | H23: =COUNTIF('Données Suivi'!$A$2:$A$3000,$A23)
... A34: TV LAAYOUNE | B34: =COUNTIFS('Données Suivi'!$A$2:$A$3000,$A34,'Données Suivi'!$C$2:$C$3000,"CONTRAT") | C34: =COUNTIFS('Données Suivi'!$A$2:$A$3000,$A34,'Données Suivi'!$C$2:$C$3000,"AOO-M") | D34: =COUNTIFS('Données Suivi'!$A$2:$A$3000,$A34,'Données Suivi'!$C$2:$C$3000,"AOO-CT") | E34: =COUNTIFS('Données Suivi'!$A$2:$A$3000,$A34,'Données Suivi'!$C$2:$C$3000,"BCL") | F34: =COUNTIFS('Données Suivi'!$A$2:$A$3000,$A34,'Données Suivi'!$C$2:$C$3000,"BCI") | G34: =COUNTIFS('Données Suivi'!$A$2:$A$3000,$A34,'Données Suivi'!$C$2:$C$3000,"CA") | H34: =COUNTIF('Données Suivi'!$A$2:$A$3000,$A34)
A35: TOTAL | B35: =SUM(B12:B34) | C35: =SUM(C12:C34) | D35: =SUM(D12:D34) | E35: =SUM(E12:E34) | F35: =SUM(F12:F34) | G35: =SUM(G12:G34) | H35: =SUM(H12:H34)
A37: Répartition des dossiers par Direction et par Statut d'Engagement — Nombre de dossiers
A38: Direction | B38: NON ENGAGE | C38: EN COURS DE PREENGAGEMENT | D38: PREENGAGE | E38: EN COURS D'ENGAGEMENT | F38: ENGAGE | G38: TOTAL
A39: ARRIYADIA | B39: =COUNTIFS('Données Suivi'!$A$2:$A$3000,$A39,'Données Suivi'!$H$2:$H$3000,"NON ENGAGE") | C39: =COUNTIFS('Données Suivi'!$A$2:$A$3000,$A39,'Données Suivi'!$H$2:$H$3000,"EN COURS DE PREENGAGEMENT") | D39: =COUNTIFS('Données Suivi'!$A$2:$A$3000,$A39,'Données Suivi'!$H$2:$H$3000,"PREENGAGE") | E39: =COUNTIFS('Données Suivi'!$A$2:$A$3000,$A39,'Données Suivi'!$H$2:$H$3000,"EN COURS D'ENGAGEMENT") | F39: =COUNTIFS('Données Suivi'!$A$2:$A$3000,$A39,'Données Suivi'!$H$2:$H$3000,"ENGAGE") | G39: =COUNTIF('Données Suivi'!$A$2:$A$3000,$A39)
A40: ASSADISSA | B40: =COUNTIFS('Données Suivi'!$A$2:$A$3000,$A40,'Données Suivi'!$H$2:$H$3000,"NON ENGAGE") | C40: =COUNTIFS('Données Suivi'!$A$2:$A$3000,$A40,'Données Suivi'!$H$2:$H$3000,"EN COURS DE PREENGAGEMENT") | D40: =COUNTIFS('Données Suivi'!$A$2:$A$3000,$A40,'Données Suivi'!$H$2:$H$3000,"PREENGAGE") | E40: =COUNTIFS('Données Suivi'!$A$2:$A$3000,$A40,'Données Suivi'!$H$2:$H$3000,"EN COURS D'ENGAGEMENT") | F40: =COUNTIFS('Données Suivi'!$A$2:$A$3000,$A40,'Données Suivi'!$H$2:$H$3000,"ENGAGE") | G40: =COUNTIF('Données Suivi'!$A$2:$A$3000,$A40)
A41: DA | B41: =COUNTIFS('Données Suivi'!$A$2:$A$3000,$A41,'Données Suivi'!$H$2:$H$3000,"NON ENGAGE") | C41: =COUNTIFS('Données Suivi'!$A$2:$A$3000,$A41,'Données Suivi'!$H$2:$H$3000,"EN COURS DE PREENGAGEMENT") | D41: =COUNTIFS('Données Suivi'!$A$2:$A$3000,$A41,'Données Suivi'!$H$2:$H$3000,"PREENGAGE") | E41: =COUNTIFS('Données Suivi'!$A$2:$A$3000,$A41,'Données Suivi'!$H$2:$H$3000,"EN COURS D'ENGAGEMENT") | F41: =COUNTIFS('Données Suivi'!$A$2:$A$3000,$A41,'Données Suivi'!$H$2:$H$3000,"ENGAGE") | G41: =COUNTIF('Données Suivi'!$A$2:$A$3000,$A41)
A42: DACG | B42: =COUNTIFS('Données Suivi'!$A$2:$A$3000,$A42,'Données Suivi'!$H$2:$H$3000,"NON ENGAGE") | C42: =COUNTIFS('Données Suivi'!$A$2:$A$3000,$A42,'Données Suivi'!$H$2:$H$3000,"EN COURS DE PREENGAGEMENT") | D42: =COUNTIFS('Données Suivi'!$A$2:$A$3000,$A42,'Données Suivi'!$H$2:$H$3000,"PREENGAGE") | E42: =COUNTIFS('Données Suivi'!$A$2:$A$3000,$A42,'Données Suivi'!$H$2:$H$3000,"EN COURS D'ENGAGEMENT") | F42: =COUNTIFS('Données Suivi'!$A$2:$A$3000,$A42,'Données Suivi'!$H$2:$H$3000,"ENGAGE") | G42: =COUNTIF('Données Suivi'!$A$2:$A$3000,$A42)
A43: DAR | B43: =COUNTIFS('Données Suivi'!$A$2:$A$3000,$A43,'Données Suivi'!$H$2:$H$3000,"NON ENGAGE") | C43: =COUNTIFS('Données Suivi'!$A$2:$A$3000,$A43,'Données Suivi'!$H$2:$H$3000,"EN COURS DE PREENGAGEMENT") | D43: =COUNTIFS('Données Suivi'!$A$2:$A$3000,$A43,'Données Suivi'!$H$2:$H$3000,"PREENGAGE") | E43: =COUNTIFS('Données Suivi'!$A$2:$A$3000,$A43,'Données Suivi'!$H$2:$H$3000,"EN COURS D'ENGAGEMENT") | F43: =COUNTIFS('Données Suivi'!$A$2:$A$3000,$A43,'Données Suivi'!$H$2:$H$3000,"ENGAGE") | G43: =COUNTIF('Données Suivi'!$A$2:$A$3000,$A43)
A44: DCPA | B44: =COUNTIFS('Données Suivi'!$A$2:$A$3000,$A44,'Données Suivi'!$H$2:$H$3000,"NON ENGAGE") | C44: =COUNTIFS('Données Suivi'!$A$2:$A$3000,$A44,'Données Suivi'!$H$2:$H$3000,"EN COURS DE PREENGAGEMENT") | D44: =COUNTIFS('Données Suivi'!$A$2:$A$3000,$A44,'Données Suivi'!$H$2:$H$3000,"PREENGAGE") | E44: =COUNTIFS('Données Suivi'!$A$2:$A$3000,$A44,'Données Suivi'!$H$2:$H$3000,"EN COURS D'ENGAGEMENT") | F44: =COUNTIFS('Données Suivi'!$A$2:$A$3000,$A44,'Données Suivi'!$H$2:$H$3000,"ENGAGE") | G44: =COUNTIF('Données Suivi'!$A$2:$A$3000,$A44)
A45: DCRI | B45: =COUNTIFS('Données Suivi'!$A$2:$A$3000,$A45,'Données Suivi'!$H$2:$H$3000,"NON ENGAGE") | C45: =COUNTIFS('Données Suivi'!$A$2:$A$3000,$A45,'Données Suivi'!$H$2:$H$3000,"EN COURS DE PREENGAGEMENT") | D45: =COUNTIFS('Données Suivi'!$A$2:$A$3000,$A45,'Données Suivi'!$H$2:$H$3000,"PREENGAGE") | E45: =COUNTIFS('Données Suivi'!$A$2:$A$3000,$A45,'Données Suivi'!$H$2:$H$3000,"EN COURS D'ENGAGEMENT") | F45: =COUNTIFS('Données Suivi'!$A$2:$A$3000,$A45,'Données Suivi'!$H$2:$H$3000,"ENGAGE") | G45: =COUNTIF('Données Suivi'!$A$2:$A$3000,$A45)
A46: DCT | B46: =COUNTIFS('Données Suivi'!$A$2:$A$3000,$A46,'Données Suivi'!$H$2:$H$3000,"NON ENGAGE") | C46: =COUNTIFS('Données Suivi'!$A$2:$A$3000,$A46,'Données Suivi'!$H$2:$H$3000,"EN COURS DE PREENGAGEMENT") | D46: =COUNTIFS('Données Suivi'!$A$2:$A$3000,$A46,'Données Suivi'!$H$2:$H$3000,"PREENGAGE") | E46: =COUNTIFS('Données Suivi'!$A$2:$A$3000,$A46,'Données Suivi'!$H$2:$H$3000,"EN COURS D'ENGAGEMENT") | F46: =COUNTIFS('Données Suivi'!$A$2:$A$3000,$A46,'Données Suivi'!$H$2:$H$3000,"ENGAGE") | G46: =COUNTIF('Données Suivi'!$A$2:$A$3000,$A46)
A47: DG | B47: =COUNTIFS('Données Suivi'!$A$2:$A$3000,$A47,'Données Suivi'!$H$2:$H$3000,"NON ENGAGE") | C47: =COUNTIFS('Données Suivi'!$A$2:$A$3000,$A47,'Données Suivi'!$H$2:$H$3000,"EN COURS DE PREENGAGEMENT") | D47: =COUNTIFS('Données Suivi'!$A$2:$A$3000,$A47,'Données Suivi'!$H$2:$H$3000,"PREENGAGE") | E47: =COUNTIFS('Données Suivi'!$A$2:$A$3000,$A47,'Données Suivi'!$H$2:$H$3000,"EN COURS D'ENGAGEMENT") | F47: =COUNTIFS('Données Suivi'!$A$2:$A$3000,$A47,'Données Suivi'!$H$2:$H$3000,"ENGAGE") | G47: =COUNTIF('Données Suivi'!$A$2:$A$3000,$A47)
A48: DINFORADIO | B48: =COUNTIFS('Données Suivi'!$A$2:$A$3000,$A48,'Données Suivi'!$H$2:$H$3000,"NON ENGAGE") | C48: =COUNTIFS('Données Suivi'!$A$2:$A$3000,$A48,'Données Suivi'!$H$2:$H$3000,"EN COURS DE PREENGAGEMENT") | D48: =COUNTIFS('Données Suivi'!$A$2:$A$3000,$A48,'Données Suivi'!$H$2:$H$3000,"PREENGAGE") | E48: =COUNTIFS('Données Suivi'!$A$2:$A$3000,$A48,'Données Suivi'!$H$2:$H$3000,"EN COURS D'ENGAGEMENT") | F48: =COUNTIFS('Données Suivi'!$A$2:$A$3000,$A48,'Données Suivi'!$H$2:$H$3000,"ENGAGE") | G48: =COUNTIF('Données Suivi'!$A$2:$A$3000,$A48)
A49: DINFOTV | B49: =COUNTIFS('Données Suivi'!$A$2:$A$3000,$A49,'Données Suivi'!$H$2:$H$3000,"NON ENGAGE") | C49: =COUNTIFS('Données Suivi'!$A$2:$A$3000,$A49,'Données Suivi'!$H$2:$H$3000,"EN COURS DE PREENGAGEMENT") | D49: =COUNTIFS('Données Suivi'!$A$2:$A$3000,$A49,'Données Suivi'!$H$2:$H$3000,"PREENGAGE") | E49: =COUNTIFS('Données Suivi'!$A$2:$A$3000,$A49,'Données Suivi'!$H$2:$H$3000,"EN COURS D'ENGAGEMENT") | F49: =COUNTIFS('Données Suivi'!$A$2:$A$3000,$A49,'Données Suivi'!$H$2:$H$3000,"ENGAGE") | G49: =COUNTIF('Données Suivi'!$A$2:$A$3000,$A49)
A50: DJURIDIQUE | B50: =COUNTIFS('Données Suivi'!$A$2:$A$3000,$A50,'Données Suivi'!$H$2:$H$3000,"NON ENGAGE") | C50: =COUNTIFS('Données Suivi'!$A$2:$A$3000,$A50,'Données Suivi'!$H$2:$H$3000,"EN COURS DE PREENGAGEMENT") | D50: =COUNTIFS('Données Suivi'!$A$2:$A$3000,$A50,'Données Suivi'!$H$2:$H$3000,"PREENGAGE") | E50: =COUNTIFS('Données Suivi'!$A$2:$A$3000,$A50,'Données Suivi'!$H$2:$H$3000,"EN COURS D'ENGAGEMENT") | F50: =COUNTIFS('Données Suivi'!$A$2:$A$3000,$A50,'Données Suivi'!$H$2:$H$3000,"ENGAGE") | G50: =COUNTIF('Données Suivi'!$A$2:$A$3000,$A50)
... A61: TV LAAYOUNE | B61: =COUNTIFS('Données Suivi'!$A$2:$A$3000,$A61,'Données Suivi'!$H$2:$H$3000,"NON ENGAGE") | C61: =COUNTIFS('Données Suivi'!$A$2:$A$3000,$A61,'Données Suivi'!$H$2:$H$3000,"EN COURS DE PREENGAGEMENT") | D61: =COUNTIFS('Données Suivi'!$A$2:$A$3000,$A61,'Données Suivi'!$H$2:$H$3000,"PREENGAGE") | E61: =COUNTIFS('Données Suivi'!$A$2:$A$3000,$A61,'Données Suivi'!$H$2:$H$3000,"EN COURS D'ENGAGEMENT") | F61: =COUNTIFS('Données Suivi'!$A$2:$A$3000,$A61,'Données Suivi'!$H$2:$H$3000,"ENGAGE") | G61: =COUNTIF('Données Suivi'!$A$2:$A$3000,$A61)
A62: TOTAL | B62: =SUM(B39:B61) | C62: =SUM(C39:C61) | D62: =SUM(D39:D61) | E62: =SUM(E39:E61) | F62: =SUM(F39:F61) | G62: =SUM(G39:G61)
A64: Taux d'engagement par Direction (montant)
A65: Direction | B65: Montant total (MAD) | C65: Montant engagé (MAD) | D65: Taux d'engagement
A66: ARRIYADIA | B66: =SUMIF('Données Suivi'!$A$2:$A$3000,$A66,'Données Suivi'!$J$2:$J$3000) | C66: =SUMIFS('Données Suivi'!$J$2:$J$3000,'Données Suivi'!$A$2:$A$3000,$A66,'Données Suivi'!$M$2:$M$3000,"Engagé") | D66: =IF(B66=0,"",C66/B66)
...

Sheet Parametres
A1: Type de Budget
A2: REPORT BUDGET ANNEE ANTERIEURE
A3: REPORT BUDGET EXCEP ANNEE ANTERIEURE
A4: Ordinaire
A5: Exceptionnel
A6: BUDGET
A7: FONCTIONNEMENT
A8: INVESTISSEMENT | C8: =IFERROR(B8/(B7+B8),0)
A9: Lignes Budget Fonctionnement
A10: Achats de productions et de programmes: Acquis définitive Programmes TV externes
A11: Achats de productions et de programmes: Acquis définitive pgm Radio externes
A12: Achats de productions et de programmes: Achats des programmes en co-production
A13: Achats de productions et de programmes: Achat des programmes en production interne - personnes physiques
A14: Achats de droits: Achats des droits de captation
A15: Achats de droits: Cession de Droits de sport
A16: Achats de matières et fournitures consommables
A17: Achats non stockés de matières et fournitures
A18: Prestations de service: Achat d'études
A19: Prestations de service: Achat prestations de services locales - personnes physiques
A20: Prestations de service: Achat prestations de services locales - sociétés
... A44: Autre Matériel et mobilier de bureau
A45: Estimation | B45: MAD | C45: %
A46: Estimation Total HT
A47: Ecart
A48: MNT Partiel | C48: =IFERROR(MTP/MTT,0)
A49: Total Marché HT
A50: DIRECTION | B50: PPA | C50: Marche
A51: TDF
A52: TDF -SITES
A53: TDF-EXP&MAIN
A54: DG
A55: DCT
A56: RSSI
A57: DPMG
A58: DRPSD
A59: DINFORADIO
A60: ARRIYADIA
A61: TV LAAYOUNE
A62: MAGHRIBIA
... A78: DSI
...

Sheet ENGAGEMENTS 2026
A1: ANNEE LANCEMENT | B1: DIRECTION | C1: REF | D1: BCI | E1: LOTS | F1: OBJET | G1: STATUT 1 | H1: STATUT SUPPORT D'ENGAGEMENT | I1: N° SUPPORT D'ENGAGEMENT | J1: CATEGORIES | K1: TYPE BUDGET | L1: BUDGET | M1: LIGNES BUDGETAIRES | N1: MONTANT PREENGAGE INITIAL | O1: ESTIMATION TTC | P1: ESTIMATION HT | Q1: NATURE BESOIN | R1: DEBUT REC | S1: FIN REC | T1: ADJUDICATAIRE / FRS | U1: ANNEE APPROBATION | V1: DATE DE LA FICHE | W1: DATE VISA | X1: DATE APPROB | Y1: MONTANT MARCHE HT PART EN MAD | Z1: MONTANT MARCHE HT PART EN DEVISES | AA1: MONTANT MARCHE TTC PART EN MAD | AB1: MONTANT MARCHE TTC PART EN DEVISES | AC1: TOTAL MARCHE HT TOTAL ENGAGE HT | AD1: TOTAL MARCHE TTC TOTAL ENGAGE TTC | AE1: STATUT D'ENGAGEMENT | AF1: Remarque (archive) | AG1: Reserve | AH1: PREVISION PPA HT | AI1: ECART ESTIMATION HT-PPA HT | AJ1: ECART ENGAGEMENT HT-PPA HT | AK1: ECART ESTIMATION eng/estim | AL1: ECART PPA enga/ppa | AM1: REMARQUE
A2: 2026 | B2: DRH | C2: EXCLUSIVITÉ | D2: CONTRAT | E2: 1 | F2: Convention SNRT-OFPPT pour la réalisation des EAP | G2: VALIDE | H2: APPROUVE | I2: 01/OFPPT/SNRT/2026 | J2: NON CONCERNE | K2: Ordinaire | L2: FONCTIONNEMENT | M2: Charges sociales diverses | Q2: BESOIN RECURRENT | T2: OFPPT | U2: 2026 | V2: 46030 | X2: 46066 | Y2: 829202 | Z2: 0 | AA2: 995042.4 | AB2: 0 | AC2: 829202 | AD2: 995042.4 | AE2: ENGAGE | AM2: « + 287 001 » - Budget PPA = 708 041,40 Dhs
