Workbook
Name ANN: Parametres!$A$116
Name ATR: Parametres!$A$129
Name BDG_DIR: #REF!
Name BDG_FAM: #REF!
Name BDG_MNT: #REF!
Name BDG_NAT: #REF!
Name BUDGET: 'ENGAGEMENTS 2026'!$M:$M
Name cc: Parametres!$A$80:$A$94
Name DIRECTION: #REF!
Name ENGAGE: Parametres!$A$99
Name Estimation: 'ENGAGEMENTS 2026'!$P:$P
Name Excep: Parametres!$A$5
Name FON: Parametres!$A$7
Name FONCTIONNEMENT: Parametres!$A$10:$A$32
Name INF: Parametres!$A$115
Name INV: Parametres!$A$8
Name INVESTISSEMENT: Parametres!$A$34:$A$44
Name LBDG: 'ENGAGEMENTS 2026'!$N:$N
Name MntENG: 'ENGAGEMENTS 2026'!$AE:$AE
Name MTP: Parametres!$B$48
Name MTT: Parametres!$B$46
Name NA: Parametres!$A$113
Name Ordn: Parametres!$A$4
Name PhaAo: Parametres!$A$134
Name PREENGAGE: Parametres!$A$97
Name qq: Parametres!$A$80:$A$94
Name SSENG: #REF!
Name StatutEng: 'ENGAGEMENTS 2026'!$AF:$AF
Name TypBudget: Parametres!$A$2:$A$5
Name TypeBudget: 'ENGAGEMENTS 2026'!$L:$L
Name xBesoin: Parametres!$A$146:$A$149
Name xBUDGET: Parametres!$A$7:$A$8
Name xCATEGORIES: Parametres!$A$137:$A$139
Name xDIRECTION: Parametres!$A$51:$A$78
Name xENG: Parametres!$A$99
Name XLB: Parametres!$A$80:$A$94
Name xNatype: Parametres!$A$142:$A$144
Name xRec: Parametres!$A$149
Name xStatut1: Parametres!$A$113:$A$118
Name xSTATUTSUP: Parametres!$A$128:$A$135
Name xStEng: Parametres!$A$96:$A$100
Name xTYPE1: Parametres!$A$102:$A$111
Name xTYPSUP: Parametres!$A$120:$A$126

Sheet Tableau de Bord
A1: TABLEAU DE BORD DES ENGAGEMENTS BUDGÉTAIRES 2026 — SNRT
A2: Montants en MAD TTC — calculés dynamiquement (SUMIFS) depuis la feuille « Données Suivi »
A3: DIRECTION | B3: FONCTIONNEMENT | H3: INVESTISSEMENT | N3: TOTAL GÉNÉRAL
B4: ENGAGE | C4: PREENGAGE | D4: EN COURS D'ENGAGEMENT | E4: EN COURS DE PREENGAGEMENT | F4: NON ENGAGE | G4: TOTAL FONC. | H4: ENGAGE | I4: PREENGAGE | J4: EN COURS D'ENGAGEMENT | K4: EN COURS DE PREENGAGEMENT | L4: NON ENGAGE | M4: TOTAL INVE.
A5: ARRIYADIA | B5: =SUMIFS('Données Suivi'!$J$2:$J$3000,'Données Suivi'!$A$2:$A$3000,$A5,'Données Suivi'!$O$2:$O$3000,"FONCTIONNEMENT",'Données Suivi'!$H$2:$H$3000,"ENGAGE") -> 1.8046948e+08 | C5: =SUMIFS('Données Suivi'!$J$2:$J$3000,'Données Suivi'!$A$2:$A$3000,$A5,'Données Suivi'!$O$2:$O$3000,"FONCTIONNEMENT",'Données Suivi'!$H$2:$H$3000,"PREENGAGE") -> 0 | D5: =SUMIFS('Données Suivi'!$J$2:$J$3000,'Données Suivi'!$A$2:$A$3000,$A5,'Données Suivi'!$O$2:$O$3000,"FONCTIONNEMENT",'Données Suivi'!$H$2:$H$3000,"EN COURS D'ENGAGEMENT") -> 73224.48 | E5: =SUMIFS('Données Suivi'!$J$2:$J$3000,'Données Suivi'!$A$2:$A$3000,$A5,'Données Suivi'!$O$2:$O$3000,"FONCTIONNEMENT",'Données Suivi'!$H$2:$H$3000,"EN COURS DE PREENGAGEMENT") -> 0 | F5: =SUMIFS('Données Suivi'!$J$2:$J$3000,'Données Suivi'!$A$2:$A$3000,$A5,'Données Suivi'!$O$2:$O$3000,"FONCTIONNEMENT",'Données Suivi'!$H$2:$H$3000,"NON ENGAGE") -> 0 | G5: =B5+C5+D5+E5+F5 -> 1.805427e+08 | H5: =SUMIFS('Données Suivi'!$J$2:$J$3000,'Données Suivi'!$A$2:$A$3000,$A5,'Données Suivi'!$O$2:$O$3000,"INVESTISSEMENT",'Données Suivi'!$H$2:$H$3000,"ENGAGE") -> 0 | I5: =SUMIFS('Données Suivi'!$J$2:$J$3000,'Données Suivi'!$A$2:$A$3000,$A5,'Données Suivi'!$O$2:$O$3000,"INVESTISSEMENT",'Données Suivi'!$H$2:$H$3000,"PREENGAGE") -> 0 | J5: =SUMIFS('Données Suivi'!$J$2:$J$3000,'Données Suivi'!$A$2:$A$3000,$A5,'Données Suivi'!$O$2:$O$3000,"INVESTISSEMENT",'Données Suivi'!$H$2:$H$3000,"EN COURS D'ENGAGEMENT") -> 0 | K5: =SUMIFS('Données Suivi'!$J$2:$J$3000,'Données Suivi'!$A$2:$A$3000,$A5,'Données Suivi'!$O$2:$O$3000,"INVESTISSEMENT",'Données Suivi'!$H$2:$H$3000,"EN COURS DE PREENGAGEMENT") -> 0 | L5: =SUMIFS('Données Suivi'!$J$2:$J$3000,'Données Suivi'!$A$2:$A$3000,$A5,'Données Suivi'!$O$2:$O$3000,"INVESTISSEMENT",'Données Suivi'!$H$2:$H$3000,"NON ENGAGE") -> 0 | M5: =H5+I5+J5+K5+L5 -> 0 | N5: =G5+M5 -> 1.805427e+08
A6: ASSADISSA | B6: =SUMIFS('Données Suivi'!$J$2:$J$3000,'Données Suivi'!$A$2:$A$3000,$A6,'Données Suivi'!$O$2:$O$3000,"FONCTIONNEMENT",'Données Suivi'!$H$2:$H$3000,"ENGAGE") -> 8022706.3 | C6: =SUMIFS('Données Suivi'!$J$2:$J$3000,'Données Suivi'!$A$2:$A$3000,$A6,'Données Suivi'!$O$2:$O$3000,"FONCTIONNEMENT",'Données Suivi'!$H$2:$H$3000,"PREENGAGE") -> 0 | D6: =SUMIFS('Données Suivi'!$J$2:$J$3000,'Données Suivi'!$A$2:$A$3000,$A6,'Données Suivi'!$O$2:$O$3000,"FONCTIONNEMENT",'Données Suivi'!$H$2:$H$3000,"EN COURS D'ENGAGEMENT") -> 0 | E6: =SUMIFS('Données Suivi'!$J$2:$J$3000,'Données Suivi'!$A$2:$A$3000,$A6,'Données Suivi'!$O$2:$O$3000,"FONCTIONNEMENT",'Données Suivi'!$H$2:$H$3000,"EN COURS DE PREENGAGEMENT") -> 0 | F6: =SUMIFS('Données Suivi'!$J$2:$J$3000,'Données Suivi'!$A$2:$A$3000,$A6,'Données Suivi'!$O$2:$O$3000,"FONCTIONNEMENT",'Données Suivi'!$H$2:$H$3000,"NON ENGAGE") -> 0 | G6: =B6+C6+D6+E6+F6 -> 8022706.3 | H6: =SUMIFS('Données Suivi'!$J$2:$J$3000,'Données Suivi'!$A$2:$A$3000,$A6,'Données Suivi'!$O$2:$O$3000,"INVESTISSEMENT",'Données Suivi'!$H$2:$H$3000,"ENGAGE") -> 0 | I6: =SUMIFS('Données Suivi'!$J$2:$J$3000,'Données Suivi'!$A$2:$A$3000,$A6,'Données Suivi'!$O$2:$O$3000,"INVESTISSEMENT",'Données Suivi'!$H$2:$H$3000,"PREENGAGE") -> 0 | J6: =SUMIFS('Données Suivi'!$J$2:$J$3000,'Données Suivi'!$A$2:$A$3000,$A6,'Données Suivi'!$O$2:$O$3000,"INVESTISSEMENT",'Données Suivi'!$H$2:$H$3000,"EN COURS D'ENGAGEMENT") -> 0 | K6: =SUMIFS('Données Suivi'!$J$2:$J$3000,'Données Suivi'!$A$2:$A$3000,$A6,'Données Suivi'!$O$2:$O$3000,"INVESTISSEMENT",'Données Suivi'!$H$2:$H$3000,"EN COURS DE PREENGAGEMENT") -> 0 | L6: =SUMIFS('Données Suivi'!$J$2:$J$3000,'Données Suivi'!$A$2:$A$3000,$A6,'Données Suivi'!$O$2:$O$3000,"INVESTISSEMENT",'Données Suivi'!$H$2:$H$3000,"NON ENGAGE") -> 0 | M6: =H6+I6+J6+K6+L6 -> 0 | N6: =G6+M6 -> 8022706.3
A7: DA | B7: =SUMIFS('Données Suivi'!$J$2:$J$3000,'Données Suivi'!$A$2:$A$3000,$A7,'Données Suivi'!$O$2:$O$3000,"FONCTIONNEMENT",'Données Suivi'!$H$2:$H$3000,"ENGAGE") -> 427760 | C7: =SUMIFS('Données Suivi'!$J$2:$J$3000,'Données Suivi'!$A$2:$A$3000,$A7,'Données Suivi'!$O$2:$O$3000,"FONCTIONNEMENT",'Données Suivi'!$H$2:$H$3000,"PREENGAGE") -> 0 | D7: =SUMIFS('Données Suivi'!$J$2:$J$3000,'Données Suivi'!$A$2:$A$3000,$A7,'Données Suivi'!$O$2:$O$3000,"FONCTIONNEMENT",'Données Suivi'!$H$2:$H$3000,"EN COURS D'ENGAGEMENT") -> 0 | E7: =SUMIFS('Données Suivi'!$J$2:$J$3000,'Données Suivi'!$A$2:$A$3000,$A7,'Données Suivi'!$O$2:$O$3000,"FONCTIONNEMENT",'Données Suivi'!$H$2:$H$3000,"EN COURS DE PREENGAGEMENT") -> 0 | F7: =SUMIFS('Données Suivi'!$J$2:$J$3000,'Données Suivi'!$A$2:$A$3000,$A7,'Données Suivi'!$O$2:$O$3000,"FONCTIONNEMENT",'Données Suivi'!$H$2:$H$3000,"NON ENGAGE") -> 0 | G7: =B7+C7+D7+E7+F7 -> 427760 | H7: =SUMIFS('Données Suivi'!$J$2:$J$3000,'Données Suivi'!$A$2:$A$3000,$A7,'Données Suivi'!$O$2:$O$3000,"INVESTISSEMENT",'Données Suivi'!$H$2:$H$3000,"ENGAGE") -> 0 | I7: =SUMIFS('Données Suivi'!$J$2:$J$3000,'Données Suivi'!$A$2:$A$3000,$A7,'Données Suivi'!$O$2:$O$3000,"INVESTISSEMENT",'Données Suivi'!$H$2:$H$3000,"PREENGAGE") -> 0 | J7: =SUMIFS('Données Suivi'!$J$2:$J$3000,'Données Suivi'!$A$2:$A$3000,$A7,'Données Suivi'!$O$2:$O$3000,"INVESTISSEMENT",'Données Suivi'!$H$2:$H$3000,"EN COURS D'ENGAGEMENT") -> 0 | K7: =SUMIFS('Données Suivi'!$J$2:$J$3000,'Données Suivi'!$A$2:$A$3000,$A7,'Données Suivi'!$O$2:$O$3000,"INVESTISSEMENT",'Données Suivi'!$H$2:$H$3000,"EN COURS DE PREENGAGEMENT") -> 0 | L7: =SUMIFS('Données Suivi'!$J$2:$J$3000,'Données Suivi'!$A$2:$A$3000,$A7,'Données Suivi'!$O$2:$O$3000,"INVESTISSEMENT",'Données Suivi'!$H$2:$H$3000,"NON ENGAGE") -> 0 | M7: =H7+I7+J7+K7+L7 -> 0 | N7: =G7+M7 -> 427760
A8: DACG | B8: =SUMIFS('Données Suivi'!$J$2:$J$3000,'Données Suivi'!$A$2:$A$3000,$A8,'Données Suivi'!$O$2:$O$3000,"FONCTIONNEMENT",'Données Suivi'!$H$2:$H$3000,"ENGAGE") -> 318500 | C8: =SUMIFS('Données Suivi'!$J$2:$J$3000,'Données Suivi'!$A$2:$A$3000,$A8,'Données Suivi'!$O$2:$O$3000,"FONCTIONNEMENT",'Données Suivi'!$H$2:$H$3000,"PREENGAGE") -> 0 | D8: =SUMIFS('Données Suivi'!$J$2:$J$3000,'Données Suivi'!$A$2:$A$3000,$A8,'Données Suivi'!$O$2:$O$3000,"FONCTIONNEMENT",'Données Suivi'!$H$2:$H$3000,"EN COURS D'ENGAGEMENT") -> 0 | E8: =SUMIFS('Données Suivi'!$J$2:$J$3000,'Données Suivi'!$A$2:$A$3000,$A8,'Données Suivi'!$O$2:$O$3000,"FONCTIONNEMENT",'Données Suivi'!$H$2:$H$3000,"EN COURS DE PREENGAGEMENT") -> 144000 | F8: =SUMIFS('Données Suivi'!$J$2:$J$3000,'Données Suivi'!$A$2:$A$3000,$A8,'Données Suivi'!$O$2:$O$3000,"FONCTIONNEMENT",'Données Suivi'!$H$2:$H$3000,"NON ENGAGE") -> 0 | G8: =B8+C8+D8+E8+F8 -> 462500 | H8: =SUMIFS('Données Suivi'!$J$2:$J$3000,'Données Suivi'!$A$2:$A$3000,$A8,'Données Suivi'!$O$2:$O$3000,"INVESTISSEMENT",'Données Suivi'!$H$2:$H$3000,"ENGAGE") -> 0 | I8: =SUMIFS('Données Suivi'!$J$2:$J$3000,'Données Suivi'!$A$2:$A$3000,$A8,'Données Suivi'!$O$2:$O$3000,"INVESTISSEMENT",'Données Suivi'!$H$2:$H$3000,"PREENGAGE") -> 0 | J8: =SUMIFS('Données Suivi'!$J$2:$J$3000,'Données Suivi'!$A$2:$A$3000,$A8,'Données Suivi'!$O$2:$O$3000,"INVESTISSEMENT",'Données Suivi'!$H$2:$H$3000,"EN COURS D'ENGAGEMENT") -> 0 | K8: =SUMIFS('Données Suivi'!$J$2:$J$3000,'Données Suivi'!$A$2:$A$3000,$A8,'Données Suivi'!$O$2:$O$3000,"INVESTISSEMENT",'Données Suivi'!$H$2:$H$3000,"EN COURS DE PREENGAGEMENT") -> 0 | L8: =SUMIFS('Données Suivi'!$J$2:$J$3000,'Données Suivi'!$A$2:$A$3000,$A8,'Données Suivi'!$O$2:$O$3000,"INVESTISSEMENT",'Données Suivi'!$H$2:$H$3000,"NON ENGAGE") -> 0 | M8: =H8+I8+J8+K8+L8 -> 0 | N8: =G8+M8 -> 462500
A9: DAR | B9: =SUMIFS('Données Suivi'!$J$2:$J$3000,'Données Suivi'!$A$2:$A$3000,$A9,'Données Suivi'!$O$2:$O$3000,"FONCTIONNEMENT",'Données Suivi'!$H$2:$H$3000,"ENGAGE") -> 108000 | C9: =SUMIFS('Données Suivi'!$J$2:$J$3000,'Données Suivi'!$A$2:$A$3000,$A9,'Données Suivi'!$O$2:$O$3000,"FONCTIONNEMENT",'Données Suivi'!$H$2:$H$3000,"PREENGAGE") -> 0 | D9: =SUMIFS('Données Suivi'!$J$2:$J$3000,'Données Suivi'!$A$2:$A$3000,$A9,'Données Suivi'!$O$2:$O$3000,"FONCTIONNEMENT",'Données Suivi'!$H$2:$H$3000,"EN COURS D'ENGAGEMENT") -> 0 | E9: =SUMIFS('Données Suivi'!$J$2:$J$3000,'Données Suivi'!$A$2:$A$3000,$A9,'Données Suivi'!$O$2:$O$3000,"FONCTIONNEMENT",'Données Suivi'!$H$2:$H$3000,"EN COURS DE PREENGAGEMENT") -> 0 | F9: =SUMIFS('Données Suivi'!$J$2:$J$3000,'Données Suivi'!$A$2:$A$3000,$A9,'Données Suivi'!$O$2:$O$3000,"FONCTIONNEMENT",'Données Suivi'!$H$2:$H$3000,"NON ENGAGE") -> 0 | G9: =B9+C9+D9+E9+F9 -> 108000 | H9: =SUMIFS('Données Suivi'!$J$2:$J$3000,'Données Suivi'!$A$2:$A$3000,$A9,'Données Suivi'!$O$2:$O$3000,"INVESTISSEMENT",'Données Suivi'!$H$2:$H$3000,"ENGAGE") -> 0 | I9: =SUMIFS('Données Suivi'!$J$2:$J$3000,'Données Suivi'!$A$2:$A$3000,$A9,'Données Suivi'!$O$2:$O$3000,"INVESTISSEMENT",'Données Suivi'!$H$2:$H$3000,"PREENGAGE") -> 0 | J9: =SUMIFS('Données Suivi'!$J$2:$J$3000,'Données Suivi'!$A$2:$A$3000,$A9,'Données Suivi'!$O$2:$O$3000,"INVESTISSEMENT",'Données Suivi'!$H$2:$H$3000,"EN COURS D'ENGAGEMENT") -> 0 | K9: =SUMIFS('Données Suivi'!$J$2:$J$3000,'Données Suivi'!$A$2:$A$3000,$A9,'Données Suivi'!$O$2:$O$3000,"INVESTISSEMENT",'Données Suivi'!$H$2:$H$3000,"EN COURS DE PREENGAGEMENT") -> 0 | L9: =SUMIFS('Données Suivi'!$J$2:$J$3000,'Données Suivi'!$A$2:$A$3000,$A9,'Données Suivi'!$O$2:$O$3000,"INVESTISSEMENT",'Données Suivi'!$H$2:$H$3000,"NON ENGAGE") -> 0 | M9: =H9+I9+J9+K9+L9 -> 0 | N9: =G9+M9 -> 108000
A10: DCPA | B10: =SUMIFS('Données Suivi'!$J$2:$J$3000,'Données Suivi'!$A$2:$A$3000,$A10,'Données Suivi'!$O$2:$O$3000,"FONCTIONNEMENT",'Données Suivi'!$H$2:$H$3000,"ENGAGE") -> 61489072 | C10: =SUMIFS('Données Suivi'!$J$2:$J$3000,'Données Suivi'!$A$2:$A$3000,$A10,'Données Suivi'!$O$2:$O$3000,"FONCTIONNEMENT",'Données Suivi'!$H$2:$H$3000,"PREENGAGE") -> 0 | D10: =SUMIFS('Données Suivi'!$J$2:$J$3000,'Données Suivi'!$A$2:$A$3000,$A10,'Données Suivi'!$O$2:$O$3000,"FONCTIONNEMENT",'Données Suivi'!$H$2:$H$3000,"EN COURS D'ENGAGEMENT") -> 9889068 | E10: =SUMIFS('Données Suivi'!$J$2:$J$3000,'Données Suivi'!$A$2:$A$3000,$A10,'Données Suivi'!$O$2:$O$3000,"FONCTIONNEMENT",'Données Suivi'!$H$2:$H$3000,"EN COURS DE PREENGAGEMENT") -> 0 | F10: =SUMIFS('Données Suivi'!$J$2:$J$3000,'Données Suivi'!$A$2:$A$3000,$A10,'Données Suivi'!$O$2:$O$3000,"FONCTIONNEMENT",'Données Suivi'!$H$2:$H$3000,"NON ENGAGE") -> 0 | G10: =B10+C10+D10+E10+F10 -> 71378140 | H10: =SUMIFS('Données Suivi'!$J$2:$J$3000,'Données Suivi'!$A$2:$A$3000,$A10,'Données Suivi'!$O$2:$O$3000,"INVESTISSEMENT",'Données Suivi'!$H$2:$H$3000,"ENGAGE") -> 0 | I10: =SUMIFS('Données Suivi'!$J$2:$J$3000,'Données Suivi'!$A$2:$A$3000,$A10,'Données Suivi'!$O$2:$O$3000,"INVESTISSEMENT",'Données Suivi'!$H$2:$H$3000,"PREENGAGE") -> 0 | J10: =SUMIFS('Données Suivi'!$J$2:$J$3000,'Données Suivi'!$A$2:$A$3000,$A10,'Données Suivi'!$O$2:$O$3000,"INVESTISSEMENT",'Données Suivi'!$H$2:$H$3000,"EN COURS D'ENGAGEMENT") -> 0 | K10: =SUMIFS('Données Suivi'!$J$2:$J$3000,'Données Suivi'!$A$2:$A$3000,$A10,'Données Suivi'!$O$2:$O$3000,"INVESTISSEMENT",'Données Suivi'!$H$2:$H$3000,"EN COURS DE PREENGAGEMENT") -> 0 | L10: =SUMIFS('Données Suivi'!$J$2:$J$3000,'Données Suivi'!$A$2:$A$3000,$A10,'Données Suivi'!$O$2:$O$3000,"INVESTISSEMENT",'Données Suivi'!$H$2:$H$3000,"NON ENGAGE") -> 0 | M10: =H10+I10+J10+K10+L10 -> 0 | N10: =G10+M10 -> 71378140
A11: DCRI | B11: =SUMIFS('Données Suivi'!$J$2:$J$3000,'Données Suivi'!$A$2:$A$3000,$A11,'Données Suivi'!$O$2:$O$3000,"FONCTIONNEMENT",'Données Suivi'!$H$2:$H$3000,"ENGAGE") -> 318240 | C11: =SUMIFS('Données Suivi'!$J$2:$J$3000,'Données Suivi'!$A$2:$A$3000,$A11,'Données Suivi'!$O$2:$O$3000,"FONCTIONNEMENT",'Données Suivi'!$H$2:$H$3000,"PREENGAGE") -> 0 | D11: =SUMIFS('Données Suivi'!$J$2:$J$3000,'Données Suivi'!$A$2:$A$3000,$A11,'Données Suivi'!$O$2:$O$3000,"FONCTIONNEMENT",'Données Suivi'!$H$2:$H$3000,"EN COURS D'ENGAGEMENT") -> 0 | E11: =SUMIFS('Données Suivi'!$J$2:$J$3000,'Données Suivi'!$A$2:$A$3000,$A11,'Données Suivi'!$O$2:$O$3000,"FONCTIONNEMENT",'Données Suivi'!$H$2:$H$3000,"EN COURS DE PREENGAGEMENT") -> 0 | F11: =SUMIFS('Données Suivi'!$J$2:$J$3000,'Données Suivi'!$A$2:$A$3000,$A11,'Données Suivi'!$O$2:$O$3000,"FONCTIONNEMENT",'Données Suivi'!$H$2:$H$3000,"NON ENGAGE") -> 0 | G11: =B11+C11+D11+E11+F11 -> 318240 | H11: =SUMIFS('Données Suivi'!$J$2:$J$3000,'Données Suivi'!$A$2:$A$3000,$A11,'Données Suivi'!$O$2:$O$3000,"INVESTISSEMENT",'Données Suivi'!$H$2:$H$3000,"ENGAGE") -> 0 | I11: =SUMIFS('Données Suivi'!$J$2:$J$3000,'Données Suivi'!$A$2:$A$3000,$A11,'Données Suivi'!$O$2:$O$3000,"INVESTISSEMENT",'Données Suivi'!$H$2:$H$3000,"PREENGAGE") -> 0 | J11: =SUMIFS('Données Suivi'!$J$2:$J$3000,'Données Suivi'!$A$2:$A$3000,$A11,'Données Suivi'!$O$2:$O$3000,"INVESTISSEMENT",'Données Suivi'!$H$2:$H$3000,"EN COURS D'ENGAGEMENT") -> 0 | K11: =SUMIFS('Données Suivi'!$J$2:$J$3000,'Données Suivi'!$A$2:$A$3000,$A11,'Données Suivi'!$O$2:$O$3000,"INVESTISSEMENT",'Données Suivi'!$H$2:$H$3000,"EN COURS DE PREENGAGEMENT") -> 0 | L11: =SUMIFS('Données Suivi'!$J$2:$J$3000,'Données Suivi'!$A$2:$A$3000,$A11,'Données Suivi'!$O$2:$O$3000,"INVESTISSEMENT",'Données Suivi'!$H$2:$H$3000,"NON ENGAGE") -> 0 | M11: =H11+I11+J11+K11+L11 -> 0 | N11: =G11+M11 -> 318240
A12: DCT | B12: =SUMIFS('Données Suivi'!$J$2:$J$3000,'Données Suivi'!$A$2:$A$3000,$A12,'Données Suivi'!$O$2:$O$3000,"FONCTIONNEMENT",'Données Suivi'!$H$2:$H$3000,"ENGAGE") -> 8945954.8 | C12: =SUMIFS('Données Suivi'!$J$2:$J$3000,'Données Suivi'!$A$2:$A$3000,$A12,'Données Suivi'!$O$2:$O$3000,"FONCTIONNEMENT",'Données Suivi'!$H$2:$H$3000,"PREENGAGE") -> 135388.8 | D12: =SUMIFS('Données Suivi'!$J$2:$J$3000,'Données Suivi'!$A$2:$A$3000,$A12,'Données Suivi'!$O$2:$O$3000,"FONCTIONNEMENT",'Données Suivi'!$H$2:$H$3000,"EN COURS D'ENGAGEMENT") -> 970159.68 | E12: =SUMIFS('Données Suivi'!$J$2:$J$3000,'Données Suivi'!$A$2:$A$3000,$A12,'Données Suivi'!$O$2:$O$3000,"FONCTIONNEMENT",'Données Suivi'!$H$2:$H$3000,"EN COURS DE PREENGAGEMENT") -> 0 | F12: =SUMIFS('Données Suivi'!$J$2:$J$3000,'Données Suivi'!$A$2:$A$3000,$A12,'Données Suivi'!$O$2:$O$3000,"FONCTIONNEMENT",'Données Suivi'!$H$2:$H$3000,"NON ENGAGE") -> 616128 | G12: =B12+C12+D12+E12+F12 -> 10667631 | H12: =SUMIFS('Données Suivi'!$J$2:$J$3000,'Données Suivi'!$A$2:$A$3000,$A12,'Données Suivi'!$O$2:$O$3000,"INVESTISSEMENT",'Données Suivi'!$H$2:$H$3000,"ENGAGE") -> 10359432 | I12: =SUMIFS('Données Suivi'!$J$2:$J$3000,'Données Suivi'!$A$2:$A$3000,$A12,'Données Suivi'!$O$2:$O$3000,"INVESTISSEMENT",'Données Suivi'!$H$2:$H$3000,"PREENGAGE") -> 27705715 | J12: =SUMIFS('Données Suivi'!$J$2:$J$3000,'Données Suivi'!$A$2:$A$3000,$A12,'Données Suivi'!$O$2:$O$3000,"INVESTISSEMENT",'Données Suivi'!$H$2:$H$3000,"EN COURS D'ENGAGEMENT") -> 2017741.2 | K12: =SUMIFS('Données Suivi'!$J$2:$J$3000,'Données Suivi'!$A$2:$A$3000,$A12,'Données Suivi'!$O$2:$O$3000,"INVESTISSEMENT",'Données Suivi'!$H$2:$H$3000,"EN COURS DE PREENGAGEMENT") -> 11556000 | L12: =SUMIFS('Données Suivi'!$J$2:$J$3000,'Données Suivi'!$A$2:$A$3000,$A12,'Données Suivi'!$O$2:$O$3000,"INVESTISSEMENT",'Données Suivi'!$H$2:$H$3000,"NON ENGAGE") -> 24966744 | M12: =H12+I12+J12+K12+L12 -> 76605632 | N12: =G12+M12 -> 87273264
A13: DG | B13: =SUMIFS('Données Suivi'!$J$2:$J$3000,'Données Suivi'!$A$2:$A$3000,$A13,'Données Suivi'!$O$2:$O$3000,"FONCTIONNEMENT",'Données Suivi'!$H$2:$H$3000,"ENGAGE") -> 576000 | C13: =SUMIFS('Données Suivi'!$J$2:$J$3000,'Données Suivi'!$A$2:$A$3000,$A13,'Données Suivi'!$O$2:$O$3000,"FONCTIONNEMENT",'Données Suivi'!$H$2:$H$3000,"PREENGAGE") -> 0 | D13: =SUMIFS('Données Suivi'!$J$2:$J$3000,'Données Suivi'!$A$2:$A$3000,$A13,'Données Suivi'!$O$2:$O$3000,"FONCTIONNEMENT",'Données Suivi'!$H$2:$H$3000,"EN COURS D'ENGAGEMENT") -> 0 | E13: =SUMIFS('Données Suivi'!$J$2:$J$3000,'Données Suivi'!$A$2:$A$3000,$A13,'Données Suivi'!$O$2:$O$3000,"FONCTIONNEMENT",'Données Suivi'!$H$2:$H$3000,"EN COURS DE PREENGAGEMENT") -> 0 | F13: =SUMIFS('Données Suivi'!$J$2:$J$3000,'Données Suivi'!$A$2:$A$3000,$A13,'Données Suivi'!$O$2:$O$3000,"FONCTIONNEMENT",'Données Suivi'!$H$2:$H$3000,"NON ENGAGE") -> 0 | G13: =B13+C13+D13+E13+F13 -> 576000 | H13: =SUMIFS('Données Suivi'!$J$2:$J$3000,'Données Suivi'!$A$2:$A$3000,$A13,'Données Suivi'!$O$2:$O$3000,"INVESTISSEMENT",'Données Suivi'!$H$2:$H$3000,"ENGAGE") -> 0 | I13: =SUMIFS('Données Suivi'!$J$2:$J$3000,'Données Suivi'!$A$2:$A$3000,$A13,'Données Suivi'!$O$2:$O$3000,"INVESTISSEMENT",'Données Suivi'!$H$2:$H$3000,"PREENGAGE") -> 0 | J13: =SUMIFS('Données Suivi'!$J$2:$J$3000,'Données Suivi'!$A$2:$A$3000,$A13,'Données Suivi'!$O$2:$O$3000,"INVESTISSEMENT",'Données Suivi'!$H$2:$H$3000,"EN COURS D'ENGAGEMENT") -> 0 | K13: =SUMIFS('Données Suivi'!$J$2:$J$3000,'Données Suivi'!$A$2:$A$3000,$A13,'Données Suivi'!$O$2:$O$3000,"INVESTISSEMENT",'Données Suivi'!$H$2:$H$3000,"EN COURS DE PREENGAGEMENT") -> 0 | L13: =SUMIFS('Données Suivi'!$J$2:$J$3000,'Données Suivi'!$A$2:$A$3000,$A13,'Données Suivi'!$O$2:$O$3000,"INVESTISSEMENT",'Données Suivi'!$H$2:$H$3000,"NON ENGAGE") -> 0 | M13: =H13+I13+J13+K13+L13 -> 0 | N13: =G13+M13 -> 576000
A14: DINFORADIO | B14: =SUMIFS('Données Suivi'!$J$2:$J$3000,'Données Suivi'!$A$2:$A$3000,$A14,'Données Suivi'!$O$2:$O$3000,"FONCTIONNEMENT",'Données Suivi'!$H$2:$H$3000,"ENGAGE") -> 2648832.5 | C14: =SUMIFS('Données Suivi'!$J$2:$J$3000,'Données Suivi'!$A$2:$A$3000,$A14,'Données Suivi'!$O$2:$O$3000,"FONCTIONNEMENT",'Données Suivi'!$H$2:$H$3000,"PREENGAGE") -> 0 | D14: =SUMIFS('Données Suivi'!$J$2:$J$3000,'Données Suivi'!$A$2:$A$3000,$A14,'Données Suivi'!$O$2:$O$3000,"FONCTIONNEMENT",'Données Suivi'!$H$2:$H$3000,"EN COURS D'ENGAGEMENT") -> 0 | E14: =SUMIFS('Données Suivi'!$J$2:$J$3000,'Données Suivi'!$A$2:$A$3000,$A14,'Données Suivi'!$O$2:$O$3000,"FONCTIONNEMENT",'Données Suivi'!$H$2:$H$3000,"EN COURS DE PREENGAGEMENT") -> 0 | F14: =SUMIFS('Données Suivi'!$J$2:$J$3000,'Données Suivi'!$A$2:$A$3000,$A14,'Données Suivi'!$O$2:$O$3000,"FONCTIONNEMENT",'Données Suivi'!$H$2:$H$3000,"NON ENGAGE") -> 0 | G14: =B14+C14+D14+E14+F14 -> 2648832.5 | H14: =SUMIFS('Données Suivi'!$J$2:$J$3000,'Données Suivi'!$A$2:$A$3000,$A14,'Données Suivi'!$O$2:$O$3000,"INVESTISSEMENT",'Données Suivi'!$H$2:$H$3000,"ENGAGE") -> 0 | I14: =SUMIFS('Données Suivi'!$J$2:$J$3000,'Données Suivi'!$A$2:$A$3000,$A14,'Données Suivi'!$O$2:$O$3000,"INVESTISSEMENT",'Données Suivi'!$H$2:$H$3000,"PREENGAGE") -> 0 | J14: =SUMIFS('Données Suivi'!$J$2:$J$3000,'Données Suivi'!$A$2:$A$3000,$A14,'Données Suivi'!$O$2:$O$3000,"INVESTISSEMENT",'Données Suivi'!$H$2:$H$3000,"EN COURS D'ENGAGEMENT") -> 0 | K14: =SUMIFS('Données Suivi'!$J$2:$J$3000,'Données Suivi'!$A$2:$A$3000,$A14,'Données Suivi'!$O$2:$O$3000,"INVESTISSEMENT",'Données Suivi'!$H$2:$H$3000,"EN COURS DE PREENGAGEMENT") -> 0 | L14: =SUMIFS('Données Suivi'!$J$2:$J$3000,'Données Suivi'!$A$2:$A$3000,$A14,'Données Suivi'!$O$2:$O$3000,"INVESTISSEMENT",'Données Suivi'!$H$2:$H$3000,"NON ENGAGE") -> 0 | M14: =H14+I14+J14+K14+L14 -> 0 | N14: =G14+M14 -> 2648832.5
A15: DINFOTV | B15: =SUMIFS('Données Suivi'!$J$2:$J$3000,'Données Suivi'!$A$2:$A$3000,$A15,'Données Suivi'!$O$2:$O$3000,"FONCTIONNEMENT",'Données Suivi'!$H$2:$H$3000,"ENGAGE") -> 10711701 | C15: =SUMIFS('Données Suivi'!$J$2:$J$3000,'Données Suivi'!$A$2:$A$3000,$A15,'Données Suivi'!$O$2:$O$3000,"FONCTIONNEMENT",'Données Suivi'!$H$2:$H$3000,"PREENGAGE") -> 0 | D15: =SUMIFS('Données Suivi'!$J$2:$J$3000,'Données Suivi'!$A$2:$A$3000,$A15,'Données Suivi'!$O$2:$O$3000,"FONCTIONNEMENT",'Données Suivi'!$H$2:$H$3000,"EN COURS D'ENGAGEMENT") -> 1508695.3 | E15: =SUMIFS('Données Suivi'!$J$2:$J$3000,'Données Suivi'!$A$2:$A$3000,$A15,'Données Suivi'!$O$2:$O$3000,"FONCTIONNEMENT",'Données Suivi'!$H$2:$H$3000,"EN COURS DE PREENGAGEMENT") -> 0 | F15: =SUMIFS('Données Suivi'!$J$2:$J$3000,'Données Suivi'!$A$2:$A$3000,$A15,'Données Suivi'!$O$2:$O$3000,"FONCTIONNEMENT",'Données Suivi'!$H$2:$H$3000,"NON ENGAGE") -> 0 | G15: =B15+C15+D15+E15+F15 -> 12220397 | H15: =SUMIFS('Données Suivi'!$J$2:$J$3000,'Données Suivi'!$A$2:$A$3000,$A15,'Données Suivi'!$O$2:$O$3000,"INVESTISSEMENT",'Données Suivi'!$H$2:$H$3000,"ENGAGE") -> 0 | I15: =SUMIFS('Données Suivi'!$J$2:$J$3000,'Données Suivi'!$A$2:$A$3000,$A15,'Données Suivi'!$O$2:$O$3000,"INVESTISSEMENT",'Données Suivi'!$H$2:$H$3000,"PREENGAGE") -> 0 | J15: =SUMIFS('Données Suivi'!$J$2:$J$3000,'Données Suivi'!$A$2:$A$3000,$A15,'Données Suivi'!$O$2:$O$3000,"INVESTISSEMENT",'Données Suivi'!$H$2:$H$3000,"EN COURS D'ENGAGEMENT") -> 0 | K15: =SUMIFS('Données Suivi'!$J$2:$J$3000,'Données Suivi'!$A$2:$A$3000,$A15,'Données Suivi'!$O$2:$O$3000,"INVESTISSEMENT",'Données Suivi'!$H$2:$H$3000,"EN COURS DE PREENGAGEMENT") -> 0 | L15: =SUMIFS('Données Suivi'!$J$2:$J$3000,'Données Suivi'!$A$2:$A$3000,$A15,'Données Suivi'!$O$2:$O$3000,"INVESTISSEMENT",'Données Suivi'!$H$2:$H$3000,"NON ENGAGE") -> 0 | M15: =H15+I15+J15+K15+L15 -> 0 | N15: =G15+M15 -> 12220397
A16: DJURIDIQUE | B16: =SUMIFS('Données Suivi'!$J$2:$J$3000,'Données Suivi'!$A$2:$A$3000,$A16,'Données Suivi'!$O$2:$O$3000,"FONCTIONNEMENT",'Données Suivi'!$H$2:$H$3000,"ENGAGE") -> 8551887.7 | C16: =SUMIFS('Données Suivi'!$J$2:$J$3000,'Données Suivi'!$A$2:$A$3000,$A16,'Données Suivi'!$O$2:$O$3000,"FONCTIONNEMENT",'Données Suivi'!$H$2:$H$3000,"PREENGAGE") -> 0 | D16: =SUMIFS('Données Suivi'!$J$2:$J$3000,'Données Suivi'!$A$2:$A$3000,$A16,'Données Suivi'!$O$2:$O$3000,"FONCTIONNEMENT",'Données Suivi'!$H$2:$H$3000,"EN COURS D'ENGAGEMENT") -> 9600 | E16: =SUMIFS('Données Suivi'!$J$2:$J$3000,'Données Suivi'!$A$2:$A$3000,$A16,'Données Suivi'!$O$2:$O$3000,"FONCTIONNEMENT",'Données Suivi'!$H$2:$H$3000,"EN COURS DE PREENGAGEMENT") -> 0 | F16: =SUMIFS('Données Suivi'!$J$2:$J$3000,'Données Suivi'!$A$2:$A$3000,$A16,'Données Suivi'!$O$2:$O$3000,"FONCTIONNEMENT",'Données Suivi'!$H$2:$H$3000,"NON ENGAGE") -> 0 | G16: =B16+C16+D16+E16+F16 -> 8561487.7 | H16: =SUMIFS('Données Suivi'!$J$2:$J$3000,'Données Suivi'!$A$2:$A$3000,$A16,'Données Suivi'!$O$2:$O$3000,"INVESTISSEMENT",'Données Suivi'!$H$2:$H$3000,"ENGAGE") -> 0 | I16: =SUMIFS('Données Suivi'!$J$2:$J$3000,'Données Suivi'!$A$2:$A$3000,$A16,'Données Suivi'!$O$2:$O$3000,"INVESTISSEMENT",'Données Suivi'!$H$2:$H$3000,"PREENGAGE") -> 0 | J16: =SUMIFS('Données Suivi'!$J$2:$J$3000,'Données Suivi'!$A$2:$A$3000,$A16,'Données Suivi'!$O$2:$O$3000,"INVESTISSEMENT",'Données Suivi'!$H$2:$H$3000,"EN COURS D'ENGAGEMENT") -> 0 | K16: =SUMIFS('Données Suivi'!$J$2:$J$3000,'Données Suivi'!$A$2:$A$3000,$A16,'Données Suivi'!$O$2:$O$3000,"INVESTISSEMENT",'Données Suivi'!$H$2:$H$3000,"EN COURS DE PREENGAGEMENT") -> 0 | L16: =SUMIFS('Données Suivi'!$J$2:$J$3000,'Données Suivi'!$A$2:$A$3000,$A16,'Données Suivi'!$O$2:$O$3000,"INVESTISSEMENT",'Données Suivi'!$H$2:$H$3000,"NON ENGAGE") -> 0 | M16: =H16+I16+J16+K16+L16 -> 0 | N16: =G16+M16 -> 8561487.7
... A27: TV LAAYOUNE | B27: =SUMIFS('Données Suivi'!$J$2:$J$3000,'Données Suivi'!$A$2:$A$3000,$A27,'Données Suivi'!$O$2:$O$3000,"FONCTIONNEMENT",'Données Suivi'!$H$2:$H$3000,"ENGAGE") -> 22592636 | C27: =SUMIFS('Données Suivi'!$J$2:$J$3000,'Données Suivi'!$A$2:$A$3000,$A27,'Données Suivi'!$O$2:$O$3000,"FONCTIONNEMENT",'Données Suivi'!$H$2:$H$3000,"PREENGAGE") -> 102000 | D27: =SUMIFS('Données Suivi'!$J$2:$J$3000,'Données Suivi'!$A$2:$A$3000,$A27,'Données Suivi'!$O$2:$O$3000,"FONCTIONNEMENT",'Données Suivi'!$H$2:$H$3000,"EN COURS D'ENGAGEMENT") -> 0 | E27: =SUMIFS('Données Suivi'!$J$2:$J$3000,'Données Suivi'!$A$2:$A$3000,$A27,'Données Suivi'!$O$2:$O$3000,"FONCTIONNEMENT",'Données Suivi'!$H$2:$H$3000,"EN COURS DE PREENGAGEMENT") -> 0 | F27: =SUMIFS('Données Suivi'!$J$2:$J$3000,'Données Suivi'!$A$2:$A$3000,$A27,'Données Suivi'!$O$2:$O$3000,"FONCTIONNEMENT",'Données Suivi'!$H$2:$H$3000,"NON ENGAGE") -> 0 | G27: =B27+C27+D27+E27+F27 -> 22694636 | H27: =SUMIFS('Données Suivi'!$J$2:$J$3000,'Données Suivi'!$A$2:$A$3000,$A27,'Données Suivi'!$O$2:$O$3000,"INVESTISSEMENT",'Données Suivi'!$H$2:$H$3000,"ENGAGE") -> 0 | I27: =SUMIFS('Données Suivi'!$J$2:$J$3000,'Données Suivi'!$A$2:$A$3000,$A27,'Données Suivi'!$O$2:$O$3000,"INVESTISSEMENT",'Données Suivi'!$H$2:$H$3000,"PREENGAGE") -> 0 | J27: =SUMIFS('Données Suivi'!$J$2:$J$3000,'Données Suivi'!$A$2:$A$3000,$A27,'Données Suivi'!$O$2:$O$3000,"INVESTISSEMENT",'Données Suivi'!$H$2:$H$3000,"EN COURS D'ENGAGEMENT") -> 0 | K27: =SUMIFS('Données Suivi'!$J$2:$J$3000,'Données Suivi'!$A$2:$A$3000,$A27,'Données Suivi'!$O$2:$O$3000,"INVESTISSEMENT",'Données Suivi'!$H$2:$H$3000,"EN COURS DE PREENGAGEMENT") -> 0 | L27: =SUMIFS('Données Suivi'!$J$2:$J$3000,'Données Suivi'!$A$2:$A$3000,$A27,'Données Suivi'!$O$2:$O$3000,"INVESTISSEMENT",'Données Suivi'!$H$2:$H$3000,"NON ENGAGE") -> 0 | M27: =H27+I27+J27+K27+L27 -> 0 | N27: =G27+M27 -> 22694636
A28: TOTAL GÉNÉRAL | B28: =SUM(B5:B27) -> 6.0709519e+08 | C28: =SUM(C5:C27) -> 32722158 | D28: =SUM(D5:D27) -> 22263126 | E28: =SUM(E5:E27) -> 9329928 | F28: =SUM(F5:F27) -> 7563008 | G28: =SUM(G5:G27) -> 6.7897341e+08 | H28: =SUM(H5:H27) -> 38663865 | I28: =SUM(I5:I27) -> 49004401 | ... N28: =SUM(N5:N27) -> 8.2113096e+08

Sheet Filtre Interactif
A1: FILTRE INTERACTIF — DIRECTION / BCI / STATUT D'ENGAGEMENT
A3: 1) Choisir une Direction : | C3: DCT
A5: 2) Choisir un Type de BCI (à partir de la répartition ci-dessous) : | C5: CONTRAT
A7: Nombre de dossiers par Type de BCI — Direction sélectionnée
A8: Type de BCI | B8: Nb dossiers | C8: Montant (MAD) | D8: NATURE BUDGET | F8: CATEGORIE
D9: Fonctionnement | E9: Investissement | F9: Général | G9: PME | H9: Non concerné
A10: CONTRAT | B10: =COUNTIFS('Données Suivi'!$A$2:$A$3000,$C$3,'Données Suivi'!$C$2:$C$3000,$A10) -> 11 | C10: =SUMIFS('Données Suivi'!$J$2:$J$3000,'Données Suivi'!$A$2:$A$3000,$C$3,'Données Suivi'!$C$2:$C$3000,$A10) -> 3339526.8 | D10: =COUNTIFS('Données Suivi'!$A$2:$A$3000,$C$3,'Données Suivi'!$C$2:$C$3000,$A10,'Données Suivi'!$O$2:$O$3000,"FONCTIONNEMENT") -> 11 | E10: =COUNTIFS('Données Suivi'!$A$2:$A$3000,$C$3,'Données Suivi'!$C$2:$C$3000,$A10,'Données Suivi'!$O$2:$O$3000,"INVESTISSEMENT") -> 0 | F10: =COUNTIFS('Données Suivi'!$A$2:$A$3000,$C$3,'Données Suivi'!$C$2:$C$3000,$A10,'Données Suivi'!$P$2:$P$3000,"GENERAL") -> 0 | G10: =COUNTIFS('Données Suivi'!$A$2:$A$3000,$C$3,'Données Suivi'!$C$2:$C$3000,$A10,'Données Suivi'!$P$2:$P$3000,"PME") -> 0 | H10: =COUNTIFS('Données Suivi'!$A$2:$A$3000,$C$3,'Données Suivi'!$C$2:$C$3000,$A10,'Données Suivi'!$P$2:$P$3000,"NON CONCERNE") -> 11
A11: AOO-M | B11: =COUNTIFS('Données Suivi'!$A$2:$A$3000,$C$3,'Données Suivi'!$C$2:$C$3000,$A11) -> 42 | C11: =SUMIFS('Données Suivi'!$J$2:$J$3000,'Données Suivi'!$A$2:$A$3000,$C$3,'Données Suivi'!$C$2:$C$3000,$A11) -> 82870899 | D11: =COUNTIFS('Données Suivi'!$A$2:$A$3000,$C$3,'Données Suivi'!$C$2:$C$3000,$A11,'Données Suivi'!$O$2:$O$3000,"FONCTIONNEMENT") -> 13 | E11: =COUNTIFS('Données Suivi'!$A$2:$A$3000,$C$3,'Données Suivi'!$C$2:$C$3000,$A11,'Données Suivi'!$O$2:$O$3000,"INVESTISSEMENT") -> 29 | F11: =COUNTIFS('Données Suivi'!$A$2:$A$3000,$C$3,'Données Suivi'!$C$2:$C$3000,$A11,'Données Suivi'!$P$2:$P$3000,"GENERAL") -> 28 | G11: =COUNTIFS('Données Suivi'!$A$2:$A$3000,$C$3,'Données Suivi'!$C$2:$C$3000,$A11,'Données Suivi'!$P$2:$P$3000,"PME") -> 9 | H11: =COUNTIFS('Données Suivi'!$A$2:$A$3000,$C$3,'Données Suivi'!$C$2:$C$3000,$A11,'Données Suivi'!$P$2:$P$3000,"NON CONCERNE") -> 5
A12: AOO-CT | B12: =COUNTIFS('Données Suivi'!$A$2:$A$3000,$C$3,'Données Suivi'!$C$2:$C$3000,$A12) -> 0 | C12: =SUMIFS('Données Suivi'!$J$2:$J$3000,'Données Suivi'!$A$2:$A$3000,$C$3,'Données Suivi'!$C$2:$C$3000,$A12) -> 0 | D12: =COUNTIFS('Données Suivi'!$A$2:$A$3000,$C$3,'Données Suivi'!$C$2:$C$3000,$A12,'Données Suivi'!$O$2:$O$3000,"FONCTIONNEMENT") -> 0 | E12: =COUNTIFS('Données Suivi'!$A$2:$A$3000,$C$3,'Données Suivi'!$C$2:$C$3000,$A12,'Données Suivi'!$O$2:$O$3000,"INVESTISSEMENT") -> 0 | F12: =COUNTIFS('Données Suivi'!$A$2:$A$3000,$C$3,'Données Suivi'!$C$2:$C$3000,$A12,'Données Suivi'!$P$2:$P$3000,"GENERAL") -> 0 | G12: =COUNTIFS('Données Suivi'!$A$2:$A$3000,$C$3,'Données Suivi'!$C$2:$C$3000,$A12,'Données Suivi'!$P$2:$P$3000,"PME") -> 0 | H12: =COUNTIFS('Données Suivi'!$A$2:$A$3000,$C$3,'Données Suivi'!$C$2:$C$3000,$A12,'Données Suivi'!$P$2:$P$3000,"NON CONCERNE") -> 0
A13: BCL | B13: =COUNTIFS('Données Suivi'!$A$2:$A$3000,$C$3,'Données Suivi'!$C$2:$C$3000,$A13) -> 4 | C13: =SUMIFS('Données Suivi'!$J$2:$J$3000,'Données Suivi'!$A$2:$A$3000,$C$3,'Données Suivi'!$C$2:$C$3000,$A13) -> 928548.96 | D13: =COUNTIFS('Données Suivi'!$A$2:$A$3000,$C$3,'Données Suivi'!$C$2:$C$3000,$A13,'Données Suivi'!$O$2:$O$3000,"FONCTIONNEMENT") -> 2 | E13: =COUNTIFS('Données Suivi'!$A$2:$A$3000,$C$3,'Données Suivi'!$C$2:$C$3000,$A13,'Données Suivi'!$O$2:$O$3000,"INVESTISSEMENT") -> 2 | F13: =COUNTIFS('Données Suivi'!$A$2:$A$3000,$C$3,'Données Suivi'!$C$2:$C$3000,$A13,'Données Suivi'!$P$2:$P$3000,"GENERAL") -> 1 | G13: =COUNTIFS('Données Suivi'!$A$2:$A$3000,$C$3,'Données Suivi'!$C$2:$C$3000,$A13,'Données Suivi'!$P$2:$P$3000,"PME") -> 0 | H13: =COUNTIFS('Données Suivi'!$A$2:$A$3000,$C$3,'Données Suivi'!$C$2:$C$3000,$A13,'Données Suivi'!$P$2:$P$3000,"NON CONCERNE") -> 3
A14: BCI | B14: =COUNTIFS('Données Suivi'!$A$2:$A$3000,$C$3,'Données Suivi'!$C$2:$C$3000,$A14) -> 1 | C14: =SUMIFS('Données Suivi'!$J$2:$J$3000,'Données Suivi'!$A$2:$A$3000,$C$3,'Données Suivi'!$C$2:$C$3000,$A14) -> 134289.08 | D14: =COUNTIFS('Données Suivi'!$A$2:$A$3000,$C$3,'Données Suivi'!$C$2:$C$3000,$A14,'Données Suivi'!$O$2:$O$3000,"FONCTIONNEMENT") -> 1 | E14: =COUNTIFS('Données Suivi'!$A$2:$A$3000,$C$3,'Données Suivi'!$C$2:$C$3000,$A14,'Données Suivi'!$O$2:$O$3000,"INVESTISSEMENT") -> 0 | F14: =COUNTIFS('Données Suivi'!$A$2:$A$3000,$C$3,'Données Suivi'!$C$2:$C$3000,$A14,'Données Suivi'!$P$2:$P$3000,"GENERAL") -> 1 | G14: =COUNTIFS('Données Suivi'!$A$2:$A$3000,$C$3,'Données Suivi'!$C$2:$C$3000,$A14,'Données Suivi'!$P$2:$P$3000,"PME") -> 0 | H14: =COUNTIFS('Données Suivi'!$A$2:$A$3000,$C$3,'Données Suivi'!$C$2:$C$3000,$A14,'Données Suivi'!$P$2:$P$3000,"NON CONCERNE") -> 0
A15: CA | B15: =COUNTIFS('Données Suivi'!$A$2:$A$3000,$C$3,'Données Suivi'!$C$2:$C$3000,$A15) -> 0 | C15: =SUMIFS('Données Suivi'!$J$2:$J$3000,'Données Suivi'!$A$2:$A$3000,$C$3,'Données Suivi'!$C$2:$C$3000,$A15) -> 0 | D15: =COUNTIFS('Données Suivi'!$A$2:$A$3000,$C$3,'Données Suivi'!$C$2:$C$3000,$A15,'Données Suivi'!$O$2:$O$3000,"FONCTIONNEMENT") -> 0 | E15: =COUNTIFS('Données Suivi'!$A$2:$A$3000,$C$3,'Données Suivi'!$C$2:$C$3000,$A15,'Données Suivi'!$O$2:$O$3000,"INVESTISSEMENT") -> 0 | F15: =COUNTIFS('Données Suivi'!$A$2:$A$3000,$C$3,'Données Suivi'!$C$2:$C$3000,$A15,'Données Suivi'!$P$2:$P$3000,"GENERAL") -> 0 | G15: =COUNTIFS('Données Suivi'!$A$2:$A$3000,$C$3,'Données Suivi'!$C$2:$C$3000,$A15,'Données Suivi'!$P$2:$P$3000,"PME") -> 0 | H15: =COUNTIFS('Données Suivi'!$A$2:$A$3000,$C$3,'Données Suivi'!$C$2:$C$3000,$A15,'Données Suivi'!$P$2:$P$3000,"NON CONCERNE") -> 0
A16: TOTAL direction | B16: =SUM(B10:B15) -> 58 | C16: =SUM(C10:C15) -> 87273264 | D16: =SUM(D10:D15) -> 27 | E16: =SUM(E10:E15) -> 31 | F16: =SUM(F10:F15) -> 30 | G16: =SUM(G10:G15) -> 9 | H16: =SUM(H10:H15) -> 19
A18: Répartition par Statut d'Engagement — Direction + Type de BCI sélectionnés
A19: Statut d'Engagement | B19: Nb dossiers | C19: Montant Fonctionnement (MAD) | D19: Montant Investissement (MAD)
A20: NON ENGAGE | B20: =COUNTIFS('Données Suivi'!$A$2:$A$3000,$C$3,'Données Suivi'!$C$2:$C$3000,$C$5,'Données Suivi'!$H$2:$H$3000,$A20) -> 1 | C20: =SUMIFS('Données Suivi'!$J$2:$J$3000,'Données Suivi'!$A$2:$A$3000,$C$3,'Données Suivi'!$C$2:$C$3000,$C$5,'Données Suivi'!$H$2:$H$3000,$A20,'Données Suivi'!$O$2:$O$3000,"FONCTIONNEMENT") -> 96000 | D20: =SUMIFS('Données Suivi'!$J$2:$J$3000,'Données Suivi'!$A$2:$A$3000,$C$3,'Données Suivi'!$C$2:$C$3000,$C$5,'Données Suivi'!$H$2:$H$3000,$A20,'Données Suivi'!$O$2:$O$3000,"INVESTISSEMENT") -> 0
A21: EN COURS DE PREENGAGEMENT | B21: =COUNTIFS('Données Suivi'!$A$2:$A$3000,$C$3,'Données Suivi'!$C$2:$C$3000,$C$5,'Données Suivi'!$H$2:$H$3000,$A21) -> 0 | C21: =SUMIFS('Données Suivi'!$J$2:$J$3000,'Données Suivi'!$A$2:$A$3000,$C$3,'Données Suivi'!$C$2:$C$3000,$C$5,'Données Suivi'!$H$2:$H$3000,$A21,'Données Suivi'!$O$2:$O$3000,"FONCTIONNEMENT") -> 0 | D21: =SUMIFS('Données Suivi'!$J$2:$J$3000,'Données Suivi'!$A$2:$A$3000,$C$3,'Données Suivi'!$C$2:$C$3000,$C$5,'Données Suivi'!$H$2:$H$3000,$A21,'Données Suivi'!$O$2:$O$3000,"INVESTISSEMENT") -> 0
A22: PREENGAGE | B22: =COUNTIFS('Données Suivi'!$A$2:$A$3000,$C$3,'Données Suivi'!$C$2:$C$3000,$C$5,'Données Suivi'!$H$2:$H$3000,$A22) -> 0 | C22: =SUMIFS('Données Suivi'!$J$2:$J$3000,'Données Suivi'!$A$2:$A$3000,$C$3,'Données Suivi'!$C$2:$C$3000,$C$5,'Données Suivi'!$H$2:$H$3000,$A22,'Données Suivi'!$O$2:$O$3000,"FONCTIONNEMENT") -> 0 | D22: =SUMIFS('Données Suivi'!$J$2:$J$3000,'Données Suivi'!$A$2:$A$3000,$C$3,'Données Suivi'!$C$2:$C$3000,$C$5,'Données Suivi'!$H$2:$H$3000,$A22,'Données Suivi'!$O$2:$O$3000,"INVESTISSEMENT") -> 0
A23: EN COURS D'ENGAGEMENT | B23: =COUNTIFS('Données Suivi'!$A$2:$A$3000,$C$3,'Données Suivi'!$C$2:$C$3000,$C$5,'Données Suivi'!$H$2:$H$3000,$A23) -> 0 | C23: =SUMIFS('Données Suivi'!$J$2:$J$3000,'Données Suivi'!$A$2:$A$3000,$C$3,'Données Suivi'!$C$2:$C$3000,$C$5,'Données Suivi'!$H$2:$H$3000,$A23,'Données Suivi'!$O$2:$O$3000,"FONCTIONNEMENT") -> 0 | D23: =SUMIFS('Données Suivi'!$J$2:$J$3000,'Données Suivi'!$A$2:$A$3000,$C$3,'Données Suivi'!$C$2:$C$3000,$C$5,'Données Suivi'!$H$2:$H$3000,$A23,'Données Suivi'!$O$2:$O$3000,"INVESTISSEMENT") -> 0
A24: ENGAGE | B24: =COUNTIFS('Données Suivi'!$A$2:$A$3000,$C$3,'Données Suivi'!$C$2:$C$3000,$C$5,'Données Suivi'!$H$2:$H$3000,$A24) -> 10 | C24: =SUMIFS('Données Suivi'!$J$2:$J$3000,'Données Suivi'!$A$2:$A$3000,$C$3,'Données Suivi'!$C$2:$C$3000,$C$5,'Données Suivi'!$H$2:$H$3000,$A24,'Données Suivi'!$O$2:$O$3000,"FONCTIONNEMENT") -> 3243526.8 | D24: =SUMIFS('Données Suivi'!$J$2:$J$3000,'Données Suivi'!$A$2:$A$3000,$C$3,'Données Suivi'!$C$2:$C$3000,$C$5,'Données Suivi'!$H$2:$H$3000,$A24,'Données Suivi'!$O$2:$O$3000,"INVESTISSEMENT") -> 0
A25: TOTAL direction + BCI | B25: =SUM(B20:B24) -> 11 | C25: =SUM(C20:C24) -> 3339526.8 | D25: =SUM(D20:D24) -> 0
A27: Détail des dossiers Non Engagé (Statut Support d'Engagement) — Direction sélectionnée
A28: Statut Support (Non Engagé) | B28: Nb dossiers | C28: Montant (MAD)
A29: INFRUCTUEUX | B29: =COUNTIFS('Données Suivi'!$A$2:$A$3000,$C$3,'Données Suivi'!$H$2:$H$3000,"NON ENGAGE",'Données Suivi'!$E$2:$E$3000,$A29) -> 14 | C29: =SUMIFS('Données Suivi'!$J$2:$J$3000,'Données Suivi'!$A$2:$A$3000,$C$3,'Données Suivi'!$H$2:$H$3000,"NON ENGAGE",'Données Suivi'!$E$2:$E$3000,$A29) -> 23580168
A30: ANNULE | B30: =COUNTIFS('Données Suivi'!$A$2:$A$3000,$C$3,'Données Suivi'!$H$2:$H$3000,"NON ENGAGE",'Données Suivi'!$E$2:$E$3000,$A30) -> 2 | C30: =SUMIFS('Données Suivi'!$J$2:$J$3000,'Données Suivi'!$A$2:$A$3000,$C$3,'Données Suivi'!$H$2:$H$3000,"NON ENGAGE",'Données Suivi'!$E$2:$E$3000,$A30) -> 2002704
A31: EN SIGNATURE | B31: =COUNTIFS('Données Suivi'!$A$2:$A$3000,$C$3,'Données Suivi'!$H$2:$H$3000,"NON ENGAGE",'Données Suivi'!$E$2:$E$3000,$A31) -> 0 | C31: =SUMIFS('Données Suivi'!$J$2:$J$3000,'Données Suivi'!$A$2:$A$3000,$C$3,'Données Suivi'!$H$2:$H$3000,"NON ENGAGE",'Données Suivi'!$E$2:$E$3000,$A31) -> 0
A32: TOTAL Non Engagé — direction | B32: =SUM(B29:B31) -> 16 | C32: =SUM(C29:C31) -> 25582872
A34: Détail des dossiers Infructueux / Annulé — Direction sélectionnée
A35: Objet | B35: Réf | C35: BCI | D35: Statut Support | E35: Montant (MAD) | F35: Date Fiche
A36: =IF($T36="","",INDEX('Données Suivi'!$D$2:$D$3000,$T36)) -> ISMAIL MESKINE - Assistant cameraman | B36: =IF($T36="","",INDEX('Données Suivi'!$B$2:$B$3000,$T36)) -> PV N° : 02RC2025- DCT | C36: =IF($T36="","",INDEX('Données Suivi'!$C$2:$C$3000,$T36)) -> CONTRAT | D36: =IF($T36="","",INDEX('Données Suivi'!$E$2:$E$3000,$T36)) -> ANNULE | E36: =IF($T36="","",INDEX('Données Suivi'!$J$2:$J$3000,$T36)) -> 96000 | F36: =IF($T36="","",INDEX('Données Suivi'!$K$2:$K$3000,$T36)) -> 46387 | T36: =IFERROR(MATCH($C$3&"|"&1,'Données Suivi'!$Q$2:$Q$3000,0),"") -> 255
A37: =IF($T37="","",INDEX('Données Suivi'!$D$2:$D$3000,$T37)) -> La fourniture et la mise en service de serveurs haute performance destinés aux applications d’intelligence artificielle et d’apprentissage automatique pour les besoins de la SNRT | B37: =IF($T37="","",INDEX('Données Suivi'!$B$2:$B$3000,$T37)) -> 15 AOM/SNRT | C37: =IF($T37="","",INDEX('Données Suivi'!$C$2:$C$3000,$T37)) -> AOO-M | D37: =IF($T37="","",INDEX('Données Suivi'!$E$2:$E$3000,$T37)) -> ANNULE | E37: =IF($T37="","",INDEX('Données Suivi'!$J$2:$J$3000,$T37)) -> 1906704 | F37: =IF($T37="","",INDEX('Données Suivi'!$K$2:$K$3000,$T37)) -> 46073 | T37: =IFERROR(MATCH($C$3&"|"&2,'Données Suivi'!$Q$2:$Q$3000,0),"") -> 369
A38: =IF($T38="","",INDEX('Données Suivi'!$D$2:$D$3000,$T38)) -> La fourniture et la mise en service d’infrastructures informatiques haute performance pour les applications d’intelligences artificielle pour les besoins de la SNRT | B38: =IF($T38="","",INDEX('Données Suivi'!$B$2:$B$3000,$T38)) -> 15 AOM/SNRT | C38: =IF($T38="","",INDEX('Données Suivi'!$C$2:$C$3000,$T38)) -> AOO-M | D38: =IF($T38="","",INDEX('Données Suivi'!$E$2:$E$3000,$T38)) -> INFRUCTUEUX | E38: =IF($T38="","",INDEX('Données Suivi'!$J$2:$J$3000,$T38)) -> 677484 | F38: =IF($T38="","",INDEX('Données Suivi'!$K$2:$K$3000,$T38)) -> 46073 | T38: =IFERROR(MATCH($C$3&"|"&3,'Données Suivi'!$Q$2:$Q$3000,0),"") -> 370
A39: =IF($T39="","",INDEX('Données Suivi'!$D$2:$D$3000,$T39)) -> La fourniture et la mise en service d'équipement informatiques les besoins de SNRT new de la SNRT | B39: =IF($T39="","",INDEX('Données Suivi'!$B$2:$B$3000,$T39)) -> 21 AOM/SNRT | C39: =IF($T39="","",INDEX('Données Suivi'!$C$2:$C$3000,$T39)) -> AOO-M | D39: =IF($T39="","",INDEX('Données Suivi'!$E$2:$E$3000,$T39)) -> INFRUCTUEUX | E39: =IF($T39="","",INDEX('Données Suivi'!$J$2:$J$3000,$T39)) -> 1896696 | F39: =IF($T39="","",INDEX('Données Suivi'!$K$2:$K$3000,$T39)) -> 46114 | T39: =IFERROR(MATCH($C$3&"|"&4,'Données Suivi'!$Q$2:$Q$3000,0),"") -> 424
A40: =IF($T40="","",INDEX('Données Suivi'!$D$2:$D$3000,$T40)) -> La fourniture et la mise en service d'accessoires,pièces de rechange et outillage informatique pour les besoins de la SNRT | B40: =IF($T40="","",INDEX('Données Suivi'!$B$2:$B$3000,$T40)) -> 06 AOM/SNRT | C40: =IF($T40="","",INDEX('Données Suivi'!$C$2:$C$3000,$T40)) -> AOO-M | D40: =IF($T40="","",INDEX('Données Suivi'!$E$2:$E$3000,$T40)) -> INFRUCTUEUX | E40: =IF($T40="","",INDEX('Données Suivi'!$J$2:$J$3000,$T40)) -> 407304 | F40: =IF($T40="","",INDEX('Données Suivi'!$K$2:$K$3000,$T40)) -> 46114 | T40: =IFERROR(MATCH($C$3&"|"&5,'Données Suivi'!$Q$2:$Q$3000,0),"") -> 427
A41: =IF($T41="","",INDEX('Données Suivi'!$D$2:$D$3000,$T41)) -> La fourniture et la mise en service d'une solution de transport des communications intercom via des coules audio IP BROADCAST pour les besoins des unités mobiles de la SNRT | B41: =IF($T41="","",INDEX('Données Suivi'!$B$2:$B$3000,$T41)) -> 23 AOM/SNRT | C41: =IF($T41="","",INDEX('Données Suivi'!$C$2:$C$3000,$T41)) -> AOO-M | D41: =IF($T41="","",INDEX('Données Suivi'!$E$2:$E$3000,$T41)) -> INFRUCTUEUX | E41: =IF($T41="","",INDEX('Données Suivi'!$J$2:$J$3000,$T41)) -> 291156 | F41: =IF($T41="","",INDEX('Données Suivi'!$K$2:$K$3000,$T41)) -> 46119 | T41: =IFERROR(MATCH($C$3&"|"&6,'Données Suivi'!$Q$2:$Q$3000,0),"") -> 430
A42: =IF($T42="","",INDEX('Données Suivi'!$D$2:$D$3000,$T42)) -> Fourniture et mise en service d’équipements audio vidéo au profit de la DCRPSD de la SNRT | B42: =IF($T42="","",INDEX('Données Suivi'!$B$2:$B$3000,$T42)) -> 26 AOM/SNRT | C42: =IF($T42="","",INDEX('Données Suivi'!$C$2:$C$3000,$T42)) -> AOO-M | D42: =IF($T42="","",INDEX('Données Suivi'!$E$2:$E$3000,$T42)) -> INFRUCTUEUX | E42: =IF($T42="","",INDEX('Données Suivi'!$J$2:$J$3000,$T42)) -> 287676 | F42: =IF($T42="","",INDEX('Données Suivi'!$K$2:$K$3000,$T42)) -> 46121 | T42: =IFERROR(MATCH($C$3&"|"&7,'Données Suivi'!$Q$2:$Q$3000,0),"") -> 431
A43: =IF($T43="","",INDEX('Données Suivi'!$D$2:$D$3000,$T43)) -> La fourniture et la mise en service de serveurs pour renouvellement de serveurs d’enregistrement et de replay pour les besoins de la production TV des manifestations sportives | B43: =IF($T43="","",INDEX('Données Suivi'!$B$2:$B$3000,$T43)) -> 30 AOM/SNRT | C43: =IF($T43="","",INDEX('Données Suivi'!$C$2:$C$3000,$T43)) -> AOO-M | D43: =IF($T43="","",INDEX('Données Suivi'!$E$2:$E$3000,$T43)) -> INFRUCTUEUX | E43: =IF($T43="","",INDEX('Données Suivi'!$J$2:$J$3000,$T43)) -> 8948880 | F43: =IF($T43="","",INDEX('Données Suivi'!$K$2:$K$3000,$T43)) -> 46129 | T43: =IFERROR(MATCH($C$3&"|"&8,'Données Suivi'!$Q$2:$Q$3000,0),"") -> 536
A44: =IF($T44="","",INDEX('Données Suivi'!$D$2:$D$3000,$T44)) -> La fourniture et la mise en service de serveurs haute performance destinés aux applications d’intelligence artificielle et d’apprentissage automatique pour les besoins de la SNRT | B44: =IF($T44="","",INDEX('Données Suivi'!$B$2:$B$3000,$T44)) -> 33 AOM/SNRT | C44: =IF($T44="","",INDEX('Données Suivi'!$C$2:$C$3000,$T44)) -> AOO-M | D44: =IF($T44="","",INDEX('Données Suivi'!$E$2:$E$3000,$T44)) -> INFRUCTUEUX | E44: =IF($T44="","",INDEX('Données Suivi'!$J$2:$J$3000,$T44)) -> 1906704 | F44: =IF($T44="","",INDEX('Données Suivi'!$K$2:$K$3000,$T44)) -> 46140 | T44: =IFERROR(MATCH($C$3&"|"&9,'Données Suivi'!$Q$2:$Q$3000,0),"") -> 550
A45: =IF($T45="","",INDEX('Données Suivi'!$D$2:$D$3000,$T45)) -> La fourniture et la mise en service de lecteurs LTO destinés aux besoins d’archivage de la SNRT | B45: =IF($T45="","",INDEX('Données Suivi'!$B$2:$B$3000,$T45)) -> 38 AOM/SNRT | C45: =IF($T45="","",INDEX('Données Suivi'!$C$2:$C$3000,$T45)) -> AOO-M | D45: =IF($T45="","",INDEX('Données Suivi'!$E$2:$E$3000,$T45)) -> INFRUCTUEUX | E45: =IF($T45="","",INDEX('Données Suivi'!$J$2:$J$3000,$T45)) -> 367296 | F45: =IF($T45="","",INDEX('Données Suivi'!$K$2:$K$3000,$T45)) -> 46147 | T45: =IFERROR(MATCH($C$3&"|"&10,'Données Suivi'!$Q$2:$Q$3000,0),"") -> 557
A46: =IF($T46="","",INDEX('Données Suivi'!$D$2:$D$3000,$T46)) -> La fourniture et la mise en service de véhicules fourgon aménagés en rayonnage pour les besoins de la production de la SNRT | B46: =IF($T46="","",INDEX('Données Suivi'!$B$2:$B$3000,$T46)) -> 52 AOM/SNRT | C46: =IF($T46="","",INDEX('Données Suivi'!$C$2:$C$3000,$T46)) -> AOO-M | D46: =IF($T46="","",INDEX('Données Suivi'!$E$2:$E$3000,$T46)) -> INFRUCTUEUX | E46: =IF($T46="","",INDEX('Données Suivi'!$J$2:$J$3000,$T46)) -> 2054700 | F46: =IF($T46="","",INDEX('Données Suivi'!$K$2:$K$3000,$T46)) -> 46175 | T46: =IFERROR(MATCH($C$3&"|"&11,'Données Suivi'!$Q$2:$Q$3000,0),"") -> 575
...

Sheet Tableau de Bord Suivi
A1: TABLEAU DE BORD DE SUIVI — ETAT D'ENGAGEMENTS 2026
A3: Nb dossiers total | C3: Montant total (MAD) | E3: Nb directions | G3: Taux d'engagement (montant) | I3: Montant restant à engager | K3: Nb dossiers en cours (à suivre)
A4: =COUNTIF('Données Suivi'!A2:A3000,"?*") -> 684 | C4: =SUM('Données Suivi'!J2:J3000) -> 8.2113096e+08 | E4: =SUMPRODUCT(('Données Suivi'!$A$2:$A$3000<>"")/COUNTIF('Données Suivi'!$A$2:$A$3000,'Données Suivi'!$A$2:$A$3000&"")) -> 23 | G4: =SUMIF('Données Suivi'!M2:M3000,"Engagé",'Données Suivi'!J2:J3000)/SUM('Données Suivi'!J2:J3000) -> 0.7864264 | I4: =SUMIF('Données Suivi'!M2:M3000,"En cours",'Données Suivi'!J2:J3000) -> 1.4607226e+08 | K4: =COUNTIF('Données Suivi'!M2:M3000,"En cours") -> 81
A6: Nb clôturés sans suite | C6: Ancienneté moy. dossiers en cours (j)
A7: =COUNTIF('Données Suivi'!M2:M3000,"Clôturé sans suite") -> 20 | C7: =AVERAGEIFS('Données Suivi'!L2:L3000,'Données Suivi'!M2:M3000,"En cours",'Données Suivi'!L2:L3000,">=0") -> 100.48889
A10: Répartition des dossiers par Direction et par BCI (type d'achat) — Nombre de dossiers
A11: Direction | B11: CONTRAT | C11: AOO-M | D11: AOO-CT | E11: BCL | F11: BCI | G11: CA | H11: TOTAL
A12: ARRIYADIA | B12: =COUNTIFS('Données Suivi'!$A$2:$A$3000,$A12,'Données Suivi'!$C$2:$C$3000,"CONTRAT") -> 77 | C12: =COUNTIFS('Données Suivi'!$A$2:$A$3000,$A12,'Données Suivi'!$C$2:$C$3000,"AOO-M") -> 0 | D12: =COUNTIFS('Données Suivi'!$A$2:$A$3000,$A12,'Données Suivi'!$C$2:$C$3000,"AOO-CT") -> 0 | E12: =COUNTIFS('Données Suivi'!$A$2:$A$3000,$A12,'Données Suivi'!$C$2:$C$3000,"BCL") -> 0 | F12: =COUNTIFS('Données Suivi'!$A$2:$A$3000,$A12,'Données Suivi'!$C$2:$C$3000,"BCI") -> 0 | G12: =COUNTIFS('Données Suivi'!$A$2:$A$3000,$A12,'Données Suivi'!$C$2:$C$3000,"CA") -> 0 | H12: =COUNTIF('Données Suivi'!$A$2:$A$3000,$A12) -> 77
A13: ASSADISSA | B13: =COUNTIFS('Données Suivi'!$A$2:$A$3000,$A13,'Données Suivi'!$C$2:$C$3000,"CONTRAT") -> 81 | C13: =COUNTIFS('Données Suivi'!$A$2:$A$3000,$A13,'Données Suivi'!$C$2:$C$3000,"AOO-M") -> 0 | D13: =COUNTIFS('Données Suivi'!$A$2:$A$3000,$A13,'Données Suivi'!$C$2:$C$3000,"AOO-CT") -> 0 | E13: =COUNTIFS('Données Suivi'!$A$2:$A$3000,$A13,'Données Suivi'!$C$2:$C$3000,"BCL") -> 0 | F13: =COUNTIFS('Données Suivi'!$A$2:$A$3000,$A13,'Données Suivi'!$C$2:$C$3000,"BCI") -> 0 | G13: =COUNTIFS('Données Suivi'!$A$2:$A$3000,$A13,'Données Suivi'!$C$2:$C$3000,"CA") -> 0 | H13: =COUNTIF('Données Suivi'!$A$2:$A$3000,$A13) -> 81
A14: DA | B14: =COUNTIFS('Données Suivi'!$A$2:$A$3000,$A14,'Données Suivi'!$C$2:$C$3000,"CONTRAT") -> 5 | C14: =COUNTIFS('Données Suivi'!$A$2:$A$3000,$A14,'Données Suivi'!$C$2:$C$3000,"AOO-M") -> 0 | D14: =COUNTIFS('Données Suivi'!$A$2:$A$3000,$A14,'Données Suivi'!$C$2:$C$3000,"AOO-CT") -> 0 | E14: =COUNTIFS('Données Suivi'!$A$2:$A$3000,$A14,'Données Suivi'!$C$2:$C$3000,"BCL") -> 0 | F14: =COUNTIFS('Données Suivi'!$A$2:$A$3000,$A14,'Données Suivi'!$C$2:$C$3000,"BCI") -> 0 | G14: =COUNTIFS('Données Suivi'!$A$2:$A$3000,$A14,'Données Suivi'!$C$2:$C$3000,"CA") -> 0 | H14: =COUNTIF('Données Suivi'!$A$2:$A$3000,$A14) -> 5
A15: DACG | B15: =COUNTIFS('Données Suivi'!$A$2:$A$3000,$A15,'Données Suivi'!$C$2:$C$3000,"CONTRAT") -> 3 | C15: =COUNTIFS('Données Suivi'!$A$2:$A$3000,$A15,'Données Suivi'!$C$2:$C$3000,"AOO-M") -> 1 | D15: =COUNTIFS('Données Suivi'!$A$2:$A$3000,$A15,'Données Suivi'!$C$2:$C$3000,"AOO-CT") -> 0 | E15: =COUNTIFS('Données Suivi'!$A$2:$A$3000,$A15,'Données Suivi'!$C$2:$C$3000,"BCL") -> 0 | F15: =COUNTIFS('Données Suivi'!$A$2:$A$3000,$A15,'Données Suivi'!$C$2:$C$3000,"BCI") -> 0 | G15: =COUNTIFS('Données Suivi'!$A$2:$A$3000,$A15,'Données Suivi'!$C$2:$C$3000,"CA") -> 0 | H15: =COUNTIF('Données Suivi'!$A$2:$A$3000,$A15) -> 4
A16: DAR | B16: =COUNTIFS('Données Suivi'!$A$2:$A$3000,$A16,'Données Suivi'!$C$2:$C$3000,"CONTRAT") -> 1 | C16: =COUNTIFS('Données Suivi'!$A$2:$A$3000,$A16,'Données Suivi'!$C$2:$C$3000,"AOO-M") -> 0 | D16: =COUNTIFS('Données Suivi'!$A$2:$A$3000,$A16,'Données Suivi'!$C$2:$C$3000,"AOO-CT") -> 0 | E16: =COUNTIFS('Données Suivi'!$A$2:$A$3000,$A16,'Données Suivi'!$C$2:$C$3000,"BCL") -> 0 | F16: =COUNTIFS('Données Suivi'!$A$2:$A$3000,$A16,'Données Suivi'!$C$2:$C$3000,"BCI") -> 0 | G16: =COUNTIFS('Données Suivi'!$A$2:$A$3000,$A16,'Données Suivi'!$C$2:$C$3000,"CA") -> 0 | H16: =COUNTIF('Données Suivi'!$A$2:$A$3000,$A16) -> 1
A17: DCPA | B17: =COUNTIFS('Données Suivi'!$A$2:$A$3000,$A17,'Données Suivi'!$C$2:$C$3000,"CONTRAT") -> 23 | C17: =COUNTIFS('Données Suivi'!$A$2:$A$3000,$A17,'Données Suivi'!$C$2:$C$3000,"AOO-M") -> 0 | D17: =COUNTIFS('Données Suivi'!$A$2:$A$3000,$A17,'Données Suivi'!$C$2:$C$3000,"AOO-CT") -> 14 | E17: =COUNTIFS('Données Suivi'!$A$2:$A$3000,$A17,'Données Suivi'!$C$2:$C$3000,"BCL") -> 2 | F17: =COUNTIFS('Données Suivi'!$A$2:$A$3000,$A17,'Données Suivi'!$C$2:$C$3000,"BCI") -> 0 | G17: =COUNTIFS('Données Suivi'!$A$2:$A$3000,$A17,'Données Suivi'!$C$2:$C$3000,"CA") -> 4 | H17: =COUNTIF('Données Suivi'!$A$2:$A$3000,$A17) -> 43
A18: DCRI | B18: =COUNTIFS('Données Suivi'!$A$2:$A$3000,$A18,'Données Suivi'!$C$2:$C$3000,"CONTRAT") -> 1 | C18: =COUNTIFS('Données Suivi'!$A$2:$A$3000,$A18,'Données Suivi'!$C$2:$C$3000,"AOO-M") -> 0 | D18: =COUNTIFS('Données Suivi'!$A$2:$A$3000,$A18,'Données Suivi'!$C$2:$C$3000,"AOO-CT") -> 0 | E18: =COUNTIFS('Données Suivi'!$A$2:$A$3000,$A18,'Données Suivi'!$C$2:$C$3000,"BCL") -> 0 | F18: =COUNTIFS('Données Suivi'!$A$2:$A$3000,$A18,'Données Suivi'!$C$2:$C$3000,"BCI") -> 0 | G18: =COUNTIFS('Données Suivi'!$A$2:$A$3000,$A18,'Données Suivi'!$C$2:$C$3000,"CA") -> 0 | H18: =COUNTIF('Données Suivi'!$A$2:$A$3000,$A18) -> 1
A19: DCT | B19: =COUNTIFS('Données Suivi'!$A$2:$A$3000,$A19,'Données Suivi'!$C$2:$C$3000,"CONTRAT") -> 11 | C19: =COUNTIFS('Données Suivi'!$A$2:$A$3000,$A19,'Données Suivi'!$C$2:$C$3000,"AOO-M") -> 42 | D19: =COUNTIFS('Données Suivi'!$A$2:$A$3000,$A19,'Données Suivi'!$C$2:$C$3000,"AOO-CT") -> 0 | E19: =COUNTIFS('Données Suivi'!$A$2:$A$3000,$A19,'Données Suivi'!$C$2:$C$3000,"BCL") -> 4 | F19: =COUNTIFS('Données Suivi'!$A$2:$A$3000,$A19,'Données Suivi'!$C$2:$C$3000,"BCI") -> 1 | G19: =COUNTIFS('Données Suivi'!$A$2:$A$3000,$A19,'Données Suivi'!$C$2:$C$3000,"CA") -> 0 | H19: =COUNTIF('Données Suivi'!$A$2:$A$3000,$A19) -> 58
A20: DG | B20: =COUNTIFS('Données Suivi'!$A$2:$A$3000,$A20,'Données Suivi'!$C$2:$C$3000,"CONTRAT") -> 1 | C20: =COUNTIFS('Données Suivi'!$A$2:$A$3000,$A20,'Données Suivi'!$C$2:$C$3000,"AOO-M") -> 0 | D20: =COUNTIFS('Données Suivi'!$A$2:$A$3000,$A20,'Données Suivi'!$C$2:$C$3000,"AOO-CT") -> 0 | E20: =COUNTIFS('Données Suivi'!$A$2:$A$3000,$A20,'Données Suivi'!$C$2:$C$3000,"BCL") -> 0 | F20: =COUNTIFS('Données Suivi'!$A$2:$A$3000,$A20,'Données Suivi'!$C$2:$C$3000,"BCI") -> 0 | G20: =COUNTIFS('Données Suivi'!$A$2:$A$3000,$A20,'Données Suivi'!$C$2:$C$3000,"CA") -> 0 | H20: =COUNTIF('Données Suivi'!$A$2:$A$3000,$A20) -> 1
A21: DINFORADIO | B21: =COUNTIFS('Données Suivi'!$A$2:$A$3000,$A21,'Données Suivi'!$C$2:$C$3000,"CONTRAT") -> 7 | C21: =COUNTIFS('Données Suivi'!$A$2:$A$3000,$A21,'Données Suivi'!$C$2:$C$3000,"AOO-M") -> 0 | D21: =COUNTIFS('Données Suivi'!$A$2:$A$3000,$A21,'Données Suivi'!$C$2:$C$3000,"AOO-CT") -> 0 | E21: =COUNTIFS('Données Suivi'!$A$2:$A$3000,$A21,'Données Suivi'!$C$2:$C$3000,"BCL") -> 0 | F21: =COUNTIFS('Données Suivi'!$A$2:$A$3000,$A21,'Données Suivi'!$C$2:$C$3000,"BCI") -> 0 | G21: =COUNTIFS('Données Suivi'!$A$2:$A$3000,$A21,'Données Suivi'!$C$2:$C$3000,"CA") -> 0 | H21: =COUNTIF('Données Suivi'!$A$2:$A$3000,$A21) -> 7
A22: DINFOTV | B22: =COUNTIFS('Données Suivi'!$A$2:$A$3000,$A22,'Données Suivi'!$C$2:$C$3000,"CONTRAT") -> 32 | C22: =COUNTIFS('Données Suivi'!$A$2:$A$3000,$A22,'Données Suivi'!$C$2:$C$3000,"AOO-M") -> 1 | D22: =COUNTIFS('Données Suivi'!$A$2:$A$3000,$A22,'Données Suivi'!$C$2:$C$3000,"AOO-CT") -> 0 | E22: =COUNTIFS('Données Suivi'!$A$2:$A$3000,$A22,'Données Suivi'!$C$2:$C$3000,"BCL") -> 0 | F22: =COUNTIFS('Données Suivi'!$A$2:$A$3000,$A22,'Données Suivi'!$C$2:$C$3000,"BCI") -> 0 | G22: =COUNTIFS('Données Suivi'!$A$2:$A$3000,$A22,'Données Suivi'!$C$2:$C$3000,"CA") -> 0 | H22: =COUNTIF('Données Suivi'!$A$2:$A$3000,$A22) -> 33
A23: DJURIDIQUE | B23: =COUNTIFS('Données Suivi'!$A$2:$A$3000,$A23,'Données Suivi'!$C$2:$C$3000,"CONTRAT") -> 8 | C23: =COUNTIFS('Données Suivi'!$A$2:$A$3000,$A23,'Données Suivi'!$C$2:$C$3000,"AOO-M") -> 0 | D23: =COUNTIFS('Données Suivi'!$A$2:$A$3000,$A23,'Données Suivi'!$C$2:$C$3000,"AOO-CT") -> 0 | E23: =COUNTIFS('Données Suivi'!$A$2:$A$3000,$A23,'Données Suivi'!$C$2:$C$3000,"BCL") -> 1 | F23: =COUNTIFS('Données Suivi'!$A$2:$A$3000,$A23,'Données Suivi'!$C$2:$C$3000,"BCI") -> 0 | G23: =COUNTIFS('Données Suivi'!$A$2:$A$3000,$A23,'Données Suivi'!$C$2:$C$3000,"CA") -> 0 | H23: =COUNTIF('Données Suivi'!$A$2:$A$3000,$A23) -> 9
... A34: TV LAAYOUNE | B34: =COUNTIFS('Données Suivi'!$A$2:$A$3000,$A34,'Données Suivi'!$C$2:$C$3000,"CONTRAT") -> 5 | C34: =COUNTIFS('Données Suivi'!$A$2:$A$3000,$A34,'Données Suivi'!$C$2:$C$3000,"AOO-M") -> 1 | D34: =COUNTIFS('Données Suivi'!$A$2:$A$3000,$A34,'Données Suivi'!$C$2:$C$3000,"AOO-CT") -> 18 | E34: =COUNTIFS('Données Suivi'!$A$2:$A$3000,$A34,'Données Suivi'!$C$2:$C$3000,"BCL") -> 3 | F34: =COUNTIFS('Données Suivi'!$A$2:$A$3000,$A34,'Données Suivi'!$C$2:$C$3000,"BCI") -> 0 | G34: =COUNTIFS('Données Suivi'!$A$2:$A$3000,$A34,'Données Suivi'!$C$2:$C$3000,"CA") -> 0 | H34: =COUNTIF('Données Suivi'!$A$2:$A$3000,$A34) -> 27
A35: TOTAL | B35: =SUM(B12:B34) -> 475 | C35: =SUM(C12:C34) -> 131 | D35: =SUM(D12:D34) -> 32 | E35: =SUM(E12:E34) -> 39 | F35: =SUM(F12:F34) -> 2 | G35: =SUM(G12:G34) -> 5 | H35: =SUM(H12:H34) -> 684
A37: Répartition des dossiers par Direction et par Statut d'Engagement — Nombre de dossiers
A38: Direction | B38: NON ENGAGE | C38: EN COURS DE PREENGAGEMENT | D38: PREENGAGE | E38: EN COURS D'ENGAGEMENT | F38: ENGAGE | G38: TOTAL
A39: ARRIYADIA | B39: =COUNTIFS('Données Suivi'!$A$2:$A$3000,$A39,'Données Suivi'!$H$2:$H$3000,"NON ENGAGE") -> 0 | C39: =COUNTIFS('Données Suivi'!$A$2:$A$3000,$A39,'Données Suivi'!$H$2:$H$3000,"EN COURS DE PREENGAGEMENT") -> 0 | D39: =COUNTIFS('Données Suivi'!$A$2:$A$3000,$A39,'Données Suivi'!$H$2:$H$3000,"PREENGAGE") -> 0 | E39: =COUNTIFS('Données Suivi'!$A$2:$A$3000,$A39,'Données Suivi'!$H$2:$H$3000,"EN COURS D'ENGAGEMENT") -> 3 | F39: =COUNTIFS('Données Suivi'!$A$2:$A$3000,$A39,'Données Suivi'!$H$2:$H$3000,"ENGAGE") -> 74 | G39: =COUNTIF('Données Suivi'!$A$2:$A$3000,$A39) -> 77
A40: ASSADISSA | B40: =COUNTIFS('Données Suivi'!$A$2:$A$3000,$A40,'Données Suivi'!$H$2:$H$3000,"NON ENGAGE") -> 0 | C40: =COUNTIFS('Données Suivi'!$A$2:$A$3000,$A40,'Données Suivi'!$H$2:$H$3000,"EN COURS DE PREENGAGEMENT") -> 0 | D40: =COUNTIFS('Données Suivi'!$A$2:$A$3000,$A40,'Données Suivi'!$H$2:$H$3000,"PREENGAGE") -> 0 | E40: =COUNTIFS('Données Suivi'!$A$2:$A$3000,$A40,'Données Suivi'!$H$2:$H$3000,"EN COURS D'ENGAGEMENT") -> 0 | F40: =COUNTIFS('Données Suivi'!$A$2:$A$3000,$A40,'Données Suivi'!$H$2:$H$3000,"ENGAGE") -> 81 | G40: =COUNTIF('Données Suivi'!$A$2:$A$3000,$A40) -> 81
A41: DA | B41: =COUNTIFS('Données Suivi'!$A$2:$A$3000,$A41,'Données Suivi'!$H$2:$H$3000,"NON ENGAGE") -> 0 | C41: =COUNTIFS('Données Suivi'!$A$2:$A$3000,$A41,'Données Suivi'!$H$2:$H$3000,"EN COURS DE PREENGAGEMENT") -> 0 | D41: =COUNTIFS('Données Suivi'!$A$2:$A$3000,$A41,'Données Suivi'!$H$2:$H$3000,"PREENGAGE") -> 0 | E41: =COUNTIFS('Données Suivi'!$A$2:$A$3000,$A41,'Données Suivi'!$H$2:$H$3000,"EN COURS D'ENGAGEMENT") -> 0 | F41: =COUNTIFS('Données Suivi'!$A$2:$A$3000,$A41,'Données Suivi'!$H$2:$H$3000,"ENGAGE") -> 5 | G41: =COUNTIF('Données Suivi'!$A$2:$A$3000,$A41) -> 5
A42: DACG | B42: =COUNTIFS('Données Suivi'!$A$2:$A$3000,$A42,'Données Suivi'!$H$2:$H$3000,"NON ENGAGE") -> 0 | C42: =COUNTIFS('Données Suivi'!$A$2:$A$3000,$A42,'Données Suivi'!$H$2:$H$3000,"EN COURS DE PREENGAGEMENT") -> 1 | D42: =COUNTIFS('Données Suivi'!$A$2:$A$3000,$A42,'Données Suivi'!$H$2:$H$3000,"PREENGAGE") -> 0 | E42: =COUNTIFS('Données Suivi'!$A$2:$A$3000,$A42,'Données Suivi'!$H$2:$H$3000,"EN COURS D'ENGAGEMENT") -> 0 | F42: =COUNTIFS('Données Suivi'!$A$2:$A$3000,$A42,'Données Suivi'!$H$2:$H$3000,"ENGAGE") -> 3 | G42: =COUNTIF('Données Suivi'!$A$2:$A$3000,$A42) -> 4
A43: DAR | B43: =COUNTIFS('Données Suivi'!$A$2:$A$3000,$A43,'Données Suivi'!$H$2:$H$3000,"NON ENGAGE") -> 0 | C43: =COUNTIFS('Données Suivi'!$A$2:$A$3000,$A43,'Données Suivi'!$H$2:$H$3000,"EN COURS DE PREENGAGEMENT") -> 0 | D43: =COUNTIFS('Données Suivi'!$A$2:$A$3000,$A43,'Données Suivi'!$H$2:$H$3000,"PREENGAGE") -> 0 | E43: =COUNTIFS('Données Suivi'!$A$2:$A$3000,$A43,'Données Suivi'!$H$2:$H$3000,"EN COURS D'ENGAGEMENT") -> 0 | F43: =COUNTIFS('Données Suivi'!$A$2:$A$3000,$A43,'Données Suivi'!$H$2:$H$3000,"ENGAGE") -> 1 | G43: =COUNTIF('Données Suivi'!$A$2:$A$3000,$A43) -> 1
A44: DCPA | B44: =COUNTIFS('Données Suivi'!$A$2:$A$3000,$A44,'Données Suivi'!$H$2:$H$3000,"NON ENGAGE") -> 1 | C44: =COUNTIFS('Données Suivi'!$A$2:$A$3000,$A44,'Données Suivi'!$H$2:$H$3000,"EN COURS DE PREENGAGEMENT") -> 0 | D44: =COUNTIFS('Données Suivi'!$A$2:$A$3000,$A44,'Données Suivi'!$H$2:$H$3000,"PREENGAGE") -> 0 | E44: =COUNTIFS('Données Suivi'!$A$2:$A$3000,$A44,'Données Suivi'!$H$2:$H$3000,"EN COURS D'ENGAGEMENT") -> 4 | F44: =COUNTIFS('Données Suivi'!$A$2:$A$3000,$A44,'Données Suivi'!$H$2:$H$3000,"ENGAGE") -> 38 | G44: =COUNTIF('Données Suivi'!$A$2:$A$3000,$A44) -> 43
A45: DCRI | B45: =COUNTIFS('Données Suivi'!$A$2:$A$3000,$A45,'Données Suivi'!$H$2:$H$3000,"NON ENGAGE") -> 0 | C45: =COUNTIFS('Données Suivi'!$A$2:$A$3000,$A45,'Données Suivi'!$H$2:$H$3000,"EN COURS DE PREENGAGEMENT") -> 0 | D45: =COUNTIFS('Données Suivi'!$A$2:$A$3000,$A45,'Données Suivi'!$H$2:$H$3000,"PREENGAGE") -> 0 | E45: =COUNTIFS('Données Suivi'!$A$2:$A$3000,$A45,'Données Suivi'!$H$2:$H$3000,"EN COURS D'ENGAGEMENT") -> 0 | F45: =COUNTIFS('Données Suivi'!$A$2:$A$3000,$A45,'Données Suivi'!$H$2:$H$3000,"ENGAGE") -> 1 | G45: =COUNTIF('Données Suivi'!$A$2:$A$3000,$A45) -> 1
A46: DCT | B46: =COUNTIFS('Données Suivi'!$A$2:$A$3000,$A46,'Données Suivi'!$H$2:$H$3000,"NON ENGAGE") -> 16 | C46: =COUNTIFS('Données Suivi'!$A$2:$A$3000,$A46,'Données Suivi'!$H$2:$H$3000,"EN COURS DE PREENGAGEMENT") -> 1 | D46: =COUNTIFS('Données Suivi'!$A$2:$A$3000,$A46,'Données Suivi'!$H$2:$H$3000,"PREENGAGE") -> 10 | E46: =COUNTIFS('Données Suivi'!$A$2:$A$3000,$A46,'Données Suivi'!$H$2:$H$3000,"EN COURS D'ENGAGEMENT") -> 2 | F46: =COUNTIFS('Données Suivi'!$A$2:$A$3000,$A46,'Données Suivi'!$H$2:$H$3000,"ENGAGE") -> 29 | G46: =COUNTIF('Données Suivi'!$A$2:$A$3000,$A46) -> 58
A47: DG | B47: =COUNTIFS('Données Suivi'!$A$2:$A$3000,$A47,'Données Suivi'!$H$2:$H$3000,"NON ENGAGE") -> 0 | C47: =COUNTIFS('Données Suivi'!$A$2:$A$3000,$A47,'Données Suivi'!$H$2:$H$3000,"EN COURS DE PREENGAGEMENT") -> 0 | D47: =COUNTIFS('Données Suivi'!$A$2:$A$3000,$A47,'Données Suivi'!$H$2:$H$3000,"PREENGAGE") -> 0 | E47: =COUNTIFS('Données Suivi'!$A$2:$A$3000,$A47,'Données Suivi'!$H$2:$H$3000,"EN COURS D'ENGAGEMENT") -> 0 | F47: =COUNTIFS('Données Suivi'!$A$2:$A$3000,$A47,'Données Suivi'!$H$2:$H$3000,"ENGAGE") -> 1 | G47: =COUNTIF('Données Suivi'!$A$2:$A$3000,$A47) -> 1
A48: DINFORADIO | B48: =COUNTIFS('Données Suivi'!$A$2:$A$3000,$A48,'Données Suivi'!$H$2:$H$3000,"NON ENGAGE") -> 0 | C48: =COUNTIFS('Données Suivi'!$A$2:$A$3000,$A48,'Données Suivi'!$H$2:$H$3000,"EN COURS DE PREENGAGEMENT") -> 0 | D48: =COUNTIFS('Données Suivi'!$A$2:$A$3000,$A48,'Données Suivi'!$H$2:$H$3000,"PREENGAGE") -> 0 | E48: =COUNTIFS('Données Suivi'!$A$2:$A$3000,$A48,'Données Suivi'!$H$2:$H$3000,"EN COURS D'ENGAGEMENT") -> 0 | F48: =COUNTIFS('Données Suivi'!$A$2:$A$3000,$A48,'Données Suivi'!$H$2:$H$3000,"ENGAGE") -> 7 | G48: =COUNTIF('Données Suivi'!$A$2:$A$3000,$A48) -> 7
