Workbook

Sheet Tableau de Bord
A1: TABLEAU DE BORD DES ENGAGEMENTS BUDGÉTAIRES 2026 — SNRT
A2: Montants en MAD TTC — calculés dynamiquement (SUMIFS) depuis la feuille « Données »
A3: DIRECTION | B3: FONCTIONNEMENT | H3: INVESTISSEMENT | N3: TOTAL GÉNÉRAL
B4: ENGAGE | C4: PREENGAGE | D4: EN COURS D'ENGAGEMENT | E4: EN COURS DE PREENGAGEMENT | F4: NON ENGAGE | G4: TOTAL FONC. | H4: ENGAGE | I4: PREENGAGE | J4: EN COURS D'ENGAGEMENT | K4: EN COURS DE PREENGAGEMENT | L4: NON ENGAGE | M4: TOTAL INVE.
A5: ARRIYADIA | B5: =SUMIFS(Données!$D$2:$D$599,Données!$A$2:$A$599,$A5,Données!$B$2:$B$599,"FONCTIONNEMENT",Données!$C$2:$C$599,"ENGAGE") -> 1.7715909e+08 | C5: =SUMIFS(Données!$D$2:$D$599,Données!$A$2:$A$599,$A5,Données!$B$2:$B$599,"FONCTIONNEMENT",Données!$C$2:$C$599,"PREENGAGE") -> 0 | D5: =SUMIFS(Données!$D$2:$D$599,Données!$A$2:$A$599,$A5,Données!$B$2:$B$599,"FONCTIONNEMENT",Données!$C$2:$C$599,"EN COURS D'ENGAGEMENT") -> 2776080 | E5: =SUMIFS(Données!$D$2:$D$599,Données!$A$2:$A$599,$A5,Données!$B$2:$B$599,"FONCTIONNEMENT",Données!$C$2:$C$599,"EN COURS DE PREENGAGEMENT") -> 0 | F5: =SUMIFS(Données!$D$2:$D$599,Données!$A$2:$A$599,$A5,Données!$B$2:$B$599,"FONCTIONNEMENT",Données!$C$2:$C$599,"NON ENGAGE") -> 0 | G5: =SUM(B5:F5) -> 1.7993517e+08 | H5: =SUMIFS(Données!$D$2:$D$599,Données!$A$2:$A$599,$A5,Données!$B$2:$B$599,"INVESTISSEMENT",Données!$C$2:$C$599,"ENGAGE") -> 0 | I5: =SUMIFS(Données!$D$2:$D$599,Données!$A$2:$A$599,$A5,Données!$B$2:$B$599,"INVESTISSEMENT",Données!$C$2:$C$599,"PREENGAGE") -> 0 | J5: =SUMIFS(Données!$D$2:$D$599,Données!$A$2:$A$599,$A5,Données!$B$2:$B$599,"INVESTISSEMENT",Données!$C$2:$C$599,"EN COURS D'ENGAGEMENT") -> 0 | K5: =SUMIFS(Données!$D$2:$D$599,Données!$A$2:$A$599,$A5,Données!$B$2:$B$599,"INVESTISSEMENT",Données!$C$2:$C$599,"EN COURS DE PREENGAGEMENT") -> 0 | L5: =SUMIFS(Données!$D$2:$D$599,Données!$A$2:$A$599,$A5,Données!$B$2:$B$599,"INVESTISSEMENT",Données!$C$2:$C$599,"NON ENGAGE") -> 0 | M5: =SUM(H5:L5) -> 0 | N5: =G5+M5 -> 1.7993517e+08
A6: ASSADISSA | B6: =SUMIFS(Données!$D$2:$D$599,Données!$A$2:$A$599,$A6,Données!$B$2:$B$599,"FONCTIONNEMENT",Données!$C$2:$C$599,"ENGAGE") -> 8022706.3 | C6: =SUMIFS(Données!$D$2:$D$599,Données!$A$2:$A$599,$A6,Données!$B$2:$B$599,"FONCTIONNEMENT",Données!$C$2:$C$599,"PREENGAGE") -> 0 | D6: =SUMIFS(Données!$D$2:$D$599,Données!$A$2:$A$599,$A6,Données!$B$2:$B$599,"FONCTIONNEMENT",Données!$C$2:$C$599,"EN COURS D'ENGAGEMENT") -> 0 | E6: =SUMIFS(Données!$D$2:$D$599,Données!$A$2:$A$599,$A6,Données!$B$2:$B$599,"FONCTIONNEMENT",Données!$C$2:$C$599,"EN COURS DE PREENGAGEMENT") -> 0 | F6: =SUMIFS(Données!$D$2:$D$599,Données!$A$2:$A$599,$A6,Données!$B$2:$B$599,"FONCTIONNEMENT",Données!$C$2:$C$599,"NON ENGAGE") -> 0 | G6: =SUM(B6:F6) -> 8022706.3 | H6: =SUMIFS(Données!$D$2:$D$599,Données!$A$2:$A$599,$A6,Données!$B$2:$B$599,"INVESTISSEMENT",Données!$C$2:$C$599,"ENGAGE") -> 0 | I6: =SUMIFS(Données!$D$2:$D$599,Données!$A$2:$A$599,$A6,Données!$B$2:$B$599,"INVESTISSEMENT",Données!$C$2:$C$599,"PREENGAGE") -> 0 | J6: =SUMIFS(Données!$D$2:$D$599,Données!$A$2:$A$599,$A6,Données!$B$2:$B$599,"INVESTISSEMENT",Données!$C$2:$C$599,"EN COURS D'ENGAGEMENT") -> 0 | K6: =SUMIFS(Données!$D$2:$D$599,Données!$A$2:$A$599,$A6,Données!$B$2:$B$599,"INVESTISSEMENT",Données!$C$2:$C$599,"EN COURS DE PREENGAGEMENT") -> 0 | L6: =SUMIFS(Données!$D$2:$D$599,Données!$A$2:$A$599,$A6,Données!$B$2:$B$599,"INVESTISSEMENT",Données!$C$2:$C$599,"NON ENGAGE") -> 0 | M6: =SUM(H6:L6) -> 0 | N6: =G6+M6 -> 8022706.3
A7: DA | B7: =SUMIFS(Données!$D$2:$D$599,Données!$A$2:$A$599,$A7,Données!$B$2:$B$599,"FONCTIONNEMENT",Données!$C$2:$C$599,"ENGAGE") -> 427760 | C7: =SUMIFS(Données!$D$2:$D$599,Données!$A$2:$A$599,$A7,Données!$B$2:$B$599,"FONCTIONNEMENT",Données!$C$2:$C$599,"PREENGAGE") -> 0 | D7: =SUMIFS(Données!$D$2:$D$599,Données!$A$2:$A$599,$A7,Données!$B$2:$B$599,"FONCTIONNEMENT",Données!$C$2:$C$599,"EN COURS D'ENGAGEMENT") -> 0 | E7: =SUMIFS(Données!$D$2:$D$599,Données!$A$2:$A$599,$A7,Données!$B$2:$B$599,"FONCTIONNEMENT",Données!$C$2:$C$599,"EN COURS DE PREENGAGEMENT") -> 0 | F7: =SUMIFS(Données!$D$2:$D$599,Données!$A$2:$A$599,$A7,Données!$B$2:$B$599,"FONCTIONNEMENT",Données!$C$2:$C$599,"NON ENGAGE") -> 0 | G7: =SUM(B7:F7) -> 427760 | H7: =SUMIFS(Données!$D$2:$D$599,Données!$A$2:$A$599,$A7,Données!$B$2:$B$599,"INVESTISSEMENT",Données!$C$2:$C$599,"ENGAGE") -> 0 | I7: =SUMIFS(Données!$D$2:$D$599,Données!$A$2:$A$599,$A7,Données!$B$2:$B$599,"INVESTISSEMENT",Données!$C$2:$C$599,"PREENGAGE") -> 0 | J7: =SUMIFS(Données!$D$2:$D$599,Données!$A$2:$A$599,$A7,Données!$B$2:$B$599,"INVESTISSEMENT",Données!$C$2:$C$599,"EN COURS D'ENGAGEMENT") -> 0 | K7: =SUMIFS(Données!$D$2:$D$599,Données!$A$2:$A$599,$A7,Données!$B$2:$B$599,"INVESTISSEMENT",Données!$C$2:$C$599,"EN COURS DE PREENGAGEMENT") -> 0 | L7: =SUMIFS(Données!$D$2:$D$599,Données!$A$2:$A$599,$A7,Données!$B$2:$B$599,"INVESTISSEMENT",Données!$C$2:$C$599,"NON ENGAGE") -> 0 | M7: =SUM(H7:L7) -> 0 | N7: =G7+M7 -> 427760
A8: DACG | B8: =SUMIFS(Données!$D$2:$D$599,Données!$A$2:$A$599,$A8,Données!$B$2:$B$599,"FONCTIONNEMENT",Données!$C$2:$C$599,"ENGAGE") -> 318500 | C8: =SUMIFS(Données!$D$2:$D$599,Données!$A$2:$A$599,$A8,Données!$B$2:$B$599,"FONCTIONNEMENT",Données!$C$2:$C$599,"PREENGAGE") -> 0 | D8: =SUMIFS(Données!$D$2:$D$599,Données!$A$2:$A$599,$A8,Données!$B$2:$B$599,"FONCTIONNEMENT",Données!$C$2:$C$599,"EN COURS D'ENGAGEMENT") -> 0 | E8: =SUMIFS(Données!$D$2:$D$599,Données!$A$2:$A$599,$A8,Données!$B$2:$B$599,"FONCTIONNEMENT",Données!$C$2:$C$599,"EN COURS DE PREENGAGEMENT") -> 0 | F8: =SUMIFS(Données!$D$2:$D$599,Données!$A$2:$A$599,$A8,Données!$B$2:$B$599,"FONCTIONNEMENT",Données!$C$2:$C$599,"NON ENGAGE") -> 0 | G8: =SUM(B8:F8) -> 318500 | H8: =SUMIFS(Données!$D$2:$D$599,Données!$A$2:$A$599,$A8,Données!$B$2:$B$599,"INVESTISSEMENT",Données!$C$2:$C$599,"ENGAGE") -> 0 | I8: =SUMIFS(Données!$D$2:$D$599,Données!$A$2:$A$599,$A8,Données!$B$2:$B$599,"INVESTISSEMENT",Données!$C$2:$C$599,"PREENGAGE") -> 0 | J8: =SUMIFS(Données!$D$2:$D$599,Données!$A$2:$A$599,$A8,Données!$B$2:$B$599,"INVESTISSEMENT",Données!$C$2:$C$599,"EN COURS D'ENGAGEMENT") -> 0 | K8: =SUMIFS(Données!$D$2:$D$599,Données!$A$2:$A$599,$A8,Données!$B$2:$B$599,"INVESTISSEMENT",Données!$C$2:$C$599,"EN COURS DE PREENGAGEMENT") -> 0 | L8: =SUMIFS(Données!$D$2:$D$599,Données!$A$2:$A$599,$A8,Données!$B$2:$B$599,"INVESTISSEMENT",Données!$C$2:$C$599,"NON ENGAGE") -> 0 | M8: =SUM(H8:L8) -> 0 | N8: =G8+M8 -> 318500
A9: DAR | B9: =SUMIFS(Données!$D$2:$D$599,Données!$A$2:$A$599,$A9,Données!$B$2:$B$599,"FONCTIONNEMENT",Données!$C$2:$C$599,"ENGAGE") -> 108000 | C9: =SUMIFS(Données!$D$2:$D$599,Données!$A$2:$A$599,$A9,Données!$B$2:$B$599,"FONCTIONNEMENT",Données!$C$2:$C$599,"PREENGAGE") -> 0 | D9: =SUMIFS(Données!$D$2:$D$599,Données!$A$2:$A$599,$A9,Données!$B$2:$B$599,"FONCTIONNEMENT",Données!$C$2:$C$599,"EN COURS D'ENGAGEMENT") -> 0 | E9: =SUMIFS(Données!$D$2:$D$599,Données!$A$2:$A$599,$A9,Données!$B$2:$B$599,"FONCTIONNEMENT",Données!$C$2:$C$599,"EN COURS DE PREENGAGEMENT") -> 0 | F9: =SUMIFS(Données!$D$2:$D$599,Données!$A$2:$A$599,$A9,Données!$B$2:$B$599,"FONCTIONNEMENT",Données!$C$2:$C$599,"NON ENGAGE") -> 0 | G9: =SUM(B9:F9) -> 108000 | H9: =SUMIFS(Données!$D$2:$D$599,Données!$A$2:$A$599,$A9,Données!$B$2:$B$599,"INVESTISSEMENT",Données!$C$2:$C$599,"ENGAGE") -> 0 | I9: =SUMIFS(Données!$D$2:$D$599,Données!$A$2:$A$599,$A9,Données!$B$2:$B$599,"INVESTISSEMENT",Données!$C$2:$C$599,"PREENGAGE") -> 0 | J9: =SUMIFS(Données!$D$2:$D$599,Données!$A$2:$A$599,$A9,Données!$B$2:$B$599,"INVESTISSEMENT",Données!$C$2:$C$599,"EN COURS D'ENGAGEMENT") -> 0 | K9: =SUMIFS(Données!$D$2:$D$599,Données!$A$2:$A$599,$A9,Données!$B$2:$B$599,"INVESTISSEMENT",Données!$C$2:$C$599,"EN COURS DE PREENGAGEMENT") -> 0 | L9: =SUMIFS(Données!$D$2:$D$599,Données!$A$2:$A$599,$A9,Données!$B$2:$B$599,"INVESTISSEMENT",Données!$C$2:$C$599,"NON ENGAGE") -> 0 | M9: =SUM(H9:L9) -> 0 | N9: =G9+M9 -> 108000
A10: DCPA | B10: =SUMIFS(Données!$D$2:$D$599,Données!$A$2:$A$599,$A10,Données!$B$2:$B$599,"FONCTIONNEMENT",Données!$C$2:$C$599,"ENGAGE") -> 17321794 | C10: =SUMIFS(Données!$D$2:$D$599,Données!$A$2:$A$599,$A10,Données!$B$2:$B$599,"FONCTIONNEMENT",Données!$C$2:$C$599,"PREENGAGE") -> 0 | D10: =SUMIFS(Données!$D$2:$D$599,Données!$A$2:$A$599,$A10,Données!$B$2:$B$599,"FONCTIONNEMENT",Données!$C$2:$C$599,"EN COURS D'ENGAGEMENT") -> 0 | E10: =SUMIFS(Données!$D$2:$D$599,Données!$A$2:$A$599,$A10,Données!$B$2:$B$599,"FONCTIONNEMENT",Données!$C$2:$C$599,"EN COURS DE PREENGAGEMENT") -> 0 | F10: =SUMIFS(Données!$D$2:$D$599,Données!$A$2:$A$599,$A10,Données!$B$2:$B$599,"FONCTIONNEMENT",Données!$C$2:$C$599,"NON ENGAGE") -> 0 | G10: =SUM(B10:F10) -> 17321794 | H10: =SUMIFS(Données!$D$2:$D$599,Données!$A$2:$A$599,$A10,Données!$B$2:$B$599,"INVESTISSEMENT",Données!$C$2:$C$599,"ENGAGE") -> 0 | I10: =SUMIFS(Données!$D$2:$D$599,Données!$A$2:$A$599,$A10,Données!$B$2:$B$599,"INVESTISSEMENT",Données!$C$2:$C$599,"PREENGAGE") -> 0 | J10: =SUMIFS(Données!$D$2:$D$599,Données!$A$2:$A$599,$A10,Données!$B$2:$B$599,"INVESTISSEMENT",Données!$C$2:$C$599,"EN COURS D'ENGAGEMENT") -> 0 | K10: =SUMIFS(Données!$D$2:$D$599,Données!$A$2:$A$599,$A10,Données!$B$2:$B$599,"INVESTISSEMENT",Données!$C$2:$C$599,"EN COURS DE PREENGAGEMENT") -> 0 | L10: =SUMIFS(Données!$D$2:$D$599,Données!$A$2:$A$599,$A10,Données!$B$2:$B$599,"INVESTISSEMENT",Données!$C$2:$C$599,"NON ENGAGE") -> 0 | M10: =SUM(H10:L10) -> 0 | N10: =G10+M10 -> 17321794
A11: DCRI | B11: =SUMIFS(Données!$D$2:$D$599,Données!$A$2:$A$599,$A11,Données!$B$2:$B$599,"FONCTIONNEMENT",Données!$C$2:$C$599,"ENGAGE") -> 318240 | C11: =SUMIFS(Données!$D$2:$D$599,Données!$A$2:$A$599,$A11,Données!$B$2:$B$599,"FONCTIONNEMENT",Données!$C$2:$C$599,"PREENGAGE") -> 0 | D11: =SUMIFS(Données!$D$2:$D$599,Données!$A$2:$A$599,$A11,Données!$B$2:$B$599,"FONCTIONNEMENT",Données!$C$2:$C$599,"EN COURS D'ENGAGEMENT") -> 0 | E11: =SUMIFS(Données!$D$2:$D$599,Données!$A$2:$A$599,$A11,Données!$B$2:$B$599,"FONCTIONNEMENT",Données!$C$2:$C$599,"EN COURS DE PREENGAGEMENT") -> 0 | F11: =SUMIFS(Données!$D$2:$D$599,Données!$A$2:$A$599,$A11,Données!$B$2:$B$599,"FONCTIONNEMENT",Données!$C$2:$C$599,"NON ENGAGE") -> 0 | G11: =SUM(B11:F11) -> 318240 | H11: =SUMIFS(Données!$D$2:$D$599,Données!$A$2:$A$599,$A11,Données!$B$2:$B$599,"INVESTISSEMENT",Données!$C$2:$C$599,"ENGAGE") -> 0 | I11: =SUMIFS(Données!$D$2:$D$599,Données!$A$2:$A$599,$A11,Données!$B$2:$B$599,"INVESTISSEMENT",Données!$C$2:$C$599,"PREENGAGE") -> 0 | J11: =SUMIFS(Données!$D$2:$D$599,Données!$A$2:$A$599,$A11,Données!$B$2:$B$599,"INVESTISSEMENT",Données!$C$2:$C$599,"EN COURS D'ENGAGEMENT") -> 0 | K11: =SUMIFS(Données!$D$2:$D$599,Données!$A$2:$A$599,$A11,Données!$B$2:$B$599,"INVESTISSEMENT",Données!$C$2:$C$599,"EN COURS DE PREENGAGEMENT") -> 0 | L11: =SUMIFS(Données!$D$2:$D$599,Données!$A$2:$A$599,$A11,Données!$B$2:$B$599,"INVESTISSEMENT",Données!$C$2:$C$599,"NON ENGAGE") -> 0 | M11: =SUM(H11:L11) -> 0 | N11: =G11+M11 -> 318240
A12: DG | B12: =SUMIFS(Données!$D$2:$D$599,Données!$A$2:$A$599,$A12,Données!$B$2:$B$599,"FONCTIONNEMENT",Données!$C$2:$C$599,"ENGAGE") -> 576000 | C12: =SUMIFS(Données!$D$2:$D$599,Données!$A$2:$A$599,$A12,Données!$B$2:$B$599,"FONCTIONNEMENT",Données!$C$2:$C$599,"PREENGAGE") -> 0 | D12: =SUMIFS(Données!$D$2:$D$599,Données!$A$2:$A$599,$A12,Données!$B$2:$B$599,"FONCTIONNEMENT",Données!$C$2:$C$599,"EN COURS D'ENGAGEMENT") -> 0 | E12: =SUMIFS(Données!$D$2:$D$599,Données!$A$2:$A$599,$A12,Données!$B$2:$B$599,"FONCTIONNEMENT",Données!$C$2:$C$599,"EN COURS DE PREENGAGEMENT") -> 0 | F12: =SUMIFS(Données!$D$2:$D$599,Données!$A$2:$A$599,$A12,Données!$B$2:$B$599,"FONCTIONNEMENT",Données!$C$2:$C$599,"NON ENGAGE") -> 0 | G12: =SUM(B12:F12) -> 576000 | H12: =SUMIFS(Données!$D$2:$D$599,Données!$A$2:$A$599,$A12,Données!$B$2:$B$599,"INVESTISSEMENT",Données!$C$2:$C$599,"ENGAGE") -> 0 | I12: =SUMIFS(Données!$D$2:$D$599,Données!$A$2:$A$599,$A12,Données!$B$2:$B$599,"INVESTISSEMENT",Données!$C$2:$C$599,"PREENGAGE") -> 0 | J12: =SUMIFS(Données!$D$2:$D$599,Données!$A$2:$A$599,$A12,Données!$B$2:$B$599,"INVESTISSEMENT",Données!$C$2:$C$599,"EN COURS D'ENGAGEMENT") -> 0 | K12: =SUMIFS(Données!$D$2:$D$599,Données!$A$2:$A$599,$A12,Données!$B$2:$B$599,"INVESTISSEMENT",Données!$C$2:$C$599,"EN COURS DE PREENGAGEMENT") -> 0 | L12: =SUMIFS(Données!$D$2:$D$599,Données!$A$2:$A$599,$A12,Données!$B$2:$B$599,"INVESTISSEMENT",Données!$C$2:$C$599,"NON ENGAGE") -> 0 | M12: =SUM(H12:L12) -> 0 | N12: =G12+M12 -> 576000
A13: DINFORADIO | B13: =SUMIFS(Données!$D$2:$D$599,Données!$A$2:$A$599,$A13,Données!$B$2:$B$599,"FONCTIONNEMENT",Données!$C$2:$C$599,"ENGAGE") -> 2648832.5 | C13: =SUMIFS(Données!$D$2:$D$599,Données!$A$2:$A$599,$A13,Données!$B$2:$B$599,"FONCTIONNEMENT",Données!$C$2:$C$599,"PREENGAGE") -> 0 | D13: =SUMIFS(Données!$D$2:$D$599,Données!$A$2:$A$599,$A13,Données!$B$2:$B$599,"FONCTIONNEMENT",Données!$C$2:$C$599,"EN COURS D'ENGAGEMENT") -> 0 | E13: =SUMIFS(Données!$D$2:$D$599,Données!$A$2:$A$599,$A13,Données!$B$2:$B$599,"FONCTIONNEMENT",Données!$C$2:$C$599,"EN COURS DE PREENGAGEMENT") -> 0 | F13: =SUMIFS(Données!$D$2:$D$599,Données!$A$2:$A$599,$A13,Données!$B$2:$B$599,"FONCTIONNEMENT",Données!$C$2:$C$599,"NON ENGAGE") -> 0 | G13: =SUM(B13:F13) -> 2648832.5 | H13: =SUMIFS(Données!$D$2:$D$599,Données!$A$2:$A$599,$A13,Données!$B$2:$B$599,"INVESTISSEMENT",Données!$C$2:$C$599,"ENGAGE") -> 0 | I13: =SUMIFS(Données!$D$2:$D$599,Données!$A$2:$A$599,$A13,Données!$B$2:$B$599,"INVESTISSEMENT",Données!$C$2:$C$599,"PREENGAGE") -> 0 | J13: =SUMIFS(Données!$D$2:$D$599,Données!$A$2:$A$599,$A13,Données!$B$2:$B$599,"INVESTISSEMENT",Données!$C$2:$C$599,"EN COURS D'ENGAGEMENT") -> 0 | K13: =SUMIFS(Données!$D$2:$D$599,Données!$A$2:$A$599,$A13,Données!$B$2:$B$599,"INVESTISSEMENT",Données!$C$2:$C$599,"EN COURS DE PREENGAGEMENT") -> 0 | L13: =SUMIFS(Données!$D$2:$D$599,Données!$A$2:$A$599,$A13,Données!$B$2:$B$599,"INVESTISSEMENT",Données!$C$2:$C$599,"NON ENGAGE") -> 0 | M13: =SUM(H13:L13) -> 0 | N13: =G13+M13 -> 2648832.5
A14: DINFOTV | B14: =SUMIFS(Données!$D$2:$D$599,Données!$A$2:$A$599,$A14,Données!$B$2:$B$599,"FONCTIONNEMENT",Données!$C$2:$C$599,"ENGAGE") -> 10711701 | C14: =SUMIFS(Données!$D$2:$D$599,Données!$A$2:$A$599,$A14,Données!$B$2:$B$599,"FONCTIONNEMENT",Données!$C$2:$C$599,"PREENGAGE") -> 76464 | D14: =SUMIFS(Données!$D$2:$D$599,Données!$A$2:$A$599,$A14,Données!$B$2:$B$599,"FONCTIONNEMENT",Données!$C$2:$C$599,"EN COURS D'ENGAGEMENT") -> 0 | E14: =SUMIFS(Données!$D$2:$D$599,Données!$A$2:$A$599,$A14,Données!$B$2:$B$599,"FONCTIONNEMENT",Données!$C$2:$C$599,"EN COURS DE PREENGAGEMENT") -> 0 | F14: =SUMIFS(Données!$D$2:$D$599,Données!$A$2:$A$599,$A14,Données!$B$2:$B$599,"FONCTIONNEMENT",Données!$C$2:$C$599,"NON ENGAGE") -> 0 | G14: =SUM(B14:F14) -> 10788165 | H14: =SUMIFS(Données!$D$2:$D$599,Données!$A$2:$A$599,$A14,Données!$B$2:$B$599,"INVESTISSEMENT",Données!$C$2:$C$599,"ENGAGE") -> 0 | I14: =SUMIFS(Données!$D$2:$D$599,Données!$A$2:$A$599,$A14,Données!$B$2:$B$599,"INVESTISSEMENT",Données!$C$2:$C$599,"PREENGAGE") -> 0 | J14: =SUMIFS(Données!$D$2:$D$599,Données!$A$2:$A$599,$A14,Données!$B$2:$B$599,"INVESTISSEMENT",Données!$C$2:$C$599,"EN COURS D'ENGAGEMENT") -> 0 | K14: =SUMIFS(Données!$D$2:$D$599,Données!$A$2:$A$599,$A14,Données!$B$2:$B$599,"INVESTISSEMENT",Données!$C$2:$C$599,"EN COURS DE PREENGAGEMENT") -> 0 | L14: =SUMIFS(Données!$D$2:$D$599,Données!$A$2:$A$599,$A14,Données!$B$2:$B$599,"INVESTISSEMENT",Données!$C$2:$C$599,"NON ENGAGE") -> 0 | M14: =SUM(H14:L14) -> 0 | N14: =G14+M14 -> 10788165
A15: DJURIDIQUE | B15: =SUMIFS(Données!$D$2:$D$599,Données!$A$2:$A$599,$A15,Données!$B$2:$B$599,"FONCTIONNEMENT",Données!$C$2:$C$599,"ENGAGE") -> 8551887.7 | C15: =SUMIFS(Données!$D$2:$D$599,Données!$A$2:$A$599,$A15,Données!$B$2:$B$599,"FONCTIONNEMENT",Données!$C$2:$C$599,"PREENGAGE") -> 0 | D15: =SUMIFS(Données!$D$2:$D$599,Données!$A$2:$A$599,$A15,Données!$B$2:$B$599,"FONCTIONNEMENT",Données!$C$2:$C$599,"EN COURS D'ENGAGEMENT") -> 0 | E15: =SUMIFS(Données!$D$2:$D$599,Données!$A$2:$A$599,$A15,Données!$B$2:$B$599,"FONCTIONNEMENT",Données!$C$2:$C$599,"EN COURS DE PREENGAGEMENT") -> 0 | F15: =SUMIFS(Données!$D$2:$D$599,Données!$A$2:$A$599,$A15,Données!$B$2:$B$599,"FONCTIONNEMENT",Données!$C$2:$C$599,"NON ENGAGE") -> 0 | G15: =SUM(B15:F15) -> 8551887.7 | H15: =SUMIFS(Données!$D$2:$D$599,Données!$A$2:$A$599,$A15,Données!$B$2:$B$599,"INVESTISSEMENT",Données!$C$2:$C$599,"ENGAGE") -> 0 | I15: =SUMIFS(Données!$D$2:$D$599,Données!$A$2:$A$599,$A15,Données!$B$2:$B$599,"INVESTISSEMENT",Données!$C$2:$C$599,"PREENGAGE") -> 0 | J15: =SUMIFS(Données!$D$2:$D$599,Données!$A$2:$A$599,$A15,Données!$B$2:$B$599,"INVESTISSEMENT",Données!$C$2:$C$599,"EN COURS D'ENGAGEMENT") -> 0 | K15: =SUMIFS(Données!$D$2:$D$599,Données!$A$2:$A$599,$A15,Données!$B$2:$B$599,"INVESTISSEMENT",Données!$C$2:$C$599,"EN COURS DE PREENGAGEMENT") -> 0 | L15: =SUMIFS(Données!$D$2:$D$599,Données!$A$2:$A$599,$A15,Données!$B$2:$B$599,"INVESTISSEMENT",Données!$C$2:$C$599,"NON ENGAGE") -> 0 | M15: =SUM(H15:L15) -> 0 | N15: =G15+M15 -> 8551887.7
A16: DMPTV | B16: =SUMIFS(Données!$D$2:$D$599,Données!$A$2:$A$599,$A16,Données!$B$2:$B$599,"FONCTIONNEMENT",Données!$C$2:$C$599,"ENGAGE") -> 23694428 | C16: =SUMIFS(Données!$D$2:$D$599,Données!$A$2:$A$599,$A16,Données!$B$2:$B$599,"FONCTIONNEMENT",Données!$C$2:$C$599,"PREENGAGE") -> 0 | D16: =SUMIFS(Données!$D$2:$D$599,Données!$A$2:$A$599,$A16,Données!$B$2:$B$599,"FONCTIONNEMENT",Données!$C$2:$C$599,"EN COURS D'ENGAGEMENT") -> 0 | E16: =SUMIFS(Données!$D$2:$D$599,Données!$A$2:$A$599,$A16,Données!$B$2:$B$599,"FONCTIONNEMENT",Données!$C$2:$C$599,"EN COURS DE PREENGAGEMENT") -> 0 | F16: =SUMIFS(Données!$D$2:$D$599,Données!$A$2:$A$599,$A16,Données!$B$2:$B$599,"FONCTIONNEMENT",Données!$C$2:$C$599,"NON ENGAGE") -> 0 | G16: =SUM(B16:F16) -> 23694428 | H16: =SUMIFS(Données!$D$2:$D$599,Données!$A$2:$A$599,$A16,Données!$B$2:$B$599,"INVESTISSEMENT",Données!$C$2:$C$599,"ENGAGE") -> 198971.91 | I16: =SUMIFS(Données!$D$2:$D$599,Données!$A$2:$A$599,$A16,Données!$B$2:$B$599,"INVESTISSEMENT",Données!$C$2:$C$599,"PREENGAGE") -> 0 | J16: =SUMIFS(Données!$D$2:$D$599,Données!$A$2:$A$599,$A16,Données!$B$2:$B$599,"INVESTISSEMENT",Données!$C$2:$C$599,"EN COURS D'ENGAGEMENT") -> 0 | K16: =SUMIFS(Données!$D$2:$D$599,Données!$A$2:$A$599,$A16,Données!$B$2:$B$599,"INVESTISSEMENT",Données!$C$2:$C$599,"EN COURS DE PREENGAGEMENT") -> 0 | L16: =SUMIFS(Données!$D$2:$D$599,Données!$A$2:$A$599,$A16,Données!$B$2:$B$599,"INVESTISSEMENT",Données!$C$2:$C$599,"NON ENGAGE") -> 0 | M16: =SUM(H16:L16) -> 198971.91 | N16: =G16+M16 -> 23893400
... A26: TV LAAYOUNE | B26: =SUMIFS(Données!$D$2:$D$599,Données!$A$2:$A$599,$A26,Données!$B$2:$B$599,"FONCTIONNEMENT",Données!$C$2:$C$599,"ENGAGE") -> 22592636 | C26: =SUMIFS(Données!$D$2:$D$599,Données!$A$2:$A$599,$A26,Données!$B$2:$B$599,"FONCTIONNEMENT",Données!$C$2:$C$599,"PREENGAGE") -> 0 | D26: =SUMIFS(Données!$D$2:$D$599,Données!$A$2:$A$599,$A26,Données!$B$2:$B$599,"FONCTIONNEMENT",Données!$C$2:$C$599,"EN COURS D'ENGAGEMENT") -> 0 | E26: =SUMIFS(Données!$D$2:$D$599,Données!$A$2:$A$599,$A26,Données!$B$2:$B$599,"FONCTIONNEMENT",Données!$C$2:$C$599,"EN COURS DE PREENGAGEMENT") -> 0 | F26: =SUMIFS(Données!$D$2:$D$599,Données!$A$2:$A$599,$A26,Données!$B$2:$B$599,"FONCTIONNEMENT",Données!$C$2:$C$599,"NON ENGAGE") -> 0 | G26: =SUM(B26:F26) -> 22592636 | H26: =SUMIFS(Données!$D$2:$D$599,Données!$A$2:$A$599,$A26,Données!$B$2:$B$599,"INVESTISSEMENT",Données!$C$2:$C$599,"ENGAGE") -> 0 | I26: =SUMIFS(Données!$D$2:$D$599,Données!$A$2:$A$599,$A26,Données!$B$2:$B$599,"INVESTISSEMENT",Données!$C$2:$C$599,"PREENGAGE") -> 0 | J26: =SUMIFS(Données!$D$2:$D$599,Données!$A$2:$A$599,$A26,Données!$B$2:$B$599,"INVESTISSEMENT",Données!$C$2:$C$599,"EN COURS D'ENGAGEMENT") -> 0 | K26: =SUMIFS(Données!$D$2:$D$599,Données!$A$2:$A$599,$A26,Données!$B$2:$B$599,"INVESTISSEMENT",Données!$C$2:$C$599,"EN COURS DE PREENGAGEMENT") -> 0 | L26: =SUMIFS(Données!$D$2:$D$599,Données!$A$2:$A$599,$A26,Données!$B$2:$B$599,"INVESTISSEMENT",Données!$C$2:$C$599,"NON ENGAGE") -> 0 | M26: =SUM(H26:L26) -> 0 | N26: =G26+M26 -> 22592636
A27: TOTAL GÉNÉRAL | B27: =SUM(B5:B26) -> 5.487332e+08 | C27: =SUM(C5:C26) -> 1216124.4 | D27: =SUM(D5:D26) -> 3569753.2 | E27: =SUM(E5:E26) -> 0 | F27: =SUM(F5:F26) -> 96000 | G27: =SUM(G5:G26) -> 5.5361508e+08 | H27: =SUM(H5:H26) -> 21806087 | I27: =SUM(I5:I26) -> 2996713.2 | ... N27: =SUM(N5:N26) -> 5.7903093e+08

Sheet Achats par Direction
A1: ANALYSE DES ACHATS PAR DIRECTION & TYPE — SNRT · BUDGET 2026
A2: Nombre de lignes & montants TTC (MAD) par type d'achat — calcul dynamique depuis « DATA_ACHATS ». Cliquez sur une direction pour voir sa fiche.
A4: LIGNES TOTALES | D4: MONTANT TOTAL (MAD) | G4: DIRECTIONS | J4: MONTANT ENGAGÉ | M4: TAUX D'ENGAGEMENT
A5: =COUNTA(DATA_ACHATS!A2:A599) -> 598 | D5: =SUM(DATA_ACHATS!E2:E599) -> 5.7903093e+08 | G5: 22 | J5: =SUMIFS(DATA_ACHATS!E:E,DATA_ACHATS!C:C,"ENGAGE") -> 5.7053929e+08 | M5: =IFERROR(SUMIFS(DATA_ACHATS!E:E,DATA_ACHATS!C:C,"ENGAGE")/SUM(DATA_ACHATS!E2:E599),0) -> 0.98533473
A7: ACCÈS RAPIDE — CLIQUEZ SUR UNE DIRECTION ▼
A8: ARRIYADIA | D8: ASSADISSA | G8: DA | J8: DACG
A9: DAR | D9: DCPA | G9: DCRI | J9: DG
A10: DINFORADIO | D10: DINFOTV | G10: DJURIDIQUE | J10: DMPTV
A11: DPMG | D11: DPPR | G11: DRH | J11: DRPSD
A12: DTSI | D12: MAGHRIBIA | G12: TAMAZIGHT | J12: TDF -SITES
A13: TDF-EXP&MAIN | D13: TV LAAYOUNE
A15: MATRICE — NOMBRE DE LIGNES & MONTANT (MAD) PAR TYPE D'ACHAT
A16: DIRECTION | B16: CONTRAT | D16: AOO-M | F16: AOO-CT | H16: BCL | J16: BCI | L16: TOTAL
B17: Nb | C17: Montant | D17: Nb | E17: Montant | F17: Nb | G17: Montant | H17: Nb | I17: Montant | J17: Nb | K17: Montant | L17: Nb | M17: Montant
A18: ARRIYADIA | B18: =COUNTIFS(DATA_ACHATS!$A:$A,$A18,DATA_ACHATS!$D:$D,"CONTRAT") -> 73 | C18: =SUMIFS(DATA_ACHATS!$E:$E,DATA_ACHATS!$A:$A,$A18,DATA_ACHATS!$D:$D,"CONTRAT") -> 1.7993517e+08 | D18: =COUNTIFS(DATA_ACHATS!$A:$A,$A18,DATA_ACHATS!$D:$D,"AOO-M") -> 0 | E18: =SUMIFS(DATA_ACHATS!$E:$E,DATA_ACHATS!$A:$A,$A18,DATA_ACHATS!$D:$D,"AOO-M") -> 0 | F18: =COUNTIFS(DATA_ACHATS!$A:$A,$A18,DATA_ACHATS!$D:$D,"AOO-CT") -> 0 | G18: =SUMIFS(DATA_ACHATS!$E:$E,DATA_ACHATS!$A:$A,$A18,DATA_ACHATS!$D:$D,"AOO-CT") -> 0 | H18: =COUNTIFS(DATA_ACHATS!$A:$A,$A18,DATA_ACHATS!$D:$D,"BCL") -> 0 | I18: =SUMIFS(DATA_ACHATS!$E:$E,DATA_ACHATS!$A:$A,$A18,DATA_ACHATS!$D:$D,"BCL") -> 0 | J18: =COUNTIFS(DATA_ACHATS!$A:$A,$A18,DATA_ACHATS!$D:$D,"BCI") -> 0 | K18: =SUMIFS(DATA_ACHATS!$E:$E,DATA_ACHATS!$A:$A,$A18,DATA_ACHATS!$D:$D,"BCI") -> 0 | L18: =COUNTIF(DATA_ACHATS!$A:$A,$A18) -> 73 | M18: =SUMIF(DATA_ACHATS!$A:$A,$A18,DATA_ACHATS!$E:$E) -> 1.7993517e+08
A19: ASSADISSA | B19: =COUNTIFS(DATA_ACHATS!$A:$A,$A19,DATA_ACHATS!$D:$D,"CONTRAT") -> 81 | C19: =SUMIFS(DATA_ACHATS!$E:$E,DATA_ACHATS!$A:$A,$A19,DATA_ACHATS!$D:$D,"CONTRAT") -> 8022706.3 | D19: =COUNTIFS(DATA_ACHATS!$A:$A,$A19,DATA_ACHATS!$D:$D,"AOO-M") -> 0 | E19: =SUMIFS(DATA_ACHATS!$E:$E,DATA_ACHATS!$A:$A,$A19,DATA_ACHATS!$D:$D,"AOO-M") -> 0 | F19: =COUNTIFS(DATA_ACHATS!$A:$A,$A19,DATA_ACHATS!$D:$D,"AOO-CT") -> 0 | G19: =SUMIFS(DATA_ACHATS!$E:$E,DATA_ACHATS!$A:$A,$A19,DATA_ACHATS!$D:$D,"AOO-CT") -> 0 | H19: =COUNTIFS(DATA_ACHATS!$A:$A,$A19,DATA_ACHATS!$D:$D,"BCL") -> 0 | I19: =SUMIFS(DATA_ACHATS!$E:$E,DATA_ACHATS!$A:$A,$A19,DATA_ACHATS!$D:$D,"BCL") -> 0 | J19: =COUNTIFS(DATA_ACHATS!$A:$A,$A19,DATA_ACHATS!$D:$D,"BCI") -> 0 | K19: =SUMIFS(DATA_ACHATS!$E:$E,DATA_ACHATS!$A:$A,$A19,DATA_ACHATS!$D:$D,"BCI") -> 0 | L19: =COUNTIF(DATA_ACHATS!$A:$A,$A19) -> 81 | M19: =SUMIF(DATA_ACHATS!$A:$A,$A19,DATA_ACHATS!$E:$E) -> 8022706.3
A20: DA | B20: =COUNTIFS(DATA_ACHATS!$A:$A,$A20,DATA_ACHATS!$D:$D,"CONTRAT") -> 5 | C20: =SUMIFS(DATA_ACHATS!$E:$E,DATA_ACHATS!$A:$A,$A20,DATA_ACHATS!$D:$D,"CONTRAT") -> 427760 | D20: =COUNTIFS(DATA_ACHATS!$A:$A,$A20,DATA_ACHATS!$D:$D,"AOO-M") -> 0 | E20: =SUMIFS(DATA_ACHATS!$E:$E,DATA_ACHATS!$A:$A,$A20,DATA_ACHATS!$D:$D,"AOO-M") -> 0 | F20: =COUNTIFS(DATA_ACHATS!$A:$A,$A20,DATA_ACHATS!$D:$D,"AOO-CT") -> 0 | G20: =SUMIFS(DATA_ACHATS!$E:$E,DATA_ACHATS!$A:$A,$A20,DATA_ACHATS!$D:$D,"AOO-CT") -> 0 | H20: =COUNTIFS(DATA_ACHATS!$A:$A,$A20,DATA_ACHATS!$D:$D,"BCL") -> 0 | I20: =SUMIFS(DATA_ACHATS!$E:$E,DATA_ACHATS!$A:$A,$A20,DATA_ACHATS!$D:$D,"BCL") -> 0 | J20: =COUNTIFS(DATA_ACHATS!$A:$A,$A20,DATA_ACHATS!$D:$D,"BCI") -> 0 | K20: =SUMIFS(DATA_ACHATS!$E:$E,DATA_ACHATS!$A:$A,$A20,DATA_ACHATS!$D:$D,"BCI") -> 0 | L20: =COUNTIF(DATA_ACHATS!$A:$A,$A20) -> 5 | M20: =SUMIF(DATA_ACHATS!$A:$A,$A20,DATA_ACHATS!$E:$E) -> 427760
A21: DACG | B21: =COUNTIFS(DATA_ACHATS!$A:$A,$A21,DATA_ACHATS!$D:$D,"CONTRAT") -> 3 | C21: =SUMIFS(DATA_ACHATS!$E:$E,DATA_ACHATS!$A:$A,$A21,DATA_ACHATS!$D:$D,"CONTRAT") -> 318500 | D21: =COUNTIFS(DATA_ACHATS!$A:$A,$A21,DATA_ACHATS!$D:$D,"AOO-M") -> 1 | E21: =SUMIFS(DATA_ACHATS!$E:$E,DATA_ACHATS!$A:$A,$A21,DATA_ACHATS!$D:$D,"AOO-M") -> 0 | F21: =COUNTIFS(DATA_ACHATS!$A:$A,$A21,DATA_ACHATS!$D:$D,"AOO-CT") -> 0 | G21: =SUMIFS(DATA_ACHATS!$E:$E,DATA_ACHATS!$A:$A,$A21,DATA_ACHATS!$D:$D,"AOO-CT") -> 0 | H21: =COUNTIFS(DATA_ACHATS!$A:$A,$A21,DATA_ACHATS!$D:$D,"BCL") -> 0 | I21: =SUMIFS(DATA_ACHATS!$E:$E,DATA_ACHATS!$A:$A,$A21,DATA_ACHATS!$D:$D,"BCL") -> 0 | J21: =COUNTIFS(DATA_ACHATS!$A:$A,$A21,DATA_ACHATS!$D:$D,"BCI") -> 0 | K21: =SUMIFS(DATA_ACHATS!$E:$E,DATA_ACHATS!$A:$A,$A21,DATA_ACHATS!$D:$D,"BCI") -> 0 | L21: =COUNTIF(DATA_ACHATS!$A:$A,$A21) -> 4 | M21: =SUMIF(DATA_ACHATS!$A:$A,$A21,DATA_ACHATS!$E:$E) -> 318500
A22: DAR | B22: =COUNTIFS(DATA_ACHATS!$A:$A,$A22,DATA_ACHATS!$D:$D,"CONTRAT") -> 1 | C22: =SUMIFS(DATA_ACHATS!$E:$E,DATA_ACHATS!$A:$A,$A22,DATA_ACHATS!$D:$D,"CONTRAT") -> 108000 | D22: =COUNTIFS(DATA_ACHATS!$A:$A,$A22,DATA_ACHATS!$D:$D,"AOO-M") -> 0 | E22: =SUMIFS(DATA_ACHATS!$E:$E,DATA_ACHATS!$A:$A,$A22,DATA_ACHATS!$D:$D,"AOO-M") -> 0 | F22: =COUNTIFS(DATA_ACHATS!$A:$A,$A22,DATA_ACHATS!$D:$D,"AOO-CT") -> 0 | G22: =SUMIFS(DATA_ACHATS!$E:$E,DATA_ACHATS!$A:$A,$A22,DATA_ACHATS!$D:$D,"AOO-CT") -> 0 | H22: =COUNTIFS(DATA_ACHATS!$A:$A,$A22,DATA_ACHATS!$D:$D,"BCL") -> 0 | I22: =SUMIFS(DATA_ACHATS!$E:$E,DATA_ACHATS!$A:$A,$A22,DATA_ACHATS!$D:$D,"BCL") -> 0 | J22: =COUNTIFS(DATA_ACHATS!$A:$A,$A22,DATA_ACHATS!$D:$D,"BCI") -> 0 | K22: =SUMIFS(DATA_ACHATS!$E:$E,DATA_ACHATS!$A:$A,$A22,DATA_ACHATS!$D:$D,"BCI") -> 0 | L22: =COUNTIF(DATA_ACHATS!$A:$A,$A22) -> 1 | M22: =SUMIF(DATA_ACHATS!$A:$A,$A22,DATA_ACHATS!$E:$E) -> 108000
A23: DCPA | B23: =COUNTIFS(DATA_ACHATS!$A:$A,$A23,DATA_ACHATS!$D:$D,"CONTRAT") -> 19 | C23: =SUMIFS(DATA_ACHATS!$E:$E,DATA_ACHATS!$A:$A,$A23,DATA_ACHATS!$D:$D,"CONTRAT") -> 4716651.5 | D23: =COUNTIFS(DATA_ACHATS!$A:$A,$A23,DATA_ACHATS!$D:$D,"AOO-M") -> 0 | E23: =SUMIFS(DATA_ACHATS!$E:$E,DATA_ACHATS!$A:$A,$A23,DATA_ACHATS!$D:$D,"AOO-M") -> 0 | F23: =COUNTIFS(DATA_ACHATS!$A:$A,$A23,DATA_ACHATS!$D:$D,"AOO-CT") -> 1 | G23: =SUMIFS(DATA_ACHATS!$E:$E,DATA_ACHATS!$A:$A,$A23,DATA_ACHATS!$D:$D,"AOO-CT") -> 12605142 | H23: =COUNTIFS(DATA_ACHATS!$A:$A,$A23,DATA_ACHATS!$D:$D,"BCL") -> 0 | I23: =SUMIFS(DATA_ACHATS!$E:$E,DATA_ACHATS!$A:$A,$A23,DATA_ACHATS!$D:$D,"BCL") -> 0 | J23: =COUNTIFS(DATA_ACHATS!$A:$A,$A23,DATA_ACHATS!$D:$D,"BCI") -> 0 | K23: =SUMIFS(DATA_ACHATS!$E:$E,DATA_ACHATS!$A:$A,$A23,DATA_ACHATS!$D:$D,"BCI") -> 0 | L23: =COUNTIF(DATA_ACHATS!$A:$A,$A23) -> 20 | M23: =SUMIF(DATA_ACHATS!$A:$A,$A23,DATA_ACHATS!$E:$E) -> 17321794
A24: DCRI | B24: =COUNTIFS(DATA_ACHATS!$A:$A,$A24,DATA_ACHATS!$D:$D,"CONTRAT") -> 1 | C24: =SUMIFS(DATA_ACHATS!$E:$E,DATA_ACHATS!$A:$A,$A24,DATA_ACHATS!$D:$D,"CONTRAT") -> 318240 | D24: =COUNTIFS(DATA_ACHATS!$A:$A,$A24,DATA_ACHATS!$D:$D,"AOO-M") -> 0 | E24: =SUMIFS(DATA_ACHATS!$E:$E,DATA_ACHATS!$A:$A,$A24,DATA_ACHATS!$D:$D,"AOO-M") -> 0 | F24: =COUNTIFS(DATA_ACHATS!$A:$A,$A24,DATA_ACHATS!$D:$D,"AOO-CT") -> 0 | G24: =SUMIFS(DATA_ACHATS!$E:$E,DATA_ACHATS!$A:$A,$A24,DATA_ACHATS!$D:$D,"AOO-CT") -> 0 | H24: =COUNTIFS(DATA_ACHATS!$A:$A,$A24,DATA_ACHATS!$D:$D,"BCL") -> 0 | I24: =SUMIFS(DATA_ACHATS!$E:$E,DATA_ACHATS!$A:$A,$A24,DATA_ACHATS!$D:$D,"BCL") -> 0 | J24: =COUNTIFS(DATA_ACHATS!$A:$A,$A24,DATA_ACHATS!$D:$D,"BCI") -> 0 | K24: =SUMIFS(DATA_ACHATS!$E:$E,DATA_ACHATS!$A:$A,$A24,DATA_ACHATS!$D:$D,"BCI") -> 0 | L24: =COUNTIF(DATA_ACHATS!$A:$A,$A24) -> 1 | M24: =SUMIF(DATA_ACHATS!$A:$A,$A24,DATA_ACHATS!$E:$E) -> 318240
A25: DG | B25: =COUNTIFS(DATA_ACHATS!$A:$A,$A25,DATA_ACHATS!$D:$D,"CONTRAT") -> 1 | C25: =SUMIFS(DATA_ACHATS!$E:$E,DATA_ACHATS!$A:$A,$A25,DATA_ACHATS!$D:$D,"CONTRAT") -> 576000 | D25: =COUNTIFS(DATA_ACHATS!$A:$A,$A25,DATA_ACHATS!$D:$D,"AOO-M") -> 0 | E25: =SUMIFS(DATA_ACHATS!$E:$E,DATA_ACHATS!$A:$A,$A25,DATA_ACHATS!$D:$D,"AOO-M") -> 0 | F25: =COUNTIFS(DATA_ACHATS!$A:$A,$A25,DATA_ACHATS!$D:$D,"AOO-CT") -> 0 | G25: =SUMIFS(DATA_ACHATS!$E:$E,DATA_ACHATS!$A:$A,$A25,DATA_ACHATS!$D:$D,"AOO-CT") -> 0 | H25: =COUNTIFS(DATA_ACHATS!$A:$A,$A25,DATA_ACHATS!$D:$D,"BCL") -> 0 | I25: =SUMIFS(DATA_ACHATS!$E:$E,DATA_ACHATS!$A:$A,$A25,DATA_ACHATS!$D:$D,"BCL") -> 0 | J25: =COUNTIFS(DATA_ACHATS!$A:$A,$A25,DATA_ACHATS!$D:$D,"BCI") -> 0 | K25: =SUMIFS(DATA_ACHATS!$E:$E,DATA_ACHATS!$A:$A,$A25,DATA_ACHATS!$D:$D,"BCI") -> 0 | L25: =COUNTIF(DATA_ACHATS!$A:$A,$A25) -> 1 | M25: =SUMIF(DATA_ACHATS!$A:$A,$A25,DATA_ACHATS!$E:$E) -> 576000
A26: DINFORADIO | B26: =COUNTIFS(DATA_ACHATS!$A:$A,$A26,DATA_ACHATS!$D:$D,"CONTRAT") -> 7 | C26: =SUMIFS(DATA_ACHATS!$E:$E,DATA_ACHATS!$A:$A,$A26,DATA_ACHATS!$D:$D,"CONTRAT") -> 2648832.5 | D26: =COUNTIFS(DATA_ACHATS!$A:$A,$A26,DATA_ACHATS!$D:$D,"AOO-M") -> 0 | E26: =SUMIFS(DATA_ACHATS!$E:$E,DATA_ACHATS!$A:$A,$A26,DATA_ACHATS!$D:$D,"AOO-M") -> 0 | F26: =COUNTIFS(DATA_ACHATS!$A:$A,$A26,DATA_ACHATS!$D:$D,"AOO-CT") -> 0 | G26: =SUMIFS(DATA_ACHATS!$E:$E,DATA_ACHATS!$A:$A,$A26,DATA_ACHATS!$D:$D,"AOO-CT") -> 0 | H26: =COUNTIFS(DATA_ACHATS!$A:$A,$A26,DATA_ACHATS!$D:$D,"BCL") -> 0 | I26: =SUMIFS(DATA_ACHATS!$E:$E,DATA_ACHATS!$A:$A,$A26,DATA_ACHATS!$D:$D,"BCL") -> 0 | J26: =COUNTIFS(DATA_ACHATS!$A:$A,$A26,DATA_ACHATS!$D:$D,"BCI") -> 0 | K26: =SUMIFS(DATA_ACHATS!$E:$E,DATA_ACHATS!$A:$A,$A26,DATA_ACHATS!$D:$D,"BCI") -> 0 | L26: =COUNTIF(DATA_ACHATS!$A:$A,$A26) -> 7 | M26: =SUMIF(DATA_ACHATS!$A:$A,$A26,DATA_ACHATS!$E:$E) -> 2648832.5
A27: DINFOTV | B27: =COUNTIFS(DATA_ACHATS!$A:$A,$A27,DATA_ACHATS!$D:$D,"CONTRAT") -> 30 | C27: =SUMIFS(DATA_ACHATS!$E:$E,DATA_ACHATS!$A:$A,$A27,DATA_ACHATS!$D:$D,"CONTRAT") -> 10711701 | D27: =COUNTIFS(DATA_ACHATS!$A:$A,$A27,DATA_ACHATS!$D:$D,"AOO-M") -> 1 | E27: =SUMIFS(DATA_ACHATS!$E:$E,DATA_ACHATS!$A:$A,$A27,DATA_ACHATS!$D:$D,"AOO-M") -> 76464 | F27: =COUNTIFS(DATA_ACHATS!$A:$A,$A27,DATA_ACHATS!$D:$D,"AOO-CT") -> 0 | G27: =SUMIFS(DATA_ACHATS!$E:$E,DATA_ACHATS!$A:$A,$A27,DATA_ACHATS!$D:$D,"AOO-CT") -> 0 | H27: =COUNTIFS(DATA_ACHATS!$A:$A,$A27,DATA_ACHATS!$D:$D,"BCL") -> 0 | I27: =SUMIFS(DATA_ACHATS!$E:$E,DATA_ACHATS!$A:$A,$A27,DATA_ACHATS!$D:$D,"BCL") -> 0 | J27: =COUNTIFS(DATA_ACHATS!$A:$A,$A27,DATA_ACHATS!$D:$D,"BCI") -> 0 | K27: =SUMIFS(DATA_ACHATS!$E:$E,DATA_ACHATS!$A:$A,$A27,DATA_ACHATS!$D:$D,"BCI") -> 0 | L27: =COUNTIF(DATA_ACHATS!$A:$A,$A27) -> 31 | M27: =SUMIF(DATA_ACHATS!$A:$A,$A27,DATA_ACHATS!$E:$E) -> 10788165
A28: DJURIDIQUE | B28: =COUNTIFS(DATA_ACHATS!$A:$A,$A28,DATA_ACHATS!$D:$D,"CONTRAT") -> 8 | C28: =SUMIFS(DATA_ACHATS!$E:$E,DATA_ACHATS!$A:$A,$A28,DATA_ACHATS!$D:$D,"CONTRAT") -> 8551887.7 | D28: =COUNTIFS(DATA_ACHATS!$A:$A,$A28,DATA_ACHATS!$D:$D,"AOO-M") -> 0 | E28: =SUMIFS(DATA_ACHATS!$E:$E,DATA_ACHATS!$A:$A,$A28,DATA_ACHATS!$D:$D,"AOO-M") -> 0 | F28: =COUNTIFS(DATA_ACHATS!$A:$A,$A28,DATA_ACHATS!$D:$D,"AOO-CT") -> 0 | G28: =SUMIFS(DATA_ACHATS!$E:$E,DATA_ACHATS!$A:$A,$A28,DATA_ACHATS!$D:$D,"AOO-CT") -> 0 | H28: =COUNTIFS(DATA_ACHATS!$A:$A,$A28,DATA_ACHATS!$D:$D,"BCL") -> 0 | I28: =SUMIFS(DATA_ACHATS!$E:$E,DATA_ACHATS!$A:$A,$A28,DATA_ACHATS!$D:$D,"BCL") -> 0 | J28: =COUNTIFS(DATA_ACHATS!$A:$A,$A28,DATA_ACHATS!$D:$D,"BCI") -> 0 | K28: =SUMIFS(DATA_ACHATS!$E:$E,DATA_ACHATS!$A:$A,$A28,DATA_ACHATS!$D:$D,"BCI") -> 0 | L28: =COUNTIF(DATA_ACHATS!$A:$A,$A28) -> 8 | M28: =SUMIF(DATA_ACHATS!$A:$A,$A28,DATA_ACHATS!$E:$E) -> 8551887.7
A29: DMPTV | B29: =COUNTIFS(DATA_ACHATS!$A:$A,$A29,DATA_ACHATS!$D:$D,"CONTRAT") -> 23 | C29: =SUMIFS(DATA_ACHATS!$E:$E,DATA_ACHATS!$A:$A,$A29,DATA_ACHATS!$D:$D,"CONTRAT") -> 23581628 | D29: =COUNTIFS(DATA_ACHATS!$A:$A,$A29,DATA_ACHATS!$D:$D,"AOO-M") -> 1 | E29: =SUMIFS(DATA_ACHATS!$E:$E,DATA_ACHATS!$A:$A,$A29,DATA_ACHATS!$D:$D,"AOO-M") -> 0 | F29: =COUNTIFS(DATA_ACHATS!$A:$A,$A29,DATA_ACHATS!$D:$D,"AOO-CT") -> 0 | G29: =SUMIFS(DATA_ACHATS!$E:$E,DATA_ACHATS!$A:$A,$A29,DATA_ACHATS!$D:$D,"AOO-CT") -> 0 | H29: =COUNTIFS(DATA_ACHATS!$A:$A,$A29,DATA_ACHATS!$D:$D,"BCL") -> 1 | I29: =SUMIFS(DATA_ACHATS!$E:$E,DATA_ACHATS!$A:$A,$A29,DATA_ACHATS!$D:$D,"BCL") -> 112800 | J29: =COUNTIFS(DATA_ACHATS!$A:$A,$A29,DATA_ACHATS!$D:$D,"BCI") -> 1 | K29: =SUMIFS(DATA_ACHATS!$E:$E,DATA_ACHATS!$A:$A,$A29,DATA_ACHATS!$D:$D,"BCI") -> 198971.91 | L29: =COUNTIF(DATA_ACHATS!$A:$A,$A29) -> 26 | M29: =SUMIF(DATA_ACHATS!$A:$A,$A29,DATA_ACHATS!$E:$E) -> 23893400
... A39: TV LAAYOUNE | B39: =COUNTIFS(DATA_ACHATS!$A:$A,$A39,DATA_ACHATS!$D:$D,"CONTRAT") -> 5 | C39: =SUMIFS(DATA_ACHATS!$E:$E,DATA_ACHATS!$A:$A,$A39,DATA_ACHATS!$D:$D,"CONTRAT") -> 1061800.7 | D39: =COUNTIFS(DATA_ACHATS!$A:$A,$A39,DATA_ACHATS!$D:$D,"AOO-M") -> 0 | E39: =SUMIFS(DATA_ACHATS!$E:$E,DATA_ACHATS!$A:$A,$A39,DATA_ACHATS!$D:$D,"AOO-M") -> 0 | F39: =COUNTIFS(DATA_ACHATS!$A:$A,$A39,DATA_ACHATS!$D:$D,"AOO-CT") -> 18 | G39: =SUMIFS(DATA_ACHATS!$E:$E,DATA_ACHATS!$A:$A,$A39,DATA_ACHATS!$D:$D,"AOO-CT") -> 21385985 | H39: =COUNTIFS(DATA_ACHATS!$A:$A,$A39,DATA_ACHATS!$D:$D,"BCL") -> 3 | I39: =SUMIFS(DATA_ACHATS!$E:$E,DATA_ACHATS!$A:$A,$A39,DATA_ACHATS!$D:$D,"BCL") -> 144850 | J39: =COUNTIFS(DATA_ACHATS!$A:$A,$A39,DATA_ACHATS!$D:$D,"BCI") -> 0 | K39: =SUMIFS(DATA_ACHATS!$E:$E,DATA_ACHATS!$A:$A,$A39,DATA_ACHATS!$D:$D,"BCI") -> 0 | L39: =COUNTIF(DATA_ACHATS!$A:$A,$A39) -> 26 | M39: =SUMIF(DATA_ACHATS!$A:$A,$A39,DATA_ACHATS!$E:$E) -> 22592636
A40: TOTAL GÉNÉRAL | B40: =SUM(B18:B39) -> 455 | C40: =SUM(C18:C39) -> 4.3551277e+08 | D40: =SUM(D18:D39) -> 102 | E40: =SUM(E18:E39) -> 1.0690133e+08 | F40: =SUM(F18:F39) -> 19 | G40: =SUM(G18:G39) -> 33991127 | H40: =SUM(H18:H39) -> 21 | I40: =SUM(I18:I39) -> 2426739.3 | ... M40: =SUM(M18:M39) -> 5.7903093e+08
A42: RÉPARTITION GLOBALE PAR TYPE D'ACHAT
A43: TYPE | B43: Nb lignes | C43: % lignes | D43: Montant (MAD) | E43: % montant | F43: Montant moyen/ligne
A44: CONTRAT | B44: =COUNTIF(DATA_ACHATS!$D:$D,"CONTRAT") -> 455 | C44: =IFERROR(B44/$B$49,0) -> 0.76086957 | D44: =SUMIF(DATA_ACHATS!$D:$D,"CONTRAT",DATA_ACHATS!$E:$E) -> 4.3551277e+08 | E44: =IFERROR(D44/$D$49,0) -> 0.75214076 | F44: =IFERROR(D44/B44,0) -> 957170.91
A45: AOO-M | B45: =COUNTIF(DATA_ACHATS!$D:$D,"AOO-M") -> 102 | C45: =IFERROR(B45/$B$49,0) -> 0.17056856 | D45: =SUMIF(DATA_ACHATS!$D:$D,"AOO-M",DATA_ACHATS!$E:$E) -> 1.0690133e+08 | E45: =IFERROR(D45/$D$49,0) -> 0.1846211 | F45: =IFERROR(D45/B45,0) -> 1048052.2
A46: AOO-CT | B46: =COUNTIF(DATA_ACHATS!$D:$D,"AOO-CT") -> 19 | C46: =IFERROR(B46/$B$49,0) -> 0.031772575 | D46: =SUMIF(DATA_ACHATS!$D:$D,"AOO-CT",DATA_ACHATS!$E:$E) -> 33991127 | E46: =IFERROR(D46/$D$49,0) -> 0.058703474 | F46: =IFERROR(D46/B46,0) -> 1789006.7
A47: BCL | B47: =COUNTIF(DATA_ACHATS!$D:$D,"BCL") -> 21 | C47: =IFERROR(B47/$B$49,0) -> 0.035117057 | D47: =SUMIF(DATA_ACHATS!$D:$D,"BCL",DATA_ACHATS!$E:$E) -> 2426739.3 | E47: =IFERROR(D47/$D$49,0) -> 0.0041910357 | F47: =IFERROR(D47/B47,0) -> 115559.01
A48: BCI | B48: =COUNTIF(DATA_ACHATS!$D:$D,"BCI") -> 1 | C48: =IFERROR(B48/$B$49,0) -> 0.0016722408 | D48: =SUMIF(DATA_ACHATS!$D:$D,"BCI",DATA_ACHATS!$E:$E) -> 198971.91 | E48: =IFERROR(D48/$D$49,0) -> 0.00034362916 | F48: =IFERROR(D48/B48,0) -> 198971.91
A49: TOTAL | B49: =SUM(B44:B48) -> 598 | C49: 1 | D49: =SUM(D44:D48) -> 5.7903093e+08 | E49: 1 | F49: =IFERROR(D49/B49,0) -> 968279.15
A52: ▌ ARRIYADIA | F52: ↑ Retour au menu
A53: Type d'achat | B53: Nb lignes | C53: Montant (MAD) | D53: % montant dir.
A54: CONTRAT | B54: =COUNTIFS(DATA_ACHATS!$A:$A,"ARRIYADIA",DATA_ACHATS!$D:$D,"CONTRAT") -> 73 | C54: =SUMIFS(DATA_ACHATS!$E:$E,DATA_ACHATS!$A:$A,"ARRIYADIA",DATA_ACHATS!$D:$D,"CONTRAT") -> 1.7993517e+08 | D54: =IFERROR(C54/$C$59,0) -> 1
A55: AOO-M | B55: =COUNTIFS(DATA_ACHATS!$A:$A,"ARRIYADIA",DATA_ACHATS!$D:$D,"AOO-M") -> 0 | C55: =SUMIFS(DATA_ACHATS!$E:$E,DATA_ACHATS!$A:$A,"ARRIYADIA",DATA_ACHATS!$D:$D,"AOO-M") -> 0 | D55: =IFERROR(C55/$C$59,0) -> 0
...

Sheet Données
A1: DIRECTION | B1: NATURE | C1: STATUT ENGAGEMENT | D1: MONTANT TTC (MAD)
A2: DRH | B2: FONCTIONNEMENT | C2: ENGAGE | D2: 995042.4
A3: DCPA | B3: FONCTIONNEMENT | C3: ENGAGE | D3: 154000
A4: DCPA | B4: FONCTIONNEMENT | C4: ENGAGE | D4: 375000
A5: DCPA | B5: FONCTIONNEMENT | C5: ENGAGE | D5: 445714.08
A6: DCPA | B6: FONCTIONNEMENT | C6: ENGAGE | D6: 880000
A7: DCPA | B7: FONCTIONNEMENT | C7: ENGAGE | D7: 176000
A8: DCPA | B8: FONCTIONNEMENT | C8: ENGAGE | D8: 342857
A9: ARRIYADIA | B9: FONCTIONNEMENT | C9: ENGAGE | D9: 113142.48
A10: ARRIYADIA | B10: FONCTIONNEMENT | C10: ENGAGE | D10: 113142.48
A11: ARRIYADIA | B11: FONCTIONNEMENT | C11: ENGAGE | D11: 113142.48
A12: ARRIYADIA | B12: FONCTIONNEMENT | C12: ENGAGE | D12: 113142.48
A13: ARRIYADIA | B13: FONCTIONNEMENT | C13: ENGAGE | D13: 113142.48
... A599: TDF -SITES | B599: INVESTISSEMENT | C599: EN COURS DE PREENGAGEMENT | D599: 0

Sheet DATA_ACHATS
A1: DIRECTION | B1: NATURE | C1: STATUT | D1: TYPE_ACHAT | E1: MONTANT_TTC
A2: DRH | B2: FONCTIONNEMENT | C2: ENGAGE | D2: CONTRAT | E2: 995042.4
A3: DCPA | B3: FONCTIONNEMENT | C3: ENGAGE | D3: CONTRAT | E3: 154000
A4: DCPA | B4: FONCTIONNEMENT | C4: ENGAGE | D4: CONTRAT | E4: 375000
A5: DCPA | B5: FONCTIONNEMENT | C5: ENGAGE | D5: CONTRAT | E5: 445714.08
A6: DCPA | B6: FONCTIONNEMENT | C6: ENGAGE | D6: CONTRAT | E6: 880000
A7: DCPA | B7: FONCTIONNEMENT | C7: ENGAGE | D7: CONTRAT | E7: 176000
A8: DCPA | B8: FONCTIONNEMENT | C8: ENGAGE | D8: CONTRAT | E8: 342857
A9: ARRIYADIA | B9: FONCTIONNEMENT | C9: ENGAGE | D9: CONTRAT | E9: 113142.48
A10: ARRIYADIA | B10: FONCTIONNEMENT | C10: ENGAGE | D10: CONTRAT | E10: 113142.48
A11: ARRIYADIA | B11: FONCTIONNEMENT | C11: ENGAGE | D11: CONTRAT | E11: 113142.48
A12: ARRIYADIA | B12: FONCTIONNEMENT | C12: ENGAGE | D12: CONTRAT | E12: 113142.48
A13: ARRIYADIA | B13: FONCTIONNEMENT | C13: ENGAGE | D13: CONTRAT | E13: 113142.48
... A599: TDF -SITES | B599: INVESTISSEMENT | C599: EN COURS DE PREENGAGEMENT | D599: AOO-M | E599: 0
